2025-04-16 12:18:21 [INFO] w3_utils.<module>:29 - Connecting to Ethereum network via Alchemy...
2025-04-16 12:18:22 [INFO] w3_utils.<module>:53 - Loading contract ABI...
2025-04-16 12:18:22 [INFO] w3_utils.<module>:85 - Initializing contract...
2025-04-16 12:18:22 [INFO] w3_utils.<module>:109 - Initializing Filebase S3 client...
2025-04-16 12:18:23 [INFO] app.<module>:160 - Starting PII Authenticator backend server
2025-04-16 12:18:56 [INFO] w3_utils.<module>:29 - Connecting to Ethereum network via Alchemy...
2025-04-16 12:18:56 [INFO] w3_utils.<module>:53 - Loading contract ABI...
2025-04-16 12:18:56 [INFO] w3_utils.<module>:85 - Initializing contract...
2025-04-16 12:18:56 [INFO] w3_utils.<module>:109 - Initializing Filebase S3 client...
2025-04-16 12:18:57 [INFO] app.<module>:160 - Starting PII Authenticator backend server
2025-04-16 12:18:58 [INFO] w3_utils.<module>:29 - Connecting to Ethereum network via Alchemy...
2025-04-16 12:18:58 [INFO] w3_utils.<module>:53 - Loading contract ABI...
2025-04-16 12:18:58 [INFO] w3_utils.<module>:85 - Initializing contract...
2025-04-16 12:18:58 [INFO] w3_utils.<module>:109 - Initializing Filebase S3 client...
2025-04-16 12:18:59 [INFO] app.<module>:160 - Starting PII Authenticator backend server
2025-04-16 12:24:58 [INFO] w3_utils.<module>:29 - Connecting to Ethereum network via Alchemy...
2025-04-16 12:24:59 [INFO] w3_utils.<module>:53 - Loading contract ABI...
2025-04-16 12:24:59 [INFO] w3_utils.<module>:85 - Initializing contract...
2025-04-16 12:24:59 [INFO] w3_utils.<module>:109 - Initializing Filebase S3 client...
2025-04-16 12:24:59 [INFO] app.<module>:160 - Starting PII Authenticator backend server
2025-04-16 12:25:00 [INFO] w3_utils.<module>:29 - Connecting to Ethereum network via Alchemy...
2025-04-16 12:25:01 [INFO] w3_utils.<module>:53 - Loading contract ABI...
2025-04-16 12:25:01 [INFO] w3_utils.<module>:85 - Initializing contract...
2025-04-16 12:25:01 [INFO] w3_utils.<module>:109 - Initializing Filebase S3 client...
2025-04-16 12:25:01 [INFO] app.<module>:160 - Starting PII Authenticator backend server
2025-04-16 12:26:43 [INFO] w3_utils.<module>:29 - Connecting to Ethereum network via Alchemy...
2025-04-16 12:26:43 [INFO] w3_utils.<module>:53 - Loading contract ABI...
2025-04-16 12:26:43 [INFO] w3_utils.<module>:85 - Initializing contract...
2025-04-16 12:26:43 [INFO] w3_utils.<module>:109 - Initializing Filebase S3 client...
2025-04-16 12:26:43 [INFO] app.<module>:160 - Starting PII Authenticator backend server
2025-04-16 12:26:45 [DEBUG] app.after_request:34 - Request 2bf87542bdd6f297 processed in 0.0002 seconds
2025-04-16 12:27:33 [INFO] w3_utils.<module>:29 - Connecting to Ethereum network via Alchemy...
2025-04-16 12:27:33 [INFO] w3_utils.<module>:53 - Loading contract ABI...
2025-04-16 12:27:33 [INFO] w3_utils.<module>:85 - Initializing contract...
2025-04-16 12:27:33 [INFO] w3_utils.<module>:109 - Initializing Filebase S3 client...
2025-04-16 12:27:33 [INFO] app.<module>:160 - Starting PII Authenticator backend server
2025-04-16 12:27:36 [DEBUG] app.after_request:34 - Request 7caf796de4b90224 processed in 0.0001 seconds
2025-04-16 12:28:28 [INFO] token_auth.get_or_generate_token:27 - Generating token for user: test_user
2025-04-16 12:28:28 [DEBUG] token_auth.generate_unique_token:14 - Generated token: YC91QOYUNE
2025-04-16 12:28:28 [INFO] w3_utils.verify_token_on_blockchain:288 - Verifying token on blockchain: YC91QOYUNE
2025-04-16 12:28:28 [DEBUG] w3_utils.verify_token_on_blockchain:308 - Calling verifyToken function for token: YC91QOYUNE
2025-04-16 12:28:29 [DEBUG] w3_utils.verify_token_on_blockchain:318 - Traceback (most recent call last):
  File "C:\Users\prajw\AppData\Local\Programs\Python\Python313\Lib\site-packages\web3\contract\utils.py", line 207, in call_contract_function
    output_data = w3.codec.decode(output_types, return_data)
  File "C:\Users\prajw\AppData\Local\Programs\Python\Python313\Lib\site-packages\eth_abi\codec.py", line 162, in decode
    return cast(Tuple[Any, ...], decoder(stream))
                                 ~~~~~~~^^^^^^^^
  File "C:\Users\prajw\AppData\Local\Programs\Python\Python313\Lib\site-packages\eth_abi\decoding.py", line 131, in __call__
    return self.decode(stream)
           ~~~~~~~~~~~^^^^^^^^
  File "C:\Users\prajw\AppData\Local\Programs\Python\Python313\Lib\site-packages\eth_utils\functional.py", line 47, in inner
    return callback(fn(*args, **kwargs))
  File "C:\Users\prajw\AppData\Local\Programs\Python\Python313\Lib\site-packages\eth_abi\decoding.py", line 224, in decode
    self.validate_pointers(stream)
    ~~~~~~~~~~~~~~~~~~~~~~^^^^^^^^
  File "C:\Users\prajw\AppData\Local\Programs\Python\Python313\Lib\site-packages\eth_abi\decoding.py", line 218, in validate_pointers
    decoder(stream)
    ~~~~~~~^^^^^^^^
  File "C:\Users\prajw\AppData\Local\Programs\Python\Python313\Lib\site-packages\eth_abi\decoding.py", line 131, in __call__
    return self.decode(stream)
           ~~~~~~~~~~~^^^^^^^^
  File "C:\Users\prajw\AppData\Local\Programs\Python\Python313\Lib\site-packages\eth_abi\decoding.py", line 250, in decode
    raw_data = self.read_data_from_stream(stream)
  File "C:\Users\prajw\AppData\Local\Programs\Python\Python313\Lib\site-packages\eth_abi\decoding.py", line 389, in read_data_from_stream
    raise InsufficientDataBytes(
    ...<2 lines>...
    )
eth_abi.exceptions.InsufficientDataBytes: Tried to read 32 bytes, only got 0 bytes.

The above exception was the direct cause of the following exception:

Traceback (most recent call last):
  File "p:\blockchain-id-authentication\PII-Authenticator\backend\w3_utils.py", line 309, in verify_token_on_blockchain
    is_valid = contract.functions.verifyToken(user_token).call()
  File "C:\Users\prajw\AppData\Local\Programs\Python\Python313\Lib\site-packages\web3\contract\contract.py", line 291, in call
    return call_contract_function(
        self.w3,
    ...<11 lines>...
        **self.kwargs or {},
    )
  File "C:\Users\prajw\AppData\Local\Programs\Python\Python313\Lib\site-packages\web3\contract\utils.py", line 225, in call_contract_function
    raise BadFunctionCallOutput(msg) from e
web3.exceptions.BadFunctionCallOutput: Could not transact with/call contract function, is contract deployed correctly and chain synced?

2025-04-16 12:28:29 [DEBUG] token_auth.get_or_generate_token:38 - Token YC91QOYUNE is unique (verified after 1 attempts)
2025-04-16 12:28:29 [INFO] w3_utils.store_token_on_blockchain:228 - Storing token on blockchain: YC91QOYUNE
2025-04-16 12:28:29 [DEBUG] w3_utils.store_token_on_blockchain:250 - Building transaction for token: YC91QOYUNE
2025-04-16 12:28:29 [DEBUG] w3_utils.store_token_on_blockchain:259 - Signing transaction...
2025-04-16 12:28:29 [DEBUG] w3_utils.store_token_on_blockchain:262 - Sending transaction to network...
2025-04-16 12:28:29 [DEBUG] w3_utils.store_token_on_blockchain:275 - Traceback (most recent call last):
  File "p:\blockchain-id-authentication\PII-Authenticator\backend\w3_utils.py", line 263, in store_token_on_blockchain
    tx_hash = web3.eth.send_raw_transaction(signed_tx.rawTransaction)
                                            ^^^^^^^^^^^^^^^^^^^^^^^^
AttributeError: 'SignedTransaction' object has no attribute 'rawTransaction'. Did you mean: 'raw_transaction'?

2025-04-16 12:28:29 [WARNING] token_auth.get_or_generate_token:50 - Failed to store token YC91QOYUNE on blockchain for user test_user
2025-04-16 12:28:29 [DEBUG] token_auth.get_or_generate_token:53 - Token generation completed in 1.1564 seconds
2025-04-16 12:28:29 [INFO] w3_utils.upload_to_filebase:140 - Uploading file YC91QOYUNE.txt to storage...
2025-04-16 12:28:30 [INFO] .None:0 - ACCESS: /encrypt | User: test_user | Token: YC91QOYUNE | IP: 127.0.0.1 | Status: success | Details: Token generated and data stored at https://s3.filebase.com/pii-authenticator-test/YC91QOYUNE.txt
2025-04-16 12:28:30 [DEBUG] app.after_request:34 - Request cf2ebfaf2b0366a4 processed in 2.3562 seconds
2025-04-16 12:29:21 [INFO] token_auth.verify_token:67 - Verifying token: YC91QOYUNE
2025-04-16 12:29:21 [INFO] w3_utils.verify_token_on_blockchain:288 - Verifying token on blockchain: YC91QOYUNE
2025-04-16 12:29:21 [DEBUG] w3_utils.verify_token_on_blockchain:308 - Calling verifyToken function for token: YC91QOYUNE
2025-04-16 12:29:22 [DEBUG] w3_utils.verify_token_on_blockchain:318 - Traceback (most recent call last):
  File "C:\Users\prajw\AppData\Local\Programs\Python\Python313\Lib\site-packages\web3\contract\utils.py", line 207, in call_contract_function
    output_data = w3.codec.decode(output_types, return_data)
  File "C:\Users\prajw\AppData\Local\Programs\Python\Python313\Lib\site-packages\eth_abi\codec.py", line 162, in decode
    return cast(Tuple[Any, ...], decoder(stream))
                                 ~~~~~~~^^^^^^^^
  File "C:\Users\prajw\AppData\Local\Programs\Python\Python313\Lib\site-packages\eth_abi\decoding.py", line 131, in __call__
    return self.decode(stream)
           ~~~~~~~~~~~^^^^^^^^
  File "C:\Users\prajw\AppData\Local\Programs\Python\Python313\Lib\site-packages\eth_utils\functional.py", line 47, in inner
    return callback(fn(*args, **kwargs))
  File "C:\Users\prajw\AppData\Local\Programs\Python\Python313\Lib\site-packages\eth_abi\decoding.py", line 224, in decode
    self.validate_pointers(stream)
    ~~~~~~~~~~~~~~~~~~~~~~^^^^^^^^
  File "C:\Users\prajw\AppData\Local\Programs\Python\Python313\Lib\site-packages\eth_abi\decoding.py", line 218, in validate_pointers
    decoder(stream)
    ~~~~~~~^^^^^^^^
  File "C:\Users\prajw\AppData\Local\Programs\Python\Python313\Lib\site-packages\eth_abi\decoding.py", line 131, in __call__
    return self.decode(stream)
           ~~~~~~~~~~~^^^^^^^^
  File "C:\Users\prajw\AppData\Local\Programs\Python\Python313\Lib\site-packages\eth_abi\decoding.py", line 250, in decode
    raw_data = self.read_data_from_stream(stream)
  File "C:\Users\prajw\AppData\Local\Programs\Python\Python313\Lib\site-packages\eth_abi\decoding.py", line 389, in read_data_from_stream
    raise InsufficientDataBytes(
    ...<2 lines>...
    )
eth_abi.exceptions.InsufficientDataBytes: Tried to read 32 bytes, only got 0 bytes.

The above exception was the direct cause of the following exception:

Traceback (most recent call last):
  File "p:\blockchain-id-authentication\PII-Authenticator\backend\w3_utils.py", line 309, in verify_token_on_blockchain
    is_valid = contract.functions.verifyToken(user_token).call()
  File "C:\Users\prajw\AppData\Local\Programs\Python\Python313\Lib\site-packages\web3\contract\contract.py", line 291, in call
    return call_contract_function(
        self.w3,
    ...<11 lines>...
        **self.kwargs or {},
    )
  File "C:\Users\prajw\AppData\Local\Programs\Python\Python313\Lib\site-packages\web3\contract\utils.py", line 225, in call_contract_function
    raise BadFunctionCallOutput(msg) from e
web3.exceptions.BadFunctionCallOutput: Could not transact with/call contract function, is contract deployed correctly and chain synced?

2025-04-16 12:29:22 [DEBUG] token_auth.verify_token:74 - Token verification completed in 0.6926 seconds
2025-04-16 12:29:22 [INFO] token_auth.verify_token:79 - Token YC91QOYUNE is invalid
2025-04-16 12:29:22 [INFO] .None:0 - ACCESS: /validate_token | User: N/A | Token: YC91QOYUNE | IP: 127.0.0.1 | Status: invalid | Details: Token validation failed
2025-04-16 12:29:22 [DEBUG] app.after_request:34 - Request 9150cddd5b7bd155 processed in 0.6932 seconds
2025-04-16 12:29:38 [DEBUG] app.after_request:34 - Request 12ea336a65e11d6e processed in 0.0001 seconds
2025-04-16 12:29:38 [INFO] token_auth.get_or_generate_token:27 - Generating token for user: test_user_1744786778
2025-04-16 12:29:38 [DEBUG] token_auth.generate_unique_token:14 - Generated token: RZHUZQNM0Q
2025-04-16 12:29:38 [INFO] w3_utils.verify_token_on_blockchain:288 - Verifying token on blockchain: RZHUZQNM0Q
2025-04-16 12:29:38 [DEBUG] w3_utils.verify_token_on_blockchain:308 - Calling verifyToken function for token: RZHUZQNM0Q
2025-04-16 12:29:39 [DEBUG] w3_utils.verify_token_on_blockchain:318 - Traceback (most recent call last):
  File "C:\Users\prajw\AppData\Local\Programs\Python\Python313\Lib\site-packages\web3\contract\utils.py", line 207, in call_contract_function
    output_data = w3.codec.decode(output_types, return_data)
  File "C:\Users\prajw\AppData\Local\Programs\Python\Python313\Lib\site-packages\eth_abi\codec.py", line 162, in decode
    return cast(Tuple[Any, ...], decoder(stream))
                                 ~~~~~~~^^^^^^^^
  File "C:\Users\prajw\AppData\Local\Programs\Python\Python313\Lib\site-packages\eth_abi\decoding.py", line 131, in __call__
    return self.decode(stream)
           ~~~~~~~~~~~^^^^^^^^
  File "C:\Users\prajw\AppData\Local\Programs\Python\Python313\Lib\site-packages\eth_utils\functional.py", line 47, in inner
    return callback(fn(*args, **kwargs))
  File "C:\Users\prajw\AppData\Local\Programs\Python\Python313\Lib\site-packages\eth_abi\decoding.py", line 224, in decode
    self.validate_pointers(stream)
    ~~~~~~~~~~~~~~~~~~~~~~^^^^^^^^
  File "C:\Users\prajw\AppData\Local\Programs\Python\Python313\Lib\site-packages\eth_abi\decoding.py", line 218, in validate_pointers
    decoder(stream)
    ~~~~~~~^^^^^^^^
  File "C:\Users\prajw\AppData\Local\Programs\Python\Python313\Lib\site-packages\eth_abi\decoding.py", line 131, in __call__
    return self.decode(stream)
           ~~~~~~~~~~~^^^^^^^^
  File "C:\Users\prajw\AppData\Local\Programs\Python\Python313\Lib\site-packages\eth_abi\decoding.py", line 250, in decode
    raw_data = self.read_data_from_stream(stream)
  File "C:\Users\prajw\AppData\Local\Programs\Python\Python313\Lib\site-packages\eth_abi\decoding.py", line 389, in read_data_from_stream
    raise InsufficientDataBytes(
    ...<2 lines>...
    )
eth_abi.exceptions.InsufficientDataBytes: Tried to read 32 bytes, only got 0 bytes.

The above exception was the direct cause of the following exception:

Traceback (most recent call last):
  File "p:\blockchain-id-authentication\PII-Authenticator\backend\w3_utils.py", line 309, in verify_token_on_blockchain
    is_valid = contract.functions.verifyToken(user_token).call()
  File "C:\Users\prajw\AppData\Local\Programs\Python\Python313\Lib\site-packages\web3\contract\contract.py", line 291, in call
    return call_contract_function(
        self.w3,
    ...<11 lines>...
        **self.kwargs or {},
    )
  File "C:\Users\prajw\AppData\Local\Programs\Python\Python313\Lib\site-packages\web3\contract\utils.py", line 225, in call_contract_function
    raise BadFunctionCallOutput(msg) from e
web3.exceptions.BadFunctionCallOutput: Could not transact with/call contract function, is contract deployed correctly and chain synced?

2025-04-16 12:29:39 [DEBUG] token_auth.get_or_generate_token:38 - Token RZHUZQNM0Q is unique (verified after 1 attempts)
2025-04-16 12:29:39 [INFO] w3_utils.store_token_on_blockchain:228 - Storing token on blockchain: RZHUZQNM0Q
2025-04-16 12:29:39 [DEBUG] w3_utils.store_token_on_blockchain:250 - Building transaction for token: RZHUZQNM0Q
2025-04-16 12:29:39 [DEBUG] w3_utils.store_token_on_blockchain:259 - Signing transaction...
2025-04-16 12:29:39 [DEBUG] w3_utils.store_token_on_blockchain:262 - Sending transaction to network...
2025-04-16 12:29:39 [DEBUG] w3_utils.store_token_on_blockchain:275 - Traceback (most recent call last):
  File "p:\blockchain-id-authentication\PII-Authenticator\backend\w3_utils.py", line 263, in store_token_on_blockchain
    tx_hash = web3.eth.send_raw_transaction(signed_tx.rawTransaction)
                                            ^^^^^^^^^^^^^^^^^^^^^^^^
AttributeError: 'SignedTransaction' object has no attribute 'rawTransaction'. Did you mean: 'raw_transaction'?

2025-04-16 12:29:39 [WARNING] token_auth.get_or_generate_token:50 - Failed to store token RZHUZQNM0Q on blockchain for user test_user_1744786778
2025-04-16 12:29:39 [DEBUG] token_auth.get_or_generate_token:53 - Token generation completed in 0.9250 seconds
2025-04-16 12:29:39 [INFO] w3_utils.upload_to_filebase:140 - Uploading file RZHUZQNM0Q.txt to storage...
2025-04-16 12:29:40 [INFO] .None:0 - ACCESS: /encrypt | User: test_user_1744786778 | Token: RZHUZQNM0Q | IP: 127.0.0.1 | Status: success | Details: Token generated and data stored at https://s3.filebase.com/pii-authenticator-test/RZHUZQNM0Q.txt
2025-04-16 12:29:40 [DEBUG] app.after_request:34 - Request 30e33a25248f7d0e processed in 1.7337 seconds
2025-04-16 12:29:40 [INFO] token_auth.verify_token:67 - Verifying token: RZHUZQNM0Q
2025-04-16 12:29:40 [INFO] w3_utils.verify_token_on_blockchain:288 - Verifying token on blockchain: RZHUZQNM0Q
2025-04-16 12:29:40 [DEBUG] w3_utils.verify_token_on_blockchain:308 - Calling verifyToken function for token: RZHUZQNM0Q
2025-04-16 12:29:40 [DEBUG] w3_utils.verify_token_on_blockchain:318 - Traceback (most recent call last):
  File "C:\Users\prajw\AppData\Local\Programs\Python\Python313\Lib\site-packages\web3\contract\utils.py", line 207, in call_contract_function
    output_data = w3.codec.decode(output_types, return_data)
  File "C:\Users\prajw\AppData\Local\Programs\Python\Python313\Lib\site-packages\eth_abi\codec.py", line 162, in decode
    return cast(Tuple[Any, ...], decoder(stream))
                                 ~~~~~~~^^^^^^^^
  File "C:\Users\prajw\AppData\Local\Programs\Python\Python313\Lib\site-packages\eth_abi\decoding.py", line 131, in __call__
    return self.decode(stream)
           ~~~~~~~~~~~^^^^^^^^
  File "C:\Users\prajw\AppData\Local\Programs\Python\Python313\Lib\site-packages\eth_utils\functional.py", line 47, in inner
    return callback(fn(*args, **kwargs))
  File "C:\Users\prajw\AppData\Local\Programs\Python\Python313\Lib\site-packages\eth_abi\decoding.py", line 224, in decode
    self.validate_pointers(stream)
    ~~~~~~~~~~~~~~~~~~~~~~^^^^^^^^
  File "C:\Users\prajw\AppData\Local\Programs\Python\Python313\Lib\site-packages\eth_abi\decoding.py", line 218, in validate_pointers
    decoder(stream)
    ~~~~~~~^^^^^^^^
  File "C:\Users\prajw\AppData\Local\Programs\Python\Python313\Lib\site-packages\eth_abi\decoding.py", line 131, in __call__
    return self.decode(stream)
           ~~~~~~~~~~~^^^^^^^^
  File "C:\Users\prajw\AppData\Local\Programs\Python\Python313\Lib\site-packages\eth_abi\decoding.py", line 250, in decode
    raw_data = self.read_data_from_stream(stream)
  File "C:\Users\prajw\AppData\Local\Programs\Python\Python313\Lib\site-packages\eth_abi\decoding.py", line 389, in read_data_from_stream
    raise InsufficientDataBytes(
    ...<2 lines>...
    )
eth_abi.exceptions.InsufficientDataBytes: Tried to read 32 bytes, only got 0 bytes.

The above exception was the direct cause of the following exception:

Traceback (most recent call last):
  File "p:\blockchain-id-authentication\PII-Authenticator\backend\w3_utils.py", line 309, in verify_token_on_blockchain
    is_valid = contract.functions.verifyToken(user_token).call()
  File "C:\Users\prajw\AppData\Local\Programs\Python\Python313\Lib\site-packages\web3\contract\contract.py", line 291, in call
    return call_contract_function(
        self.w3,
    ...<11 lines>...
        **self.kwargs or {},
    )
  File "C:\Users\prajw\AppData\Local\Programs\Python\Python313\Lib\site-packages\web3\contract\utils.py", line 225, in call_contract_function
    raise BadFunctionCallOutput(msg) from e
web3.exceptions.BadFunctionCallOutput: Could not transact with/call contract function, is contract deployed correctly and chain synced?

2025-04-16 12:29:40 [DEBUG] token_auth.verify_token:74 - Token verification completed in 0.6680 seconds
2025-04-16 12:29:40 [INFO] token_auth.verify_token:79 - Token RZHUZQNM0Q is invalid
2025-04-16 12:29:40 [INFO] .None:0 - ACCESS: /validate_token | User: N/A | Token: RZHUZQNM0Q | IP: 127.0.0.1 | Status: invalid | Details: Token validation failed
2025-04-16 12:29:40 [DEBUG] app.after_request:34 - Request 861a7b828e50a8b1 processed in 0.6692 seconds
2025-04-16 12:29:40 [INFO] token_auth.verify_token:67 - Verifying token: INVALID123
2025-04-16 12:29:40 [INFO] w3_utils.verify_token_on_blockchain:288 - Verifying token on blockchain: INVALID123
2025-04-16 12:29:40 [DEBUG] w3_utils.verify_token_on_blockchain:308 - Calling verifyToken function for token: INVALID123
2025-04-16 12:29:41 [DEBUG] w3_utils.verify_token_on_blockchain:318 - Traceback (most recent call last):
  File "C:\Users\prajw\AppData\Local\Programs\Python\Python313\Lib\site-packages\web3\contract\utils.py", line 207, in call_contract_function
    output_data = w3.codec.decode(output_types, return_data)
  File "C:\Users\prajw\AppData\Local\Programs\Python\Python313\Lib\site-packages\eth_abi\codec.py", line 162, in decode
    return cast(Tuple[Any, ...], decoder(stream))
                                 ~~~~~~~^^^^^^^^
  File "C:\Users\prajw\AppData\Local\Programs\Python\Python313\Lib\site-packages\eth_abi\decoding.py", line 131, in __call__
    return self.decode(stream)
           ~~~~~~~~~~~^^^^^^^^
  File "C:\Users\prajw\AppData\Local\Programs\Python\Python313\Lib\site-packages\eth_utils\functional.py", line 47, in inner
    return callback(fn(*args, **kwargs))
  File "C:\Users\prajw\AppData\Local\Programs\Python\Python313\Lib\site-packages\eth_abi\decoding.py", line 224, in decode
    self.validate_pointers(stream)
    ~~~~~~~~~~~~~~~~~~~~~~^^^^^^^^
  File "C:\Users\prajw\AppData\Local\Programs\Python\Python313\Lib\site-packages\eth_abi\decoding.py", line 218, in validate_pointers
    decoder(stream)
    ~~~~~~~^^^^^^^^
  File "C:\Users\prajw\AppData\Local\Programs\Python\Python313\Lib\site-packages\eth_abi\decoding.py", line 131, in __call__
    return self.decode(stream)
           ~~~~~~~~~~~^^^^^^^^
  File "C:\Users\prajw\AppData\Local\Programs\Python\Python313\Lib\site-packages\eth_abi\decoding.py", line 250, in decode
    raw_data = self.read_data_from_stream(stream)
  File "C:\Users\prajw\AppData\Local\Programs\Python\Python313\Lib\site-packages\eth_abi\decoding.py", line 389, in read_data_from_stream
    raise InsufficientDataBytes(
    ...<2 lines>...
    )
eth_abi.exceptions.InsufficientDataBytes: Tried to read 32 bytes, only got 0 bytes.

The above exception was the direct cause of the following exception:

Traceback (most recent call last):
  File "p:\blockchain-id-authentication\PII-Authenticator\backend\w3_utils.py", line 309, in verify_token_on_blockchain
    is_valid = contract.functions.verifyToken(user_token).call()
  File "C:\Users\prajw\AppData\Local\Programs\Python\Python313\Lib\site-packages\web3\contract\contract.py", line 291, in call
    return call_contract_function(
        self.w3,
    ...<11 lines>...
        **self.kwargs or {},
    )
  File "C:\Users\prajw\AppData\Local\Programs\Python\Python313\Lib\site-packages\web3\contract\utils.py", line 225, in call_contract_function
    raise BadFunctionCallOutput(msg) from e
web3.exceptions.BadFunctionCallOutput: Could not transact with/call contract function, is contract deployed correctly and chain synced?

2025-04-16 12:29:41 [DEBUG] token_auth.verify_token:74 - Token verification completed in 0.7020 seconds
2025-04-16 12:29:41 [INFO] token_auth.verify_token:79 - Token INVALID123 is invalid
2025-04-16 12:29:41 [INFO] .None:0 - ACCESS: /validate_token | User: N/A | Token: INVALID123 | IP: 127.0.0.1 | Status: invalid | Details: Token validation failed
2025-04-16 12:29:41 [DEBUG] app.after_request:34 - Request c19281cdb9908f6e processed in 0.7023 seconds
2025-04-16 12:29:41 [INFO] .None:0 - ACCESS: /encrypt | User: N/A | Token: N/A | IP: 127.0.0.1 | Status: failure | Details: Missing fields
2025-04-16 12:29:41 [DEBUG] app.after_request:34 - Request c6c24e99e634f8f6 processed in 0.0009 seconds
2025-04-16 12:29:41 [INFO] .None:0 - ACCESS: /encrypt | User: test_user | Token: N/A | IP: 127.0.0.1 | Status: failure | Details: Missing fields
2025-04-16 12:29:41 [DEBUG] app.after_request:34 - Request 2c96b763bbaf1afc processed in 0.0002 seconds
2025-04-16 12:29:41 [INFO] .None:0 - ACCESS: /validate_token | User: N/A | Token: N/A | IP: 127.0.0.1 | Status: failure | Details: Token required
2025-04-16 12:29:41 [DEBUG] app.after_request:34 - Request d854ae05d45109d5 processed in 0.0002 seconds
2025-04-16 12:36:17 [INFO] token_auth.get_or_generate_token:27 - Generating token for user: test_user_1744787177685
2025-04-16 12:36:17 [INFO] token_auth.get_or_generate_token:27 - Generating token for user: test_user_1744787177685
2025-04-16 12:36:17 [DEBUG] token_auth.generate_unique_token:14 - Generated token: Q6MI5WMMRD
2025-04-16 12:36:17 [DEBUG] token_auth.generate_unique_token:14 - Generated token: XKD2X7DIL4
2025-04-16 12:36:17 [INFO] w3_utils.verify_token_on_blockchain:288 - Verifying token on blockchain: Q6MI5WMMRD
2025-04-16 12:36:17 [INFO] w3_utils.verify_token_on_blockchain:288 - Verifying token on blockchain: XKD2X7DIL4
2025-04-16 12:36:17 [DEBUG] w3_utils.verify_token_on_blockchain:308 - Calling verifyToken function for token: Q6MI5WMMRD
2025-04-16 12:36:17 [DEBUG] w3_utils.verify_token_on_blockchain:308 - Calling verifyToken function for token: XKD2X7DIL4
2025-04-16 12:36:18 [DEBUG] w3_utils.verify_token_on_blockchain:318 - Traceback (most recent call last):
  File "C:\Users\prajw\AppData\Local\Programs\Python\Python313\Lib\site-packages\web3\contract\utils.py", line 207, in call_contract_function
    output_data = w3.codec.decode(output_types, return_data)
  File "C:\Users\prajw\AppData\Local\Programs\Python\Python313\Lib\site-packages\eth_abi\codec.py", line 162, in decode
    return cast(Tuple[Any, ...], decoder(stream))
                                 ~~~~~~~^^^^^^^^
  File "C:\Users\prajw\AppData\Local\Programs\Python\Python313\Lib\site-packages\eth_abi\decoding.py", line 131, in __call__
    return self.decode(stream)
           ~~~~~~~~~~~^^^^^^^^
  File "C:\Users\prajw\AppData\Local\Programs\Python\Python313\Lib\site-packages\eth_utils\functional.py", line 47, in inner
    return callback(fn(*args, **kwargs))
  File "C:\Users\prajw\AppData\Local\Programs\Python\Python313\Lib\site-packages\eth_abi\decoding.py", line 224, in decode
    self.validate_pointers(stream)
    ~~~~~~~~~~~~~~~~~~~~~~^^^^^^^^
  File "C:\Users\prajw\AppData\Local\Programs\Python\Python313\Lib\site-packages\eth_abi\decoding.py", line 218, in validate_pointers
    decoder(stream)
    ~~~~~~~^^^^^^^^
  File "C:\Users\prajw\AppData\Local\Programs\Python\Python313\Lib\site-packages\eth_abi\decoding.py", line 131, in __call__
    return self.decode(stream)
           ~~~~~~~~~~~^^^^^^^^
  File "C:\Users\prajw\AppData\Local\Programs\Python\Python313\Lib\site-packages\eth_abi\decoding.py", line 250, in decode
    raw_data = self.read_data_from_stream(stream)
  File "C:\Users\prajw\AppData\Local\Programs\Python\Python313\Lib\site-packages\eth_abi\decoding.py", line 389, in read_data_from_stream
    raise InsufficientDataBytes(
    ...<2 lines>...
    )
eth_abi.exceptions.InsufficientDataBytes: Tried to read 32 bytes, only got 0 bytes.

The above exception was the direct cause of the following exception:

Traceback (most recent call last):
  File "p:\blockchain-id-authentication\PII-Authenticator\backend\w3_utils.py", line 309, in verify_token_on_blockchain
    is_valid = contract.functions.verifyToken(user_token).call()
  File "C:\Users\prajw\AppData\Local\Programs\Python\Python313\Lib\site-packages\web3\contract\contract.py", line 291, in call
    return call_contract_function(
        self.w3,
    ...<11 lines>...
        **self.kwargs or {},
    )
  File "C:\Users\prajw\AppData\Local\Programs\Python\Python313\Lib\site-packages\web3\contract\utils.py", line 225, in call_contract_function
    raise BadFunctionCallOutput(msg) from e
web3.exceptions.BadFunctionCallOutput: Could not transact with/call contract function, is contract deployed correctly and chain synced?

2025-04-16 12:36:18 [DEBUG] token_auth.get_or_generate_token:38 - Token XKD2X7DIL4 is unique (verified after 1 attempts)
2025-04-16 12:36:18 [INFO] w3_utils.store_token_on_blockchain:228 - Storing token on blockchain: XKD2X7DIL4
2025-04-16 12:36:18 [DEBUG] w3_utils.store_token_on_blockchain:250 - Building transaction for token: XKD2X7DIL4
2025-04-16 12:36:18 [DEBUG] w3_utils.verify_token_on_blockchain:318 - Traceback (most recent call last):
  File "C:\Users\prajw\AppData\Local\Programs\Python\Python313\Lib\site-packages\web3\contract\utils.py", line 207, in call_contract_function
    output_data = w3.codec.decode(output_types, return_data)
  File "C:\Users\prajw\AppData\Local\Programs\Python\Python313\Lib\site-packages\eth_abi\codec.py", line 162, in decode
    return cast(Tuple[Any, ...], decoder(stream))
                                 ~~~~~~~^^^^^^^^
  File "C:\Users\prajw\AppData\Local\Programs\Python\Python313\Lib\site-packages\eth_abi\decoding.py", line 131, in __call__
    return self.decode(stream)
           ~~~~~~~~~~~^^^^^^^^
  File "C:\Users\prajw\AppData\Local\Programs\Python\Python313\Lib\site-packages\eth_utils\functional.py", line 47, in inner
    return callback(fn(*args, **kwargs))
  File "C:\Users\prajw\AppData\Local\Programs\Python\Python313\Lib\site-packages\eth_abi\decoding.py", line 224, in decode
    self.validate_pointers(stream)
    ~~~~~~~~~~~~~~~~~~~~~~^^^^^^^^
  File "C:\Users\prajw\AppData\Local\Programs\Python\Python313\Lib\site-packages\eth_abi\decoding.py", line 218, in validate_pointers
    decoder(stream)
    ~~~~~~~^^^^^^^^
  File "C:\Users\prajw\AppData\Local\Programs\Python\Python313\Lib\site-packages\eth_abi\decoding.py", line 131, in __call__
    return self.decode(stream)
           ~~~~~~~~~~~^^^^^^^^
  File "C:\Users\prajw\AppData\Local\Programs\Python\Python313\Lib\site-packages\eth_abi\decoding.py", line 250, in decode
    raw_data = self.read_data_from_stream(stream)
  File "C:\Users\prajw\AppData\Local\Programs\Python\Python313\Lib\site-packages\eth_abi\decoding.py", line 389, in read_data_from_stream
    raise InsufficientDataBytes(
    ...<2 lines>...
    )
eth_abi.exceptions.InsufficientDataBytes: Tried to read 32 bytes, only got 0 bytes.

The above exception was the direct cause of the following exception:

Traceback (most recent call last):
  File "p:\blockchain-id-authentication\PII-Authenticator\backend\w3_utils.py", line 309, in verify_token_on_blockchain
    is_valid = contract.functions.verifyToken(user_token).call()
  File "C:\Users\prajw\AppData\Local\Programs\Python\Python313\Lib\site-packages\web3\contract\contract.py", line 291, in call
    return call_contract_function(
        self.w3,
    ...<11 lines>...
        **self.kwargs or {},
    )
  File "C:\Users\prajw\AppData\Local\Programs\Python\Python313\Lib\site-packages\web3\contract\utils.py", line 225, in call_contract_function
    raise BadFunctionCallOutput(msg) from e
web3.exceptions.BadFunctionCallOutput: Could not transact with/call contract function, is contract deployed correctly and chain synced?

2025-04-16 12:36:18 [DEBUG] token_auth.get_or_generate_token:38 - Token Q6MI5WMMRD is unique (verified after 1 attempts)
2025-04-16 12:36:18 [INFO] w3_utils.store_token_on_blockchain:228 - Storing token on blockchain: Q6MI5WMMRD
2025-04-16 12:36:18 [DEBUG] w3_utils.store_token_on_blockchain:250 - Building transaction for token: Q6MI5WMMRD
2025-04-16 12:36:18 [DEBUG] w3_utils.store_token_on_blockchain:259 - Signing transaction...
2025-04-16 12:36:18 [DEBUG] w3_utils.store_token_on_blockchain:262 - Sending transaction to network...
2025-04-16 12:36:18 [DEBUG] w3_utils.store_token_on_blockchain:275 - Traceback (most recent call last):
  File "p:\blockchain-id-authentication\PII-Authenticator\backend\w3_utils.py", line 263, in store_token_on_blockchain
    tx_hash = web3.eth.send_raw_transaction(signed_tx.rawTransaction)
                                            ^^^^^^^^^^^^^^^^^^^^^^^^
AttributeError: 'SignedTransaction' object has no attribute 'rawTransaction'. Did you mean: 'raw_transaction'?

2025-04-16 12:36:18 [WARNING] token_auth.get_or_generate_token:50 - Failed to store token XKD2X7DIL4 on blockchain for user test_user_1744787177685
2025-04-16 12:36:18 [DEBUG] token_auth.get_or_generate_token:53 - Token generation completed in 1.0749 seconds
2025-04-16 12:36:18 [INFO] w3_utils.upload_to_filebase:140 - Uploading file XKD2X7DIL4.txt to storage...
2025-04-16 12:36:18 [DEBUG] w3_utils.store_token_on_blockchain:259 - Signing transaction...
2025-04-16 12:36:18 [DEBUG] w3_utils.store_token_on_blockchain:262 - Sending transaction to network...
2025-04-16 12:36:18 [DEBUG] w3_utils.store_token_on_blockchain:275 - Traceback (most recent call last):
  File "p:\blockchain-id-authentication\PII-Authenticator\backend\w3_utils.py", line 263, in store_token_on_blockchain
    tx_hash = web3.eth.send_raw_transaction(signed_tx.rawTransaction)
                                            ^^^^^^^^^^^^^^^^^^^^^^^^
AttributeError: 'SignedTransaction' object has no attribute 'rawTransaction'. Did you mean: 'raw_transaction'?

2025-04-16 12:36:18 [WARNING] token_auth.get_or_generate_token:50 - Failed to store token Q6MI5WMMRD on blockchain for user test_user_1744787177685
2025-04-16 12:36:18 [DEBUG] token_auth.get_or_generate_token:53 - Token generation completed in 1.0930 seconds
2025-04-16 12:36:18 [INFO] w3_utils.upload_to_filebase:140 - Uploading file Q6MI5WMMRD.txt to storage...
2025-04-16 12:36:19 [INFO] .None:0 - ACCESS: /encrypt | User: test_user_1744787177685 | Token: Q6MI5WMMRD | IP: 127.0.0.1 | Status: success | Details: Token generated and data stored at https://s3.filebase.com/pii-authenticator-test/Q6MI5WMMRD.txt
2025-04-16 12:36:19 [DEBUG] app.after_request:34 - Request 6302332026b03878 processed in 2.1479 seconds
2025-04-16 12:36:19 [INFO] token_auth.get_or_generate_token:27 - Generating token for user: test_user_1744787179875
2025-04-16 12:36:19 [DEBUG] token_auth.generate_unique_token:14 - Generated token: 4Z6YTCIAG3
2025-04-16 12:36:19 [INFO] w3_utils.verify_token_on_blockchain:288 - Verifying token on blockchain: 4Z6YTCIAG3
2025-04-16 12:36:19 [DEBUG] w3_utils.verify_token_on_blockchain:308 - Calling verifyToken function for token: 4Z6YTCIAG3
2025-04-16 12:36:20 [INFO] .None:0 - ACCESS: /encrypt | User: test_user_1744787177685 | Token: XKD2X7DIL4 | IP: 127.0.0.1 | Status: success | Details: Token generated and data stored at https://s3.filebase.com/pii-authenticator-test/XKD2X7DIL4.txt
2025-04-16 12:36:20 [DEBUG] app.after_request:34 - Request 370c93c329883812 processed in 2.7986 seconds
2025-04-16 12:36:20 [INFO] token_auth.get_or_generate_token:27 - Generating token for user: test_user_1744787180536
2025-04-16 12:36:20 [DEBUG] token_auth.generate_unique_token:14 - Generated token: O9NY11T91J
2025-04-16 12:36:20 [INFO] w3_utils.verify_token_on_blockchain:288 - Verifying token on blockchain: O9NY11T91J
2025-04-16 12:36:20 [DEBUG] w3_utils.verify_token_on_blockchain:308 - Calling verifyToken function for token: O9NY11T91J
2025-04-16 12:36:20 [DEBUG] w3_utils.verify_token_on_blockchain:318 - Traceback (most recent call last):
  File "C:\Users\prajw\AppData\Local\Programs\Python\Python313\Lib\site-packages\web3\contract\utils.py", line 207, in call_contract_function
    output_data = w3.codec.decode(output_types, return_data)
  File "C:\Users\prajw\AppData\Local\Programs\Python\Python313\Lib\site-packages\eth_abi\codec.py", line 162, in decode
    return cast(Tuple[Any, ...], decoder(stream))
                                 ~~~~~~~^^^^^^^^
  File "C:\Users\prajw\AppData\Local\Programs\Python\Python313\Lib\site-packages\eth_abi\decoding.py", line 131, in __call__
    return self.decode(stream)
           ~~~~~~~~~~~^^^^^^^^
  File "C:\Users\prajw\AppData\Local\Programs\Python\Python313\Lib\site-packages\eth_utils\functional.py", line 47, in inner
    return callback(fn(*args, **kwargs))
  File "C:\Users\prajw\AppData\Local\Programs\Python\Python313\Lib\site-packages\eth_abi\decoding.py", line 224, in decode
    self.validate_pointers(stream)
    ~~~~~~~~~~~~~~~~~~~~~~^^^^^^^^
  File "C:\Users\prajw\AppData\Local\Programs\Python\Python313\Lib\site-packages\eth_abi\decoding.py", line 218, in validate_pointers
    decoder(stream)
    ~~~~~~~^^^^^^^^
  File "C:\Users\prajw\AppData\Local\Programs\Python\Python313\Lib\site-packages\eth_abi\decoding.py", line 131, in __call__
    return self.decode(stream)
           ~~~~~~~~~~~^^^^^^^^
  File "C:\Users\prajw\AppData\Local\Programs\Python\Python313\Lib\site-packages\eth_abi\decoding.py", line 250, in decode
    raw_data = self.read_data_from_stream(stream)
  File "C:\Users\prajw\AppData\Local\Programs\Python\Python313\Lib\site-packages\eth_abi\decoding.py", line 389, in read_data_from_stream
    raise InsufficientDataBytes(
    ...<2 lines>...
    )
eth_abi.exceptions.InsufficientDataBytes: Tried to read 32 bytes, only got 0 bytes.

The above exception was the direct cause of the following exception:

Traceback (most recent call last):
  File "p:\blockchain-id-authentication\PII-Authenticator\backend\w3_utils.py", line 309, in verify_token_on_blockchain
    is_valid = contract.functions.verifyToken(user_token).call()
  File "C:\Users\prajw\AppData\Local\Programs\Python\Python313\Lib\site-packages\web3\contract\contract.py", line 291, in call
    return call_contract_function(
        self.w3,
    ...<11 lines>...
        **self.kwargs or {},
    )
  File "C:\Users\prajw\AppData\Local\Programs\Python\Python313\Lib\site-packages\web3\contract\utils.py", line 225, in call_contract_function
    raise BadFunctionCallOutput(msg) from e
web3.exceptions.BadFunctionCallOutput: Could not transact with/call contract function, is contract deployed correctly and chain synced?

2025-04-16 12:36:20 [DEBUG] token_auth.get_or_generate_token:38 - Token 4Z6YTCIAG3 is unique (verified after 1 attempts)
2025-04-16 12:36:20 [INFO] w3_utils.store_token_on_blockchain:228 - Storing token on blockchain: 4Z6YTCIAG3
2025-04-16 12:36:20 [DEBUG] w3_utils.store_token_on_blockchain:250 - Building transaction for token: 4Z6YTCIAG3
2025-04-16 12:36:20 [DEBUG] w3_utils.store_token_on_blockchain:259 - Signing transaction...
2025-04-16 12:36:20 [DEBUG] w3_utils.store_token_on_blockchain:262 - Sending transaction to network...
2025-04-16 12:36:20 [DEBUG] w3_utils.store_token_on_blockchain:275 - Traceback (most recent call last):
  File "p:\blockchain-id-authentication\PII-Authenticator\backend\w3_utils.py", line 263, in store_token_on_blockchain
    tx_hash = web3.eth.send_raw_transaction(signed_tx.rawTransaction)
                                            ^^^^^^^^^^^^^^^^^^^^^^^^
AttributeError: 'SignedTransaction' object has no attribute 'rawTransaction'. Did you mean: 'raw_transaction'?

2025-04-16 12:36:20 [WARNING] token_auth.get_or_generate_token:50 - Failed to store token 4Z6YTCIAG3 on blockchain for user test_user_1744787179875
2025-04-16 12:36:20 [DEBUG] token_auth.get_or_generate_token:53 - Token generation completed in 0.9016 seconds
2025-04-16 12:36:20 [INFO] w3_utils.upload_to_filebase:140 - Uploading file 4Z6YTCIAG3.txt to storage...
2025-04-16 12:36:21 [DEBUG] w3_utils.verify_token_on_blockchain:318 - Traceback (most recent call last):
  File "C:\Users\prajw\AppData\Local\Programs\Python\Python313\Lib\site-packages\web3\contract\utils.py", line 207, in call_contract_function
    output_data = w3.codec.decode(output_types, return_data)
  File "C:\Users\prajw\AppData\Local\Programs\Python\Python313\Lib\site-packages\eth_abi\codec.py", line 162, in decode
    return cast(Tuple[Any, ...], decoder(stream))
                                 ~~~~~~~^^^^^^^^
  File "C:\Users\prajw\AppData\Local\Programs\Python\Python313\Lib\site-packages\eth_abi\decoding.py", line 131, in __call__
    return self.decode(stream)
           ~~~~~~~~~~~^^^^^^^^
  File "C:\Users\prajw\AppData\Local\Programs\Python\Python313\Lib\site-packages\eth_utils\functional.py", line 47, in inner
    return callback(fn(*args, **kwargs))
  File "C:\Users\prajw\AppData\Local\Programs\Python\Python313\Lib\site-packages\eth_abi\decoding.py", line 224, in decode
    self.validate_pointers(stream)
    ~~~~~~~~~~~~~~~~~~~~~~^^^^^^^^
  File "C:\Users\prajw\AppData\Local\Programs\Python\Python313\Lib\site-packages\eth_abi\decoding.py", line 218, in validate_pointers
    decoder(stream)
    ~~~~~~~^^^^^^^^
  File "C:\Users\prajw\AppData\Local\Programs\Python\Python313\Lib\site-packages\eth_abi\decoding.py", line 131, in __call__
    return self.decode(stream)
           ~~~~~~~~~~~^^^^^^^^
  File "C:\Users\prajw\AppData\Local\Programs\Python\Python313\Lib\site-packages\eth_abi\decoding.py", line 250, in decode
    raw_data = self.read_data_from_stream(stream)
  File "C:\Users\prajw\AppData\Local\Programs\Python\Python313\Lib\site-packages\eth_abi\decoding.py", line 389, in read_data_from_stream
    raise InsufficientDataBytes(
    ...<2 lines>...
    )
eth_abi.exceptions.InsufficientDataBytes: Tried to read 32 bytes, only got 0 bytes.

The above exception was the direct cause of the following exception:

Traceback (most recent call last):
  File "p:\blockchain-id-authentication\PII-Authenticator\backend\w3_utils.py", line 309, in verify_token_on_blockchain
    is_valid = contract.functions.verifyToken(user_token).call()
  File "C:\Users\prajw\AppData\Local\Programs\Python\Python313\Lib\site-packages\web3\contract\contract.py", line 291, in call
    return call_contract_function(
        self.w3,
    ...<11 lines>...
        **self.kwargs or {},
    )
  File "C:\Users\prajw\AppData\Local\Programs\Python\Python313\Lib\site-packages\web3\contract\utils.py", line 225, in call_contract_function
    raise BadFunctionCallOutput(msg) from e
web3.exceptions.BadFunctionCallOutput: Could not transact with/call contract function, is contract deployed correctly and chain synced?

2025-04-16 12:36:21 [DEBUG] token_auth.get_or_generate_token:38 - Token O9NY11T91J is unique (verified after 1 attempts)
2025-04-16 12:36:21 [INFO] w3_utils.store_token_on_blockchain:228 - Storing token on blockchain: O9NY11T91J
2025-04-16 12:36:21 [DEBUG] w3_utils.store_token_on_blockchain:250 - Building transaction for token: O9NY11T91J
2025-04-16 12:36:21 [INFO] .None:0 - ACCESS: /encrypt | User: test_user_1744787179875 | Token: 4Z6YTCIAG3 | IP: 127.0.0.1 | Status: success | Details: Token generated and data stored at https://s3.filebase.com/pii-authenticator-test/4Z6YTCIAG3.txt
2025-04-16 12:36:21 [DEBUG] app.after_request:34 - Request ff62f9bcddcf2225 processed in 1.4972 seconds
2025-04-16 12:36:21 [INFO] token_auth.get_or_generate_token:27 - Generating token for user: test_user_1744787181400
2025-04-16 12:36:21 [DEBUG] token_auth.generate_unique_token:14 - Generated token: XZDXYY4M4P
2025-04-16 12:36:21 [INFO] w3_utils.verify_token_on_blockchain:288 - Verifying token on blockchain: XZDXYY4M4P
2025-04-16 12:36:21 [DEBUG] w3_utils.verify_token_on_blockchain:308 - Calling verifyToken function for token: XZDXYY4M4P
2025-04-16 12:36:21 [DEBUG] w3_utils.store_token_on_blockchain:259 - Signing transaction...
2025-04-16 12:36:21 [DEBUG] w3_utils.store_token_on_blockchain:262 - Sending transaction to network...
2025-04-16 12:36:21 [DEBUG] w3_utils.store_token_on_blockchain:275 - Traceback (most recent call last):
  File "p:\blockchain-id-authentication\PII-Authenticator\backend\w3_utils.py", line 263, in store_token_on_blockchain
    tx_hash = web3.eth.send_raw_transaction(signed_tx.rawTransaction)
                                            ^^^^^^^^^^^^^^^^^^^^^^^^
AttributeError: 'SignedTransaction' object has no attribute 'rawTransaction'. Did you mean: 'raw_transaction'?

2025-04-16 12:36:21 [WARNING] token_auth.get_or_generate_token:50 - Failed to store token O9NY11T91J on blockchain for user test_user_1744787180536
2025-04-16 12:36:21 [DEBUG] token_auth.get_or_generate_token:53 - Token generation completed in 1.0130 seconds
2025-04-16 12:36:21 [INFO] w3_utils.upload_to_filebase:140 - Uploading file O9NY11T91J.txt to storage...
2025-04-16 12:36:22 [DEBUG] w3_utils.verify_token_on_blockchain:318 - Traceback (most recent call last):
  File "C:\Users\prajw\AppData\Local\Programs\Python\Python313\Lib\site-packages\web3\contract\utils.py", line 207, in call_contract_function
    output_data = w3.codec.decode(output_types, return_data)
  File "C:\Users\prajw\AppData\Local\Programs\Python\Python313\Lib\site-packages\eth_abi\codec.py", line 162, in decode
    return cast(Tuple[Any, ...], decoder(stream))
                                 ~~~~~~~^^^^^^^^
  File "C:\Users\prajw\AppData\Local\Programs\Python\Python313\Lib\site-packages\eth_abi\decoding.py", line 131, in __call__
    return self.decode(stream)
           ~~~~~~~~~~~^^^^^^^^
  File "C:\Users\prajw\AppData\Local\Programs\Python\Python313\Lib\site-packages\eth_utils\functional.py", line 47, in inner
    return callback(fn(*args, **kwargs))
  File "C:\Users\prajw\AppData\Local\Programs\Python\Python313\Lib\site-packages\eth_abi\decoding.py", line 224, in decode
    self.validate_pointers(stream)
    ~~~~~~~~~~~~~~~~~~~~~~^^^^^^^^
  File "C:\Users\prajw\AppData\Local\Programs\Python\Python313\Lib\site-packages\eth_abi\decoding.py", line 218, in validate_pointers
    decoder(stream)
    ~~~~~~~^^^^^^^^
  File "C:\Users\prajw\AppData\Local\Programs\Python\Python313\Lib\site-packages\eth_abi\decoding.py", line 131, in __call__
    return self.decode(stream)
           ~~~~~~~~~~~^^^^^^^^
  File "C:\Users\prajw\AppData\Local\Programs\Python\Python313\Lib\site-packages\eth_abi\decoding.py", line 250, in decode
    raw_data = self.read_data_from_stream(stream)
  File "C:\Users\prajw\AppData\Local\Programs\Python\Python313\Lib\site-packages\eth_abi\decoding.py", line 389, in read_data_from_stream
    raise InsufficientDataBytes(
    ...<2 lines>...
    )
eth_abi.exceptions.InsufficientDataBytes: Tried to read 32 bytes, only got 0 bytes.

The above exception was the direct cause of the following exception:

Traceback (most recent call last):
  File "p:\blockchain-id-authentication\PII-Authenticator\backend\w3_utils.py", line 309, in verify_token_on_blockchain
    is_valid = contract.functions.verifyToken(user_token).call()
  File "C:\Users\prajw\AppData\Local\Programs\Python\Python313\Lib\site-packages\web3\contract\contract.py", line 291, in call
    return call_contract_function(
        self.w3,
    ...<11 lines>...
        **self.kwargs or {},
    )
  File "C:\Users\prajw\AppData\Local\Programs\Python\Python313\Lib\site-packages\web3\contract\utils.py", line 225, in call_contract_function
    raise BadFunctionCallOutput(msg) from e
web3.exceptions.BadFunctionCallOutput: Could not transact with/call contract function, is contract deployed correctly and chain synced?

2025-04-16 12:36:22 [DEBUG] token_auth.get_or_generate_token:38 - Token XZDXYY4M4P is unique (verified after 1 attempts)
2025-04-16 12:36:22 [INFO] w3_utils.store_token_on_blockchain:228 - Storing token on blockchain: XZDXYY4M4P
2025-04-16 12:36:22 [DEBUG] w3_utils.store_token_on_blockchain:250 - Building transaction for token: XZDXYY4M4P
2025-04-16 12:36:22 [INFO] .None:0 - ACCESS: /encrypt | User: test_user_1744787180536 | Token: O9NY11T91J | IP: 127.0.0.1 | Status: success | Details: Token generated and data stored at https://s3.filebase.com/pii-authenticator-test/O9NY11T91J.txt
2025-04-16 12:36:22 [DEBUG] app.after_request:34 - Request 9d96e6156da141ef processed in 1.6179 seconds
2025-04-16 12:36:22 [DEBUG] w3_utils.store_token_on_blockchain:259 - Signing transaction...
2025-04-16 12:36:22 [DEBUG] w3_utils.store_token_on_blockchain:262 - Sending transaction to network...
2025-04-16 12:36:22 [DEBUG] w3_utils.store_token_on_blockchain:275 - Traceback (most recent call last):
  File "p:\blockchain-id-authentication\PII-Authenticator\backend\w3_utils.py", line 263, in store_token_on_blockchain
    tx_hash = web3.eth.send_raw_transaction(signed_tx.rawTransaction)
                                            ^^^^^^^^^^^^^^^^^^^^^^^^
AttributeError: 'SignedTransaction' object has no attribute 'rawTransaction'. Did you mean: 'raw_transaction'?

2025-04-16 12:36:22 [WARNING] token_auth.get_or_generate_token:50 - Failed to store token XZDXYY4M4P on blockchain for user test_user_1744787181400
2025-04-16 12:36:22 [DEBUG] token_auth.get_or_generate_token:53 - Token generation completed in 0.9343 seconds
2025-04-16 12:36:22 [INFO] w3_utils.upload_to_filebase:140 - Uploading file XZDXYY4M4P.txt to storage...
2025-04-16 12:36:22 [INFO] .None:0 - ACCESS: /encrypt | User: test_user_1744787181400 | Token: XZDXYY4M4P | IP: 127.0.0.1 | Status: success | Details: Token generated and data stored at https://s3.filebase.com/pii-authenticator-test/XZDXYY4M4P.txt
2025-04-16 12:36:22 [DEBUG] app.after_request:34 - Request 0f176179d56fd63f processed in 1.5080 seconds
2025-04-16 12:36:23 [INFO] token_auth.verify_token:67 - Verifying token: INVALID1744787183183
2025-04-16 12:36:23 [INFO] w3_utils.verify_token_on_blockchain:288 - Verifying token on blockchain: INVALID1744787183183
2025-04-16 12:36:23 [DEBUG] w3_utils.verify_token_on_blockchain:308 - Calling verifyToken function for token: INVALID1744787183183
2025-04-16 12:36:23 [INFO] token_auth.verify_token:67 - Verifying token: Q6MI5WMMRD
2025-04-16 12:36:23 [INFO] w3_utils.verify_token_on_blockchain:288 - Verifying token on blockchain: Q6MI5WMMRD
2025-04-16 12:36:23 [DEBUG] w3_utils.verify_token_on_blockchain:308 - Calling verifyToken function for token: Q6MI5WMMRD
2025-04-16 12:36:23 [DEBUG] w3_utils.verify_token_on_blockchain:318 - Traceback (most recent call last):
  File "C:\Users\prajw\AppData\Local\Programs\Python\Python313\Lib\site-packages\web3\contract\utils.py", line 207, in call_contract_function
    output_data = w3.codec.decode(output_types, return_data)
  File "C:\Users\prajw\AppData\Local\Programs\Python\Python313\Lib\site-packages\eth_abi\codec.py", line 162, in decode
    return cast(Tuple[Any, ...], decoder(stream))
                                 ~~~~~~~^^^^^^^^
  File "C:\Users\prajw\AppData\Local\Programs\Python\Python313\Lib\site-packages\eth_abi\decoding.py", line 131, in __call__
    return self.decode(stream)
           ~~~~~~~~~~~^^^^^^^^
  File "C:\Users\prajw\AppData\Local\Programs\Python\Python313\Lib\site-packages\eth_utils\functional.py", line 47, in inner
    return callback(fn(*args, **kwargs))
  File "C:\Users\prajw\AppData\Local\Programs\Python\Python313\Lib\site-packages\eth_abi\decoding.py", line 224, in decode
    self.validate_pointers(stream)
    ~~~~~~~~~~~~~~~~~~~~~~^^^^^^^^
  File "C:\Users\prajw\AppData\Local\Programs\Python\Python313\Lib\site-packages\eth_abi\decoding.py", line 218, in validate_pointers
    decoder(stream)
    ~~~~~~~^^^^^^^^
  File "C:\Users\prajw\AppData\Local\Programs\Python\Python313\Lib\site-packages\eth_abi\decoding.py", line 131, in __call__
    return self.decode(stream)
           ~~~~~~~~~~~^^^^^^^^
  File "C:\Users\prajw\AppData\Local\Programs\Python\Python313\Lib\site-packages\eth_abi\decoding.py", line 250, in decode
    raw_data = self.read_data_from_stream(stream)
  File "C:\Users\prajw\AppData\Local\Programs\Python\Python313\Lib\site-packages\eth_abi\decoding.py", line 389, in read_data_from_stream
    raise InsufficientDataBytes(
    ...<2 lines>...
    )
eth_abi.exceptions.InsufficientDataBytes: Tried to read 32 bytes, only got 0 bytes.

The above exception was the direct cause of the following exception:

Traceback (most recent call last):
  File "p:\blockchain-id-authentication\PII-Authenticator\backend\w3_utils.py", line 309, in verify_token_on_blockchain
    is_valid = contract.functions.verifyToken(user_token).call()
  File "C:\Users\prajw\AppData\Local\Programs\Python\Python313\Lib\site-packages\web3\contract\contract.py", line 291, in call
    return call_contract_function(
        self.w3,
    ...<11 lines>...
        **self.kwargs or {},
    )
  File "C:\Users\prajw\AppData\Local\Programs\Python\Python313\Lib\site-packages\web3\contract\utils.py", line 225, in call_contract_function
    raise BadFunctionCallOutput(msg) from e
web3.exceptions.BadFunctionCallOutput: Could not transact with/call contract function, is contract deployed correctly and chain synced?

2025-04-16 12:36:23 [DEBUG] token_auth.verify_token:74 - Token verification completed in 0.6509 seconds
2025-04-16 12:36:23 [INFO] token_auth.verify_token:79 - Token Q6MI5WMMRD is invalid
2025-04-16 12:36:23 [INFO] .None:0 - ACCESS: /validate_token | User: N/A | Token: Q6MI5WMMRD | IP: 127.0.0.1 | Status: invalid | Details: Token validation failed
2025-04-16 12:36:23 [DEBUG] app.after_request:34 - Request 418c3a86c3e6fe92 processed in 0.6514 seconds
2025-04-16 12:36:23 [DEBUG] w3_utils.verify_token_on_blockchain:318 - Traceback (most recent call last):
  File "C:\Users\prajw\AppData\Local\Programs\Python\Python313\Lib\site-packages\web3\contract\utils.py", line 207, in call_contract_function
    output_data = w3.codec.decode(output_types, return_data)
  File "C:\Users\prajw\AppData\Local\Programs\Python\Python313\Lib\site-packages\eth_abi\codec.py", line 162, in decode
    return cast(Tuple[Any, ...], decoder(stream))
                                 ~~~~~~~^^^^^^^^
  File "C:\Users\prajw\AppData\Local\Programs\Python\Python313\Lib\site-packages\eth_abi\decoding.py", line 131, in __call__
    return self.decode(stream)
           ~~~~~~~~~~~^^^^^^^^
  File "C:\Users\prajw\AppData\Local\Programs\Python\Python313\Lib\site-packages\eth_utils\functional.py", line 47, in inner
    return callback(fn(*args, **kwargs))
  File "C:\Users\prajw\AppData\Local\Programs\Python\Python313\Lib\site-packages\eth_abi\decoding.py", line 224, in decode
    self.validate_pointers(stream)
    ~~~~~~~~~~~~~~~~~~~~~~^^^^^^^^
  File "C:\Users\prajw\AppData\Local\Programs\Python\Python313\Lib\site-packages\eth_abi\decoding.py", line 218, in validate_pointers
    decoder(stream)
    ~~~~~~~^^^^^^^^
  File "C:\Users\prajw\AppData\Local\Programs\Python\Python313\Lib\site-packages\eth_abi\decoding.py", line 131, in __call__
    return self.decode(stream)
           ~~~~~~~~~~~^^^^^^^^
  File "C:\Users\prajw\AppData\Local\Programs\Python\Python313\Lib\site-packages\eth_abi\decoding.py", line 250, in decode
    raw_data = self.read_data_from_stream(stream)
  File "C:\Users\prajw\AppData\Local\Programs\Python\Python313\Lib\site-packages\eth_abi\decoding.py", line 389, in read_data_from_stream
    raise InsufficientDataBytes(
    ...<2 lines>...
    )
eth_abi.exceptions.InsufficientDataBytes: Tried to read 32 bytes, only got 0 bytes.

The above exception was the direct cause of the following exception:

Traceback (most recent call last):
  File "p:\blockchain-id-authentication\PII-Authenticator\backend\w3_utils.py", line 309, in verify_token_on_blockchain
    is_valid = contract.functions.verifyToken(user_token).call()
  File "C:\Users\prajw\AppData\Local\Programs\Python\Python313\Lib\site-packages\web3\contract\contract.py", line 291, in call
    return call_contract_function(
        self.w3,
    ...<11 lines>...
        **self.kwargs or {},
    )
  File "C:\Users\prajw\AppData\Local\Programs\Python\Python313\Lib\site-packages\web3\contract\utils.py", line 225, in call_contract_function
    raise BadFunctionCallOutput(msg) from e
web3.exceptions.BadFunctionCallOutput: Could not transact with/call contract function, is contract deployed correctly and chain synced?

2025-04-16 12:36:23 [DEBUG] token_auth.verify_token:74 - Token verification completed in 0.6784 seconds
2025-04-16 12:36:23 [INFO] token_auth.verify_token:79 - Token INVALID1744787183183 is invalid
2025-04-16 12:36:23 [INFO] .None:0 - ACCESS: /validate_token | User: N/A | Token: INVALID1744787183183 | IP: 127.0.0.1 | Status: invalid | Details: Token validation failed
2025-04-16 12:36:23 [DEBUG] app.after_request:34 - Request 300ef4a9d85fdeaf processed in 0.6790 seconds
2025-04-16 12:36:23 [INFO] token_auth.verify_token:67 - Verifying token: INVALID1744787183855
2025-04-16 12:36:23 [INFO] w3_utils.verify_token_on_blockchain:288 - Verifying token on blockchain: INVALID1744787183855
2025-04-16 12:36:23 [DEBUG] w3_utils.verify_token_on_blockchain:308 - Calling verifyToken function for token: INVALID1744787183855
2025-04-16 12:36:23 [INFO] token_auth.verify_token:67 - Verifying token: O9NY11T91J
2025-04-16 12:36:23 [INFO] w3_utils.verify_token_on_blockchain:288 - Verifying token on blockchain: O9NY11T91J
2025-04-16 12:36:23 [DEBUG] w3_utils.verify_token_on_blockchain:308 - Calling verifyToken function for token: O9NY11T91J
2025-04-16 12:36:24 [DEBUG] w3_utils.verify_token_on_blockchain:318 - Traceback (most recent call last):
  File "C:\Users\prajw\AppData\Local\Programs\Python\Python313\Lib\site-packages\web3\contract\utils.py", line 207, in call_contract_function
    output_data = w3.codec.decode(output_types, return_data)
  File "C:\Users\prajw\AppData\Local\Programs\Python\Python313\Lib\site-packages\eth_abi\codec.py", line 162, in decode
    return cast(Tuple[Any, ...], decoder(stream))
                                 ~~~~~~~^^^^^^^^
  File "C:\Users\prajw\AppData\Local\Programs\Python\Python313\Lib\site-packages\eth_abi\decoding.py", line 131, in __call__
    return self.decode(stream)
           ~~~~~~~~~~~^^^^^^^^
  File "C:\Users\prajw\AppData\Local\Programs\Python\Python313\Lib\site-packages\eth_utils\functional.py", line 47, in inner
    return callback(fn(*args, **kwargs))
  File "C:\Users\prajw\AppData\Local\Programs\Python\Python313\Lib\site-packages\eth_abi\decoding.py", line 224, in decode
    self.validate_pointers(stream)
    ~~~~~~~~~~~~~~~~~~~~~~^^^^^^^^
  File "C:\Users\prajw\AppData\Local\Programs\Python\Python313\Lib\site-packages\eth_abi\decoding.py", line 218, in validate_pointers
    decoder(stream)
    ~~~~~~~^^^^^^^^
  File "C:\Users\prajw\AppData\Local\Programs\Python\Python313\Lib\site-packages\eth_abi\decoding.py", line 131, in __call__
    return self.decode(stream)
           ~~~~~~~~~~~^^^^^^^^
  File "C:\Users\prajw\AppData\Local\Programs\Python\Python313\Lib\site-packages\eth_abi\decoding.py", line 250, in decode
    raw_data = self.read_data_from_stream(stream)
  File "C:\Users\prajw\AppData\Local\Programs\Python\Python313\Lib\site-packages\eth_abi\decoding.py", line 389, in read_data_from_stream
    raise InsufficientDataBytes(
    ...<2 lines>...
    )
eth_abi.exceptions.InsufficientDataBytes: Tried to read 32 bytes, only got 0 bytes.

The above exception was the direct cause of the following exception:

Traceback (most recent call last):
  File "p:\blockchain-id-authentication\PII-Authenticator\backend\w3_utils.py", line 309, in verify_token_on_blockchain
    is_valid = contract.functions.verifyToken(user_token).call()
  File "C:\Users\prajw\AppData\Local\Programs\Python\Python313\Lib\site-packages\web3\contract\contract.py", line 291, in call
    return call_contract_function(
        self.w3,
    ...<11 lines>...
        **self.kwargs or {},
    )
  File "C:\Users\prajw\AppData\Local\Programs\Python\Python313\Lib\site-packages\web3\contract\utils.py", line 225, in call_contract_function
    raise BadFunctionCallOutput(msg) from e
web3.exceptions.BadFunctionCallOutput: Could not transact with/call contract function, is contract deployed correctly and chain synced?

2025-04-16 12:36:24 [DEBUG] token_auth.verify_token:74 - Token verification completed in 0.6567 seconds
2025-04-16 12:36:24 [INFO] token_auth.verify_token:79 - Token INVALID1744787183855 is invalid
2025-04-16 12:36:24 [INFO] .None:0 - ACCESS: /validate_token | User: N/A | Token: INVALID1744787183855 | IP: 127.0.0.1 | Status: invalid | Details: Token validation failed
2025-04-16 12:36:24 [DEBUG] app.after_request:34 - Request a7d67a83e687fb9d processed in 0.6573 seconds
2025-04-16 12:36:24 [INFO] token_auth.verify_token:67 - Verifying token: XKD2X7DIL4
2025-04-16 12:36:24 [INFO] w3_utils.verify_token_on_blockchain:288 - Verifying token on blockchain: XKD2X7DIL4
2025-04-16 12:36:24 [DEBUG] w3_utils.verify_token_on_blockchain:308 - Calling verifyToken function for token: XKD2X7DIL4
2025-04-16 12:36:24 [DEBUG] w3_utils.verify_token_on_blockchain:318 - Traceback (most recent call last):
  File "C:\Users\prajw\AppData\Local\Programs\Python\Python313\Lib\site-packages\web3\contract\utils.py", line 207, in call_contract_function
    output_data = w3.codec.decode(output_types, return_data)
  File "C:\Users\prajw\AppData\Local\Programs\Python\Python313\Lib\site-packages\eth_abi\codec.py", line 162, in decode
    return cast(Tuple[Any, ...], decoder(stream))
                                 ~~~~~~~^^^^^^^^
  File "C:\Users\prajw\AppData\Local\Programs\Python\Python313\Lib\site-packages\eth_abi\decoding.py", line 131, in __call__
    return self.decode(stream)
           ~~~~~~~~~~~^^^^^^^^
  File "C:\Users\prajw\AppData\Local\Programs\Python\Python313\Lib\site-packages\eth_utils\functional.py", line 47, in inner
    return callback(fn(*args, **kwargs))
  File "C:\Users\prajw\AppData\Local\Programs\Python\Python313\Lib\site-packages\eth_abi\decoding.py", line 224, in decode
    self.validate_pointers(stream)
    ~~~~~~~~~~~~~~~~~~~~~~^^^^^^^^
  File "C:\Users\prajw\AppData\Local\Programs\Python\Python313\Lib\site-packages\eth_abi\decoding.py", line 218, in validate_pointers
    decoder(stream)
    ~~~~~~~^^^^^^^^
  File "C:\Users\prajw\AppData\Local\Programs\Python\Python313\Lib\site-packages\eth_abi\decoding.py", line 131, in __call__
    return self.decode(stream)
           ~~~~~~~~~~~^^^^^^^^
  File "C:\Users\prajw\AppData\Local\Programs\Python\Python313\Lib\site-packages\eth_abi\decoding.py", line 250, in decode
    raw_data = self.read_data_from_stream(stream)
  File "C:\Users\prajw\AppData\Local\Programs\Python\Python313\Lib\site-packages\eth_abi\decoding.py", line 389, in read_data_from_stream
    raise InsufficientDataBytes(
    ...<2 lines>...
    )
eth_abi.exceptions.InsufficientDataBytes: Tried to read 32 bytes, only got 0 bytes.

The above exception was the direct cause of the following exception:

Traceback (most recent call last):
  File "p:\blockchain-id-authentication\PII-Authenticator\backend\w3_utils.py", line 309, in verify_token_on_blockchain
    is_valid = contract.functions.verifyToken(user_token).call()
  File "C:\Users\prajw\AppData\Local\Programs\Python\Python313\Lib\site-packages\web3\contract\contract.py", line 291, in call
    return call_contract_function(
        self.w3,
    ...<11 lines>...
        **self.kwargs or {},
    )
  File "C:\Users\prajw\AppData\Local\Programs\Python\Python313\Lib\site-packages\web3\contract\utils.py", line 225, in call_contract_function
    raise BadFunctionCallOutput(msg) from e
web3.exceptions.BadFunctionCallOutput: Could not transact with/call contract function, is contract deployed correctly and chain synced?

2025-04-16 12:36:24 [DEBUG] token_auth.verify_token:74 - Token verification completed in 0.7004 seconds
2025-04-16 12:36:24 [INFO] token_auth.verify_token:79 - Token O9NY11T91J is invalid
2025-04-16 12:36:24 [INFO] .None:0 - ACCESS: /validate_token | User: N/A | Token: O9NY11T91J | IP: 127.0.0.1 | Status: invalid | Details: Token validation failed
2025-04-16 12:36:24 [DEBUG] app.after_request:34 - Request df01f1d64cd7d499 processed in 0.7008 seconds
2025-04-16 12:36:25 [DEBUG] w3_utils.verify_token_on_blockchain:318 - Traceback (most recent call last):
  File "C:\Users\prajw\AppData\Local\Programs\Python\Python313\Lib\site-packages\web3\contract\utils.py", line 207, in call_contract_function
    output_data = w3.codec.decode(output_types, return_data)
  File "C:\Users\prajw\AppData\Local\Programs\Python\Python313\Lib\site-packages\eth_abi\codec.py", line 162, in decode
    return cast(Tuple[Any, ...], decoder(stream))
                                 ~~~~~~~^^^^^^^^
  File "C:\Users\prajw\AppData\Local\Programs\Python\Python313\Lib\site-packages\eth_abi\decoding.py", line 131, in __call__
    return self.decode(stream)
           ~~~~~~~~~~~^^^^^^^^
  File "C:\Users\prajw\AppData\Local\Programs\Python\Python313\Lib\site-packages\eth_utils\functional.py", line 47, in inner
    return callback(fn(*args, **kwargs))
  File "C:\Users\prajw\AppData\Local\Programs\Python\Python313\Lib\site-packages\eth_abi\decoding.py", line 224, in decode
    self.validate_pointers(stream)
    ~~~~~~~~~~~~~~~~~~~~~~^^^^^^^^
  File "C:\Users\prajw\AppData\Local\Programs\Python\Python313\Lib\site-packages\eth_abi\decoding.py", line 218, in validate_pointers
    decoder(stream)
    ~~~~~~~^^^^^^^^
  File "C:\Users\prajw\AppData\Local\Programs\Python\Python313\Lib\site-packages\eth_abi\decoding.py", line 131, in __call__
    return self.decode(stream)
           ~~~~~~~~~~~^^^^^^^^
  File "C:\Users\prajw\AppData\Local\Programs\Python\Python313\Lib\site-packages\eth_abi\decoding.py", line 250, in decode
    raw_data = self.read_data_from_stream(stream)
  File "C:\Users\prajw\AppData\Local\Programs\Python\Python313\Lib\site-packages\eth_abi\decoding.py", line 389, in read_data_from_stream
    raise InsufficientDataBytes(
    ...<2 lines>...
    )
eth_abi.exceptions.InsufficientDataBytes: Tried to read 32 bytes, only got 0 bytes.

The above exception was the direct cause of the following exception:

Traceback (most recent call last):
  File "p:\blockchain-id-authentication\PII-Authenticator\backend\w3_utils.py", line 309, in verify_token_on_blockchain
    is_valid = contract.functions.verifyToken(user_token).call()
  File "C:\Users\prajw\AppData\Local\Programs\Python\Python313\Lib\site-packages\web3\contract\contract.py", line 291, in call
    return call_contract_function(
        self.w3,
    ...<11 lines>...
        **self.kwargs or {},
    )
  File "C:\Users\prajw\AppData\Local\Programs\Python\Python313\Lib\site-packages\web3\contract\utils.py", line 225, in call_contract_function
    raise BadFunctionCallOutput(msg) from e
web3.exceptions.BadFunctionCallOutput: Could not transact with/call contract function, is contract deployed correctly and chain synced?

2025-04-16 12:36:25 [DEBUG] token_auth.verify_token:74 - Token verification completed in 0.6866 seconds
2025-04-16 12:36:25 [INFO] token_auth.verify_token:79 - Token XKD2X7DIL4 is invalid
2025-04-16 12:36:25 [INFO] .None:0 - ACCESS: /validate_token | User: N/A | Token: XKD2X7DIL4 | IP: 127.0.0.1 | Status: invalid | Details: Token validation failed
2025-04-16 12:36:25 [DEBUG] app.after_request:34 - Request 6b2becaad32708c9 processed in 0.6870 seconds
2025-04-16 12:36:51 [INFO] token_auth.get_or_generate_token:27 - Generating token for user: test_user_1744787211851
2025-04-16 12:36:51 [DEBUG] token_auth.generate_unique_token:14 - Generated token: 85OXRI2605
2025-04-16 12:36:51 [INFO] token_auth.get_or_generate_token:27 - Generating token for user: test_user_1744787211852
2025-04-16 12:36:51 [INFO] w3_utils.verify_token_on_blockchain:288 - Verifying token on blockchain: 85OXRI2605
2025-04-16 12:36:51 [DEBUG] token_auth.generate_unique_token:14 - Generated token: BQ3FXGQGIM
2025-04-16 12:36:51 [DEBUG] w3_utils.verify_token_on_blockchain:308 - Calling verifyToken function for token: 85OXRI2605
2025-04-16 12:36:51 [INFO] w3_utils.verify_token_on_blockchain:288 - Verifying token on blockchain: BQ3FXGQGIM
2025-04-16 12:36:51 [DEBUG] w3_utils.verify_token_on_blockchain:308 - Calling verifyToken function for token: BQ3FXGQGIM
2025-04-16 12:36:51 [INFO] token_auth.get_or_generate_token:27 - Generating token for user: test_user_1744787211852
2025-04-16 12:36:51 [DEBUG] token_auth.generate_unique_token:14 - Generated token: R1ZL9K8OAS
2025-04-16 12:36:51 [INFO] w3_utils.verify_token_on_blockchain:288 - Verifying token on blockchain: R1ZL9K8OAS
2025-04-16 12:36:51 [DEBUG] w3_utils.verify_token_on_blockchain:308 - Calling verifyToken function for token: R1ZL9K8OAS
2025-04-16 12:36:52 [DEBUG] w3_utils.verify_token_on_blockchain:318 - Traceback (most recent call last):
  File "C:\Users\prajw\AppData\Local\Programs\Python\Python313\Lib\site-packages\web3\contract\utils.py", line 207, in call_contract_function
    output_data = w3.codec.decode(output_types, return_data)
  File "C:\Users\prajw\AppData\Local\Programs\Python\Python313\Lib\site-packages\eth_abi\codec.py", line 162, in decode
    return cast(Tuple[Any, ...], decoder(stream))
                                 ~~~~~~~^^^^^^^^
  File "C:\Users\prajw\AppData\Local\Programs\Python\Python313\Lib\site-packages\eth_abi\decoding.py", line 131, in __call__
    return self.decode(stream)
           ~~~~~~~~~~~^^^^^^^^
  File "C:\Users\prajw\AppData\Local\Programs\Python\Python313\Lib\site-packages\eth_utils\functional.py", line 47, in inner
    return callback(fn(*args, **kwargs))
  File "C:\Users\prajw\AppData\Local\Programs\Python\Python313\Lib\site-packages\eth_abi\decoding.py", line 224, in decode
    self.validate_pointers(stream)
    ~~~~~~~~~~~~~~~~~~~~~~^^^^^^^^
  File "C:\Users\prajw\AppData\Local\Programs\Python\Python313\Lib\site-packages\eth_abi\decoding.py", line 218, in validate_pointers
    decoder(stream)
    ~~~~~~~^^^^^^^^
  File "C:\Users\prajw\AppData\Local\Programs\Python\Python313\Lib\site-packages\eth_abi\decoding.py", line 131, in __call__
    return self.decode(stream)
           ~~~~~~~~~~~^^^^^^^^
  File "C:\Users\prajw\AppData\Local\Programs\Python\Python313\Lib\site-packages\eth_abi\decoding.py", line 250, in decode
    raw_data = self.read_data_from_stream(stream)
  File "C:\Users\prajw\AppData\Local\Programs\Python\Python313\Lib\site-packages\eth_abi\decoding.py", line 389, in read_data_from_stream
    raise InsufficientDataBytes(
    ...<2 lines>...
    )
eth_abi.exceptions.InsufficientDataBytes: Tried to read 32 bytes, only got 0 bytes.

The above exception was the direct cause of the following exception:

Traceback (most recent call last):
  File "p:\blockchain-id-authentication\PII-Authenticator\backend\w3_utils.py", line 309, in verify_token_on_blockchain
    is_valid = contract.functions.verifyToken(user_token).call()
  File "C:\Users\prajw\AppData\Local\Programs\Python\Python313\Lib\site-packages\web3\contract\contract.py", line 291, in call
    return call_contract_function(
        self.w3,
    ...<11 lines>...
        **self.kwargs or {},
    )
  File "C:\Users\prajw\AppData\Local\Programs\Python\Python313\Lib\site-packages\web3\contract\utils.py", line 225, in call_contract_function
    raise BadFunctionCallOutput(msg) from e
web3.exceptions.BadFunctionCallOutput: Could not transact with/call contract function, is contract deployed correctly and chain synced?

2025-04-16 12:36:52 [DEBUG] token_auth.get_or_generate_token:38 - Token 85OXRI2605 is unique (verified after 1 attempts)
2025-04-16 12:36:52 [INFO] w3_utils.store_token_on_blockchain:228 - Storing token on blockchain: 85OXRI2605
2025-04-16 12:36:52 [DEBUG] w3_utils.store_token_on_blockchain:250 - Building transaction for token: 85OXRI2605
2025-04-16 12:36:52 [DEBUG] w3_utils.verify_token_on_blockchain:318 - Traceback (most recent call last):
  File "C:\Users\prajw\AppData\Local\Programs\Python\Python313\Lib\site-packages\web3\contract\utils.py", line 207, in call_contract_function
    output_data = w3.codec.decode(output_types, return_data)
  File "C:\Users\prajw\AppData\Local\Programs\Python\Python313\Lib\site-packages\eth_abi\codec.py", line 162, in decode
    return cast(Tuple[Any, ...], decoder(stream))
                                 ~~~~~~~^^^^^^^^
  File "C:\Users\prajw\AppData\Local\Programs\Python\Python313\Lib\site-packages\eth_abi\decoding.py", line 131, in __call__
    return self.decode(stream)
           ~~~~~~~~~~~^^^^^^^^
  File "C:\Users\prajw\AppData\Local\Programs\Python\Python313\Lib\site-packages\eth_utils\functional.py", line 47, in inner
    return callback(fn(*args, **kwargs))
  File "C:\Users\prajw\AppData\Local\Programs\Python\Python313\Lib\site-packages\eth_abi\decoding.py", line 224, in decode
    self.validate_pointers(stream)
    ~~~~~~~~~~~~~~~~~~~~~~^^^^^^^^
  File "C:\Users\prajw\AppData\Local\Programs\Python\Python313\Lib\site-packages\eth_abi\decoding.py", line 218, in validate_pointers
    decoder(stream)
    ~~~~~~~^^^^^^^^
  File "C:\Users\prajw\AppData\Local\Programs\Python\Python313\Lib\site-packages\eth_abi\decoding.py", line 131, in __call__
    return self.decode(stream)
           ~~~~~~~~~~~^^^^^^^^
  File "C:\Users\prajw\AppData\Local\Programs\Python\Python313\Lib\site-packages\eth_abi\decoding.py", line 250, in decode
    raw_data = self.read_data_from_stream(stream)
  File "C:\Users\prajw\AppData\Local\Programs\Python\Python313\Lib\site-packages\eth_abi\decoding.py", line 389, in read_data_from_stream
    raise InsufficientDataBytes(
    ...<2 lines>...
    )
eth_abi.exceptions.InsufficientDataBytes: Tried to read 32 bytes, only got 0 bytes.

The above exception was the direct cause of the following exception:

Traceback (most recent call last):
  File "p:\blockchain-id-authentication\PII-Authenticator\backend\w3_utils.py", line 309, in verify_token_on_blockchain
    is_valid = contract.functions.verifyToken(user_token).call()
  File "C:\Users\prajw\AppData\Local\Programs\Python\Python313\Lib\site-packages\web3\contract\contract.py", line 291, in call
    return call_contract_function(
        self.w3,
    ...<11 lines>...
        **self.kwargs or {},
    )
  File "C:\Users\prajw\AppData\Local\Programs\Python\Python313\Lib\site-packages\web3\contract\utils.py", line 225, in call_contract_function
    raise BadFunctionCallOutput(msg) from e
web3.exceptions.BadFunctionCallOutput: Could not transact with/call contract function, is contract deployed correctly and chain synced?

2025-04-16 12:36:52 [DEBUG] token_auth.get_or_generate_token:38 - Token R1ZL9K8OAS is unique (verified after 1 attempts)
2025-04-16 12:36:52 [INFO] w3_utils.store_token_on_blockchain:228 - Storing token on blockchain: R1ZL9K8OAS
2025-04-16 12:36:52 [DEBUG] w3_utils.store_token_on_blockchain:250 - Building transaction for token: R1ZL9K8OAS
2025-04-16 12:36:52 [DEBUG] w3_utils.verify_token_on_blockchain:318 - Traceback (most recent call last):
  File "C:\Users\prajw\AppData\Local\Programs\Python\Python313\Lib\site-packages\web3\contract\utils.py", line 207, in call_contract_function
    output_data = w3.codec.decode(output_types, return_data)
  File "C:\Users\prajw\AppData\Local\Programs\Python\Python313\Lib\site-packages\eth_abi\codec.py", line 162, in decode
    return cast(Tuple[Any, ...], decoder(stream))
                                 ~~~~~~~^^^^^^^^
  File "C:\Users\prajw\AppData\Local\Programs\Python\Python313\Lib\site-packages\eth_abi\decoding.py", line 131, in __call__
    return self.decode(stream)
           ~~~~~~~~~~~^^^^^^^^
  File "C:\Users\prajw\AppData\Local\Programs\Python\Python313\Lib\site-packages\eth_utils\functional.py", line 47, in inner
    return callback(fn(*args, **kwargs))
  File "C:\Users\prajw\AppData\Local\Programs\Python\Python313\Lib\site-packages\eth_abi\decoding.py", line 224, in decode
    self.validate_pointers(stream)
    ~~~~~~~~~~~~~~~~~~~~~~^^^^^^^^
  File "C:\Users\prajw\AppData\Local\Programs\Python\Python313\Lib\site-packages\eth_abi\decoding.py", line 218, in validate_pointers
    decoder(stream)
    ~~~~~~~^^^^^^^^
  File "C:\Users\prajw\AppData\Local\Programs\Python\Python313\Lib\site-packages\eth_abi\decoding.py", line 131, in __call__
    return self.decode(stream)
           ~~~~~~~~~~~^^^^^^^^
  File "C:\Users\prajw\AppData\Local\Programs\Python\Python313\Lib\site-packages\eth_abi\decoding.py", line 250, in decode
    raw_data = self.read_data_from_stream(stream)
  File "C:\Users\prajw\AppData\Local\Programs\Python\Python313\Lib\site-packages\eth_abi\decoding.py", line 389, in read_data_from_stream
    raise InsufficientDataBytes(
    ...<2 lines>...
    )
eth_abi.exceptions.InsufficientDataBytes: Tried to read 32 bytes, only got 0 bytes.

The above exception was the direct cause of the following exception:

Traceback (most recent call last):
  File "p:\blockchain-id-authentication\PII-Authenticator\backend\w3_utils.py", line 309, in verify_token_on_blockchain
    is_valid = contract.functions.verifyToken(user_token).call()
  File "C:\Users\prajw\AppData\Local\Programs\Python\Python313\Lib\site-packages\web3\contract\contract.py", line 291, in call
    return call_contract_function(
        self.w3,
    ...<11 lines>...
        **self.kwargs or {},
    )
  File "C:\Users\prajw\AppData\Local\Programs\Python\Python313\Lib\site-packages\web3\contract\utils.py", line 225, in call_contract_function
    raise BadFunctionCallOutput(msg) from e
web3.exceptions.BadFunctionCallOutput: Could not transact with/call contract function, is contract deployed correctly and chain synced?

2025-04-16 12:36:52 [DEBUG] token_auth.get_or_generate_token:38 - Token BQ3FXGQGIM is unique (verified after 1 attempts)
2025-04-16 12:36:52 [INFO] w3_utils.store_token_on_blockchain:228 - Storing token on blockchain: BQ3FXGQGIM
2025-04-16 12:36:52 [DEBUG] w3_utils.store_token_on_blockchain:250 - Building transaction for token: BQ3FXGQGIM
2025-04-16 12:36:52 [DEBUG] w3_utils.store_token_on_blockchain:259 - Signing transaction...
2025-04-16 12:36:52 [DEBUG] w3_utils.store_token_on_blockchain:262 - Sending transaction to network...
2025-04-16 12:36:52 [DEBUG] w3_utils.store_token_on_blockchain:275 - Traceback (most recent call last):
  File "p:\blockchain-id-authentication\PII-Authenticator\backend\w3_utils.py", line 263, in store_token_on_blockchain
    tx_hash = web3.eth.send_raw_transaction(signed_tx.rawTransaction)
                                            ^^^^^^^^^^^^^^^^^^^^^^^^
AttributeError: 'SignedTransaction' object has no attribute 'rawTransaction'. Did you mean: 'raw_transaction'?

2025-04-16 12:36:52 [WARNING] token_auth.get_or_generate_token:50 - Failed to store token BQ3FXGQGIM on blockchain for user test_user_1744787211852
2025-04-16 12:36:52 [DEBUG] token_auth.get_or_generate_token:53 - Token generation completed in 0.9307 seconds
2025-04-16 12:36:52 [INFO] w3_utils.upload_to_filebase:140 - Uploading file BQ3FXGQGIM.txt to storage...
2025-04-16 12:36:52 [DEBUG] w3_utils.store_token_on_blockchain:259 - Signing transaction...
2025-04-16 12:36:52 [DEBUG] w3_utils.store_token_on_blockchain:262 - Sending transaction to network...
2025-04-16 12:36:52 [DEBUG] w3_utils.store_token_on_blockchain:275 - Traceback (most recent call last):
  File "p:\blockchain-id-authentication\PII-Authenticator\backend\w3_utils.py", line 263, in store_token_on_blockchain
    tx_hash = web3.eth.send_raw_transaction(signed_tx.rawTransaction)
                                            ^^^^^^^^^^^^^^^^^^^^^^^^
AttributeError: 'SignedTransaction' object has no attribute 'rawTransaction'. Did you mean: 'raw_transaction'?

2025-04-16 12:36:52 [WARNING] token_auth.get_or_generate_token:50 - Failed to store token 85OXRI2605 on blockchain for user test_user_1744787211851
2025-04-16 12:36:52 [DEBUG] token_auth.get_or_generate_token:53 - Token generation completed in 0.9474 seconds
2025-04-16 12:36:52 [INFO] w3_utils.upload_to_filebase:140 - Uploading file 85OXRI2605.txt to storage...
2025-04-16 12:36:52 [DEBUG] w3_utils.store_token_on_blockchain:259 - Signing transaction...
2025-04-16 12:36:52 [DEBUG] w3_utils.store_token_on_blockchain:262 - Sending transaction to network...
2025-04-16 12:36:52 [DEBUG] w3_utils.store_token_on_blockchain:275 - Traceback (most recent call last):
  File "p:\blockchain-id-authentication\PII-Authenticator\backend\w3_utils.py", line 263, in store_token_on_blockchain
    tx_hash = web3.eth.send_raw_transaction(signed_tx.rawTransaction)
                                            ^^^^^^^^^^^^^^^^^^^^^^^^
AttributeError: 'SignedTransaction' object has no attribute 'rawTransaction'. Did you mean: 'raw_transaction'?

2025-04-16 12:36:52 [WARNING] token_auth.get_or_generate_token:50 - Failed to store token R1ZL9K8OAS on blockchain for user test_user_1744787211852
2025-04-16 12:36:52 [DEBUG] token_auth.get_or_generate_token:53 - Token generation completed in 0.9647 seconds
2025-04-16 12:36:52 [INFO] w3_utils.upload_to_filebase:140 - Uploading file R1ZL9K8OAS.txt to storage...
2025-04-16 12:36:53 [INFO] .None:0 - ACCESS: /encrypt | User: test_user_1744787211852 | Token: BQ3FXGQGIM | IP: 127.0.0.1 | Status: success | Details: Token generated and data stored at https://s3.filebase.com/pii-authenticator-test/BQ3FXGQGIM.txt
2025-04-16 12:36:53 [INFO] .None:0 - ACCESS: /encrypt | User: test_user_1744787211851 | Token: 85OXRI2605 | IP: 127.0.0.1 | Status: success | Details: Token generated and data stored at https://s3.filebase.com/pii-authenticator-test/85OXRI2605.txt
2025-04-16 12:36:53 [DEBUG] app.after_request:34 - Request bee98575fa786559 processed in 1.5794 seconds
2025-04-16 12:36:53 [DEBUG] app.after_request:34 - Request 1724a372e48dd018 processed in 1.5804 seconds
2025-04-16 12:36:53 [INFO] token_auth.get_or_generate_token:27 - Generating token for user: test_user_1744787213438
2025-04-16 12:36:53 [DEBUG] token_auth.generate_unique_token:14 - Generated token: 14QASR890L
2025-04-16 12:36:53 [INFO] w3_utils.verify_token_on_blockchain:288 - Verifying token on blockchain: 14QASR890L
2025-04-16 12:36:53 [DEBUG] w3_utils.verify_token_on_blockchain:308 - Calling verifyToken function for token: 14QASR890L
2025-04-16 12:36:53 [INFO] token_auth.get_or_generate_token:27 - Generating token for user: test_user_1744787213438
2025-04-16 12:36:53 [DEBUG] token_auth.generate_unique_token:14 - Generated token: 88IO9WR8AU
2025-04-16 12:36:53 [INFO] w3_utils.verify_token_on_blockchain:288 - Verifying token on blockchain: 88IO9WR8AU
2025-04-16 12:36:53 [DEBUG] w3_utils.verify_token_on_blockchain:308 - Calling verifyToken function for token: 88IO9WR8AU
2025-04-16 12:36:54 [INFO] .None:0 - ACCESS: /encrypt | User: test_user_1744787211852 | Token: R1ZL9K8OAS | IP: 127.0.0.1 | Status: success | Details: Token generated and data stored at https://s3.filebase.com/pii-authenticator-test/R1ZL9K8OAS.txt
2025-04-16 12:36:54 [DEBUG] app.after_request:34 - Request 6958285b0fcc807c processed in 2.1682 seconds
2025-04-16 12:36:54 [INFO] token_auth.get_or_generate_token:27 - Generating token for user: test_user_1744787214050
2025-04-16 12:36:54 [DEBUG] token_auth.generate_unique_token:14 - Generated token: 4MJPW1N9MF
2025-04-16 12:36:54 [INFO] w3_utils.verify_token_on_blockchain:288 - Verifying token on blockchain: 4MJPW1N9MF
2025-04-16 12:36:54 [DEBUG] w3_utils.verify_token_on_blockchain:308 - Calling verifyToken function for token: 4MJPW1N9MF
2025-04-16 12:36:54 [DEBUG] w3_utils.verify_token_on_blockchain:318 - Traceback (most recent call last):
  File "C:\Users\prajw\AppData\Local\Programs\Python\Python313\Lib\site-packages\web3\contract\utils.py", line 207, in call_contract_function
    output_data = w3.codec.decode(output_types, return_data)
  File "C:\Users\prajw\AppData\Local\Programs\Python\Python313\Lib\site-packages\eth_abi\codec.py", line 162, in decode
    return cast(Tuple[Any, ...], decoder(stream))
                                 ~~~~~~~^^^^^^^^
  File "C:\Users\prajw\AppData\Local\Programs\Python\Python313\Lib\site-packages\eth_abi\decoding.py", line 131, in __call__
    return self.decode(stream)
           ~~~~~~~~~~~^^^^^^^^
  File "C:\Users\prajw\AppData\Local\Programs\Python\Python313\Lib\site-packages\eth_utils\functional.py", line 47, in inner
    return callback(fn(*args, **kwargs))
  File "C:\Users\prajw\AppData\Local\Programs\Python\Python313\Lib\site-packages\eth_abi\decoding.py", line 224, in decode
    self.validate_pointers(stream)
    ~~~~~~~~~~~~~~~~~~~~~~^^^^^^^^
  File "C:\Users\prajw\AppData\Local\Programs\Python\Python313\Lib\site-packages\eth_abi\decoding.py", line 218, in validate_pointers
    decoder(stream)
    ~~~~~~~^^^^^^^^
  File "C:\Users\prajw\AppData\Local\Programs\Python\Python313\Lib\site-packages\eth_abi\decoding.py", line 131, in __call__
    return self.decode(stream)
           ~~~~~~~~~~~^^^^^^^^
  File "C:\Users\prajw\AppData\Local\Programs\Python\Python313\Lib\site-packages\eth_abi\decoding.py", line 250, in decode
    raw_data = self.read_data_from_stream(stream)
  File "C:\Users\prajw\AppData\Local\Programs\Python\Python313\Lib\site-packages\eth_abi\decoding.py", line 389, in read_data_from_stream
    raise InsufficientDataBytes(
    ...<2 lines>...
    )
eth_abi.exceptions.InsufficientDataBytes: Tried to read 32 bytes, only got 0 bytes.

The above exception was the direct cause of the following exception:

Traceback (most recent call last):
  File "p:\blockchain-id-authentication\PII-Authenticator\backend\w3_utils.py", line 309, in verify_token_on_blockchain
    is_valid = contract.functions.verifyToken(user_token).call()
  File "C:\Users\prajw\AppData\Local\Programs\Python\Python313\Lib\site-packages\web3\contract\contract.py", line 291, in call
    return call_contract_function(
        self.w3,
    ...<11 lines>...
        **self.kwargs or {},
    )
  File "C:\Users\prajw\AppData\Local\Programs\Python\Python313\Lib\site-packages\web3\contract\utils.py", line 225, in call_contract_function
    raise BadFunctionCallOutput(msg) from e
web3.exceptions.BadFunctionCallOutput: Could not transact with/call contract function, is contract deployed correctly and chain synced?

2025-04-16 12:36:54 [DEBUG] token_auth.get_or_generate_token:38 - Token 14QASR890L is unique (verified after 1 attempts)
2025-04-16 12:36:54 [INFO] w3_utils.store_token_on_blockchain:228 - Storing token on blockchain: 14QASR890L
2025-04-16 12:36:54 [DEBUG] w3_utils.store_token_on_blockchain:250 - Building transaction for token: 14QASR890L
2025-04-16 12:36:54 [DEBUG] w3_utils.verify_token_on_blockchain:318 - Traceback (most recent call last):
  File "C:\Users\prajw\AppData\Local\Programs\Python\Python313\Lib\site-packages\web3\contract\utils.py", line 207, in call_contract_function
    output_data = w3.codec.decode(output_types, return_data)
  File "C:\Users\prajw\AppData\Local\Programs\Python\Python313\Lib\site-packages\eth_abi\codec.py", line 162, in decode
    return cast(Tuple[Any, ...], decoder(stream))
                                 ~~~~~~~^^^^^^^^
  File "C:\Users\prajw\AppData\Local\Programs\Python\Python313\Lib\site-packages\eth_abi\decoding.py", line 131, in __call__
    return self.decode(stream)
           ~~~~~~~~~~~^^^^^^^^
  File "C:\Users\prajw\AppData\Local\Programs\Python\Python313\Lib\site-packages\eth_utils\functional.py", line 47, in inner
    return callback(fn(*args, **kwargs))
  File "C:\Users\prajw\AppData\Local\Programs\Python\Python313\Lib\site-packages\eth_abi\decoding.py", line 224, in decode
    self.validate_pointers(stream)
    ~~~~~~~~~~~~~~~~~~~~~~^^^^^^^^
  File "C:\Users\prajw\AppData\Local\Programs\Python\Python313\Lib\site-packages\eth_abi\decoding.py", line 218, in validate_pointers
    decoder(stream)
    ~~~~~~~^^^^^^^^
  File "C:\Users\prajw\AppData\Local\Programs\Python\Python313\Lib\site-packages\eth_abi\decoding.py", line 131, in __call__
    return self.decode(stream)
           ~~~~~~~~~~~^^^^^^^^
  File "C:\Users\prajw\AppData\Local\Programs\Python\Python313\Lib\site-packages\eth_abi\decoding.py", line 250, in decode
    raw_data = self.read_data_from_stream(stream)
  File "C:\Users\prajw\AppData\Local\Programs\Python\Python313\Lib\site-packages\eth_abi\decoding.py", line 389, in read_data_from_stream
    raise InsufficientDataBytes(
    ...<2 lines>...
    )
eth_abi.exceptions.InsufficientDataBytes: Tried to read 32 bytes, only got 0 bytes.

The above exception was the direct cause of the following exception:

Traceback (most recent call last):
  File "p:\blockchain-id-authentication\PII-Authenticator\backend\w3_utils.py", line 309, in verify_token_on_blockchain
    is_valid = contract.functions.verifyToken(user_token).call()
  File "C:\Users\prajw\AppData\Local\Programs\Python\Python313\Lib\site-packages\web3\contract\contract.py", line 291, in call
    return call_contract_function(
        self.w3,
    ...<11 lines>...
        **self.kwargs or {},
    )
  File "C:\Users\prajw\AppData\Local\Programs\Python\Python313\Lib\site-packages\web3\contract\utils.py", line 225, in call_contract_function
    raise BadFunctionCallOutput(msg) from e
web3.exceptions.BadFunctionCallOutput: Could not transact with/call contract function, is contract deployed correctly and chain synced?

2025-04-16 12:36:54 [DEBUG] token_auth.get_or_generate_token:38 - Token 88IO9WR8AU is unique (verified after 1 attempts)
2025-04-16 12:36:54 [INFO] w3_utils.store_token_on_blockchain:228 - Storing token on blockchain: 88IO9WR8AU
2025-04-16 12:36:54 [DEBUG] w3_utils.store_token_on_blockchain:250 - Building transaction for token: 88IO9WR8AU
2025-04-16 12:36:54 [DEBUG] w3_utils.store_token_on_blockchain:259 - Signing transaction...
2025-04-16 12:36:54 [DEBUG] w3_utils.store_token_on_blockchain:262 - Sending transaction to network...
2025-04-16 12:36:54 [DEBUG] w3_utils.store_token_on_blockchain:275 - Traceback (most recent call last):
  File "p:\blockchain-id-authentication\PII-Authenticator\backend\w3_utils.py", line 263, in store_token_on_blockchain
    tx_hash = web3.eth.send_raw_transaction(signed_tx.rawTransaction)
                                            ^^^^^^^^^^^^^^^^^^^^^^^^
AttributeError: 'SignedTransaction' object has no attribute 'rawTransaction'. Did you mean: 'raw_transaction'?

2025-04-16 12:36:54 [WARNING] token_auth.get_or_generate_token:50 - Failed to store token 88IO9WR8AU on blockchain for user test_user_1744787213438
2025-04-16 12:36:54 [DEBUG] token_auth.get_or_generate_token:53 - Token generation completed in 0.9396 seconds
2025-04-16 12:36:54 [INFO] w3_utils.upload_to_filebase:140 - Uploading file 88IO9WR8AU.txt to storage...
2025-04-16 12:36:54 [DEBUG] w3_utils.store_token_on_blockchain:259 - Signing transaction...
2025-04-16 12:36:54 [DEBUG] w3_utils.store_token_on_blockchain:262 - Sending transaction to network...
2025-04-16 12:36:54 [DEBUG] w3_utils.store_token_on_blockchain:275 - Traceback (most recent call last):
  File "p:\blockchain-id-authentication\PII-Authenticator\backend\w3_utils.py", line 263, in store_token_on_blockchain
    tx_hash = web3.eth.send_raw_transaction(signed_tx.rawTransaction)
                                            ^^^^^^^^^^^^^^^^^^^^^^^^
AttributeError: 'SignedTransaction' object has no attribute 'rawTransaction'. Did you mean: 'raw_transaction'?

2025-04-16 12:36:54 [WARNING] token_auth.get_or_generate_token:50 - Failed to store token 14QASR890L on blockchain for user test_user_1744787213438
2025-04-16 12:36:54 [DEBUG] token_auth.get_or_generate_token:53 - Token generation completed in 0.9610 seconds
2025-04-16 12:36:54 [INFO] w3_utils.upload_to_filebase:140 - Uploading file 14QASR890L.txt to storage...
2025-04-16 12:36:54 [DEBUG] w3_utils.verify_token_on_blockchain:318 - Traceback (most recent call last):
  File "C:\Users\prajw\AppData\Local\Programs\Python\Python313\Lib\site-packages\web3\contract\utils.py", line 207, in call_contract_function
    output_data = w3.codec.decode(output_types, return_data)
  File "C:\Users\prajw\AppData\Local\Programs\Python\Python313\Lib\site-packages\eth_abi\codec.py", line 162, in decode
    return cast(Tuple[Any, ...], decoder(stream))
                                 ~~~~~~~^^^^^^^^
  File "C:\Users\prajw\AppData\Local\Programs\Python\Python313\Lib\site-packages\eth_abi\decoding.py", line 131, in __call__
    return self.decode(stream)
           ~~~~~~~~~~~^^^^^^^^
  File "C:\Users\prajw\AppData\Local\Programs\Python\Python313\Lib\site-packages\eth_utils\functional.py", line 47, in inner
    return callback(fn(*args, **kwargs))
  File "C:\Users\prajw\AppData\Local\Programs\Python\Python313\Lib\site-packages\eth_abi\decoding.py", line 224, in decode
    self.validate_pointers(stream)
    ~~~~~~~~~~~~~~~~~~~~~~^^^^^^^^
  File "C:\Users\prajw\AppData\Local\Programs\Python\Python313\Lib\site-packages\eth_abi\decoding.py", line 218, in validate_pointers
    decoder(stream)
    ~~~~~~~^^^^^^^^
  File "C:\Users\prajw\AppData\Local\Programs\Python\Python313\Lib\site-packages\eth_abi\decoding.py", line 131, in __call__
    return self.decode(stream)
           ~~~~~~~~~~~^^^^^^^^
  File "C:\Users\prajw\AppData\Local\Programs\Python\Python313\Lib\site-packages\eth_abi\decoding.py", line 250, in decode
    raw_data = self.read_data_from_stream(stream)
  File "C:\Users\prajw\AppData\Local\Programs\Python\Python313\Lib\site-packages\eth_abi\decoding.py", line 389, in read_data_from_stream
    raise InsufficientDataBytes(
    ...<2 lines>...
    )
eth_abi.exceptions.InsufficientDataBytes: Tried to read 32 bytes, only got 0 bytes.

The above exception was the direct cause of the following exception:

Traceback (most recent call last):
  File "p:\blockchain-id-authentication\PII-Authenticator\backend\w3_utils.py", line 309, in verify_token_on_blockchain
    is_valid = contract.functions.verifyToken(user_token).call()
  File "C:\Users\prajw\AppData\Local\Programs\Python\Python313\Lib\site-packages\web3\contract\contract.py", line 291, in call
    return call_contract_function(
        self.w3,
    ...<11 lines>...
        **self.kwargs or {},
    )
  File "C:\Users\prajw\AppData\Local\Programs\Python\Python313\Lib\site-packages\web3\contract\utils.py", line 225, in call_contract_function
    raise BadFunctionCallOutput(msg) from e
web3.exceptions.BadFunctionCallOutput: Could not transact with/call contract function, is contract deployed correctly and chain synced?

2025-04-16 12:36:54 [DEBUG] token_auth.get_or_generate_token:38 - Token 4MJPW1N9MF is unique (verified after 1 attempts)
2025-04-16 12:36:54 [INFO] w3_utils.store_token_on_blockchain:228 - Storing token on blockchain: 4MJPW1N9MF
2025-04-16 12:36:54 [DEBUG] w3_utils.store_token_on_blockchain:250 - Building transaction for token: 4MJPW1N9MF
2025-04-16 12:36:54 [DEBUG] w3_utils.store_token_on_blockchain:259 - Signing transaction...
2025-04-16 12:36:54 [DEBUG] w3_utils.store_token_on_blockchain:262 - Sending transaction to network...
2025-04-16 12:36:54 [DEBUG] w3_utils.store_token_on_blockchain:275 - Traceback (most recent call last):
  File "p:\blockchain-id-authentication\PII-Authenticator\backend\w3_utils.py", line 263, in store_token_on_blockchain
    tx_hash = web3.eth.send_raw_transaction(signed_tx.rawTransaction)
                                            ^^^^^^^^^^^^^^^^^^^^^^^^
AttributeError: 'SignedTransaction' object has no attribute 'rawTransaction'. Did you mean: 'raw_transaction'?

2025-04-16 12:36:54 [WARNING] token_auth.get_or_generate_token:50 - Failed to store token 4MJPW1N9MF on blockchain for user test_user_1744787214050
2025-04-16 12:36:54 [DEBUG] token_auth.get_or_generate_token:53 - Token generation completed in 0.8922 seconds
2025-04-16 12:36:54 [INFO] w3_utils.upload_to_filebase:140 - Uploading file 4MJPW1N9MF.txt to storage...
2025-04-16 12:36:54 [INFO] .None:0 - ACCESS: /encrypt | User: test_user_1744787213438 | Token: 88IO9WR8AU | IP: 127.0.0.1 | Status: success | Details: Token generated and data stored at https://s3.filebase.com/pii-authenticator-test/88IO9WR8AU.txt
2025-04-16 12:36:54 [DEBUG] app.after_request:34 - Request 31eb64d36f010a8b processed in 1.5329 seconds
2025-04-16 12:36:54 [INFO] .None:0 - ACCESS: /encrypt | User: test_user_1744787213438 | Token: 14QASR890L | IP: 127.0.0.1 | Status: success | Details: Token generated and data stored at https://s3.filebase.com/pii-authenticator-test/14QASR890L.txt
2025-04-16 12:36:54 [DEBUG] app.after_request:34 - Request 12e408bad7f3accc processed in 1.5513 seconds
2025-04-16 12:36:55 [INFO] token_auth.get_or_generate_token:27 - Generating token for user: test_user_1744787214978
2025-04-16 12:36:55 [DEBUG] token_auth.generate_unique_token:14 - Generated token: W4V6QRFO1O
2025-04-16 12:36:55 [INFO] w3_utils.verify_token_on_blockchain:288 - Verifying token on blockchain: W4V6QRFO1O
2025-04-16 12:36:55 [DEBUG] w3_utils.verify_token_on_blockchain:308 - Calling verifyToken function for token: W4V6QRFO1O
2025-04-16 12:36:55 [INFO] token_auth.get_or_generate_token:27 - Generating token for user: test_user_1744787214995
2025-04-16 12:36:55 [DEBUG] token_auth.generate_unique_token:14 - Generated token: CW4WD7W81F
2025-04-16 12:36:55 [INFO] w3_utils.verify_token_on_blockchain:288 - Verifying token on blockchain: CW4WD7W81F
2025-04-16 12:36:55 [DEBUG] w3_utils.verify_token_on_blockchain:308 - Calling verifyToken function for token: CW4WD7W81F
2025-04-16 12:36:55 [INFO] .None:0 - ACCESS: /encrypt | User: test_user_1744787214050 | Token: 4MJPW1N9MF | IP: 127.0.0.1 | Status: success | Details: Token generated and data stored at https://s3.filebase.com/pii-authenticator-test/4MJPW1N9MF.txt
2025-04-16 12:36:55 [DEBUG] app.after_request:34 - Request 902606fd40f7feea processed in 1.3800 seconds
2025-04-16 12:36:55 [INFO] token_auth.get_or_generate_token:27 - Generating token for user: test_user_1744787215453
2025-04-16 12:36:55 [DEBUG] token_auth.generate_unique_token:14 - Generated token: 6HRV098TDA
2025-04-16 12:36:55 [INFO] w3_utils.verify_token_on_blockchain:288 - Verifying token on blockchain: 6HRV098TDA
2025-04-16 12:36:55 [DEBUG] w3_utils.verify_token_on_blockchain:308 - Calling verifyToken function for token: 6HRV098TDA
2025-04-16 12:36:55 [DEBUG] w3_utils.verify_token_on_blockchain:318 - Traceback (most recent call last):
  File "C:\Users\prajw\AppData\Local\Programs\Python\Python313\Lib\site-packages\web3\contract\utils.py", line 207, in call_contract_function
    output_data = w3.codec.decode(output_types, return_data)
  File "C:\Users\prajw\AppData\Local\Programs\Python\Python313\Lib\site-packages\eth_abi\codec.py", line 162, in decode
    return cast(Tuple[Any, ...], decoder(stream))
                                 ~~~~~~~^^^^^^^^
  File "C:\Users\prajw\AppData\Local\Programs\Python\Python313\Lib\site-packages\eth_abi\decoding.py", line 131, in __call__
    return self.decode(stream)
           ~~~~~~~~~~~^^^^^^^^
  File "C:\Users\prajw\AppData\Local\Programs\Python\Python313\Lib\site-packages\eth_utils\functional.py", line 47, in inner
    return callback(fn(*args, **kwargs))
  File "C:\Users\prajw\AppData\Local\Programs\Python\Python313\Lib\site-packages\eth_abi\decoding.py", line 224, in decode
    self.validate_pointers(stream)
    ~~~~~~~~~~~~~~~~~~~~~~^^^^^^^^
  File "C:\Users\prajw\AppData\Local\Programs\Python\Python313\Lib\site-packages\eth_abi\decoding.py", line 218, in validate_pointers
    decoder(stream)
    ~~~~~~~^^^^^^^^
  File "C:\Users\prajw\AppData\Local\Programs\Python\Python313\Lib\site-packages\eth_abi\decoding.py", line 131, in __call__
    return self.decode(stream)
           ~~~~~~~~~~~^^^^^^^^
  File "C:\Users\prajw\AppData\Local\Programs\Python\Python313\Lib\site-packages\eth_abi\decoding.py", line 250, in decode
    raw_data = self.read_data_from_stream(stream)
  File "C:\Users\prajw\AppData\Local\Programs\Python\Python313\Lib\site-packages\eth_abi\decoding.py", line 389, in read_data_from_stream
    raise InsufficientDataBytes(
    ...<2 lines>...
    )
eth_abi.exceptions.InsufficientDataBytes: Tried to read 32 bytes, only got 0 bytes.

The above exception was the direct cause of the following exception:

Traceback (most recent call last):
  File "p:\blockchain-id-authentication\PII-Authenticator\backend\w3_utils.py", line 309, in verify_token_on_blockchain
    is_valid = contract.functions.verifyToken(user_token).call()
  File "C:\Users\prajw\AppData\Local\Programs\Python\Python313\Lib\site-packages\web3\contract\contract.py", line 291, in call
    return call_contract_function(
        self.w3,
    ...<11 lines>...
        **self.kwargs or {},
    )
  File "C:\Users\prajw\AppData\Local\Programs\Python\Python313\Lib\site-packages\web3\contract\utils.py", line 225, in call_contract_function
    raise BadFunctionCallOutput(msg) from e
web3.exceptions.BadFunctionCallOutput: Could not transact with/call contract function, is contract deployed correctly and chain synced?

2025-04-16 12:36:55 [DEBUG] token_auth.get_or_generate_token:38 - Token CW4WD7W81F is unique (verified after 1 attempts)
2025-04-16 12:36:55 [INFO] w3_utils.store_token_on_blockchain:228 - Storing token on blockchain: CW4WD7W81F
2025-04-16 12:36:55 [DEBUG] w3_utils.store_token_on_blockchain:250 - Building transaction for token: CW4WD7W81F
2025-04-16 12:36:55 [DEBUG] w3_utils.verify_token_on_blockchain:318 - Traceback (most recent call last):
  File "C:\Users\prajw\AppData\Local\Programs\Python\Python313\Lib\site-packages\web3\contract\utils.py", line 207, in call_contract_function
    output_data = w3.codec.decode(output_types, return_data)
  File "C:\Users\prajw\AppData\Local\Programs\Python\Python313\Lib\site-packages\eth_abi\codec.py", line 162, in decode
    return cast(Tuple[Any, ...], decoder(stream))
                                 ~~~~~~~^^^^^^^^
  File "C:\Users\prajw\AppData\Local\Programs\Python\Python313\Lib\site-packages\eth_abi\decoding.py", line 131, in __call__
    return self.decode(stream)
           ~~~~~~~~~~~^^^^^^^^
  File "C:\Users\prajw\AppData\Local\Programs\Python\Python313\Lib\site-packages\eth_utils\functional.py", line 47, in inner
    return callback(fn(*args, **kwargs))
  File "C:\Users\prajw\AppData\Local\Programs\Python\Python313\Lib\site-packages\eth_abi\decoding.py", line 224, in decode
    self.validate_pointers(stream)
    ~~~~~~~~~~~~~~~~~~~~~~^^^^^^^^
  File "C:\Users\prajw\AppData\Local\Programs\Python\Python313\Lib\site-packages\eth_abi\decoding.py", line 218, in validate_pointers
    decoder(stream)
    ~~~~~~~^^^^^^^^
  File "C:\Users\prajw\AppData\Local\Programs\Python\Python313\Lib\site-packages\eth_abi\decoding.py", line 131, in __call__
    return self.decode(stream)
           ~~~~~~~~~~~^^^^^^^^
  File "C:\Users\prajw\AppData\Local\Programs\Python\Python313\Lib\site-packages\eth_abi\decoding.py", line 250, in decode
    raw_data = self.read_data_from_stream(stream)
  File "C:\Users\prajw\AppData\Local\Programs\Python\Python313\Lib\site-packages\eth_abi\decoding.py", line 389, in read_data_from_stream
    raise InsufficientDataBytes(
    ...<2 lines>...
    )
eth_abi.exceptions.InsufficientDataBytes: Tried to read 32 bytes, only got 0 bytes.

The above exception was the direct cause of the following exception:

Traceback (most recent call last):
  File "p:\blockchain-id-authentication\PII-Authenticator\backend\w3_utils.py", line 309, in verify_token_on_blockchain
    is_valid = contract.functions.verifyToken(user_token).call()
  File "C:\Users\prajw\AppData\Local\Programs\Python\Python313\Lib\site-packages\web3\contract\contract.py", line 291, in call
    return call_contract_function(
        self.w3,
    ...<11 lines>...
        **self.kwargs or {},
    )
  File "C:\Users\prajw\AppData\Local\Programs\Python\Python313\Lib\site-packages\web3\contract\utils.py", line 225, in call_contract_function
    raise BadFunctionCallOutput(msg) from e
web3.exceptions.BadFunctionCallOutput: Could not transact with/call contract function, is contract deployed correctly and chain synced?

2025-04-16 12:36:55 [DEBUG] token_auth.get_or_generate_token:38 - Token W4V6QRFO1O is unique (verified after 1 attempts)
2025-04-16 12:36:55 [INFO] w3_utils.store_token_on_blockchain:228 - Storing token on blockchain: W4V6QRFO1O
2025-04-16 12:36:55 [DEBUG] w3_utils.store_token_on_blockchain:250 - Building transaction for token: W4V6QRFO1O
2025-04-16 12:36:55 [DEBUG] w3_utils.store_token_on_blockchain:259 - Signing transaction...
2025-04-16 12:36:55 [DEBUG] w3_utils.store_token_on_blockchain:259 - Signing transaction...
2025-04-16 12:36:55 [DEBUG] w3_utils.store_token_on_blockchain:262 - Sending transaction to network...
2025-04-16 12:36:55 [DEBUG] w3_utils.store_token_on_blockchain:262 - Sending transaction to network...
2025-04-16 12:36:55 [DEBUG] w3_utils.store_token_on_blockchain:275 - Traceback (most recent call last):
  File "p:\blockchain-id-authentication\PII-Authenticator\backend\w3_utils.py", line 263, in store_token_on_blockchain
    tx_hash = web3.eth.send_raw_transaction(signed_tx.rawTransaction)
                                            ^^^^^^^^^^^^^^^^^^^^^^^^
AttributeError: 'SignedTransaction' object has no attribute 'rawTransaction'. Did you mean: 'raw_transaction'?

2025-04-16 12:36:55 [WARNING] token_auth.get_or_generate_token:50 - Failed to store token CW4WD7W81F on blockchain for user test_user_1744787214995
2025-04-16 12:36:55 [DEBUG] token_auth.get_or_generate_token:53 - Token generation completed in 0.9240 seconds
2025-04-16 12:36:55 [INFO] w3_utils.upload_to_filebase:140 - Uploading file CW4WD7W81F.txt to storage...
2025-04-16 12:36:55 [DEBUG] w3_utils.store_token_on_blockchain:275 - Traceback (most recent call last):
  File "p:\blockchain-id-authentication\PII-Authenticator\backend\w3_utils.py", line 263, in store_token_on_blockchain
    tx_hash = web3.eth.send_raw_transaction(signed_tx.rawTransaction)
                                            ^^^^^^^^^^^^^^^^^^^^^^^^
AttributeError: 'SignedTransaction' object has no attribute 'rawTransaction'. Did you mean: 'raw_transaction'?

2025-04-16 12:36:55 [WARNING] token_auth.get_or_generate_token:50 - Failed to store token W4V6QRFO1O on blockchain for user test_user_1744787214978
2025-04-16 12:36:55 [DEBUG] token_auth.get_or_generate_token:53 - Token generation completed in 0.9430 seconds
2025-04-16 12:36:55 [INFO] w3_utils.upload_to_filebase:140 - Uploading file W4V6QRFO1O.txt to storage...
2025-04-16 12:36:56 [DEBUG] w3_utils.verify_token_on_blockchain:318 - Traceback (most recent call last):
  File "C:\Users\prajw\AppData\Local\Programs\Python\Python313\Lib\site-packages\web3\contract\utils.py", line 207, in call_contract_function
    output_data = w3.codec.decode(output_types, return_data)
  File "C:\Users\prajw\AppData\Local\Programs\Python\Python313\Lib\site-packages\eth_abi\codec.py", line 162, in decode
    return cast(Tuple[Any, ...], decoder(stream))
                                 ~~~~~~~^^^^^^^^
  File "C:\Users\prajw\AppData\Local\Programs\Python\Python313\Lib\site-packages\eth_abi\decoding.py", line 131, in __call__
    return self.decode(stream)
           ~~~~~~~~~~~^^^^^^^^
  File "C:\Users\prajw\AppData\Local\Programs\Python\Python313\Lib\site-packages\eth_utils\functional.py", line 47, in inner
    return callback(fn(*args, **kwargs))
  File "C:\Users\prajw\AppData\Local\Programs\Python\Python313\Lib\site-packages\eth_abi\decoding.py", line 224, in decode
    self.validate_pointers(stream)
    ~~~~~~~~~~~~~~~~~~~~~~^^^^^^^^
  File "C:\Users\prajw\AppData\Local\Programs\Python\Python313\Lib\site-packages\eth_abi\decoding.py", line 218, in validate_pointers
    decoder(stream)
    ~~~~~~~^^^^^^^^
  File "C:\Users\prajw\AppData\Local\Programs\Python\Python313\Lib\site-packages\eth_abi\decoding.py", line 131, in __call__
    return self.decode(stream)
           ~~~~~~~~~~~^^^^^^^^
  File "C:\Users\prajw\AppData\Local\Programs\Python\Python313\Lib\site-packages\eth_abi\decoding.py", line 250, in decode
    raw_data = self.read_data_from_stream(stream)
  File "C:\Users\prajw\AppData\Local\Programs\Python\Python313\Lib\site-packages\eth_abi\decoding.py", line 389, in read_data_from_stream
    raise InsufficientDataBytes(
    ...<2 lines>...
    )
eth_abi.exceptions.InsufficientDataBytes: Tried to read 32 bytes, only got 0 bytes.

The above exception was the direct cause of the following exception:

Traceback (most recent call last):
  File "p:\blockchain-id-authentication\PII-Authenticator\backend\w3_utils.py", line 309, in verify_token_on_blockchain
    is_valid = contract.functions.verifyToken(user_token).call()
  File "C:\Users\prajw\AppData\Local\Programs\Python\Python313\Lib\site-packages\web3\contract\contract.py", line 291, in call
    return call_contract_function(
        self.w3,
    ...<11 lines>...
        **self.kwargs or {},
    )
  File "C:\Users\prajw\AppData\Local\Programs\Python\Python313\Lib\site-packages\web3\contract\utils.py", line 225, in call_contract_function
    raise BadFunctionCallOutput(msg) from e
web3.exceptions.BadFunctionCallOutput: Could not transact with/call contract function, is contract deployed correctly and chain synced?

2025-04-16 12:36:56 [DEBUG] token_auth.get_or_generate_token:38 - Token 6HRV098TDA is unique (verified after 1 attempts)
2025-04-16 12:36:56 [INFO] w3_utils.store_token_on_blockchain:228 - Storing token on blockchain: 6HRV098TDA
2025-04-16 12:36:56 [DEBUG] w3_utils.store_token_on_blockchain:250 - Building transaction for token: 6HRV098TDA
2025-04-16 12:36:56 [DEBUG] w3_utils.store_token_on_blockchain:259 - Signing transaction...
2025-04-16 12:36:56 [DEBUG] w3_utils.store_token_on_blockchain:262 - Sending transaction to network...
2025-04-16 12:36:56 [DEBUG] w3_utils.store_token_on_blockchain:275 - Traceback (most recent call last):
  File "p:\blockchain-id-authentication\PII-Authenticator\backend\w3_utils.py", line 263, in store_token_on_blockchain
    tx_hash = web3.eth.send_raw_transaction(signed_tx.rawTransaction)
                                            ^^^^^^^^^^^^^^^^^^^^^^^^
AttributeError: 'SignedTransaction' object has no attribute 'rawTransaction'. Did you mean: 'raw_transaction'?

2025-04-16 12:36:56 [WARNING] token_auth.get_or_generate_token:50 - Failed to store token 6HRV098TDA on blockchain for user test_user_1744787215453
2025-04-16 12:36:56 [DEBUG] token_auth.get_or_generate_token:53 - Token generation completed in 0.9378 seconds
2025-04-16 12:36:56 [INFO] w3_utils.upload_to_filebase:140 - Uploading file 6HRV098TDA.txt to storage...
2025-04-16 12:36:56 [INFO] .None:0 - ACCESS: /encrypt | User: test_user_1744787214978 | Token: W4V6QRFO1O | IP: 127.0.0.1 | Status: success | Details: Token generated and data stored at https://s3.filebase.com/pii-authenticator-test/W4V6QRFO1O.txt
2025-04-16 12:36:56 [DEBUG] app.after_request:34 - Request b27e1e552efdedc8 processed in 1.5221 seconds
2025-04-16 12:36:56 [INFO] .None:0 - ACCESS: /encrypt | User: test_user_1744787214995 | Token: CW4WD7W81F | IP: 127.0.0.1 | Status: success | Details: Token generated and data stored at https://s3.filebase.com/pii-authenticator-test/CW4WD7W81F.txt
2025-04-16 12:36:56 [DEBUG] app.after_request:34 - Request 33ab596de2406374 processed in 1.5121 seconds
2025-04-16 12:36:56 [INFO] token_auth.get_or_generate_token:27 - Generating token for user: test_user_1744787216526
2025-04-16 12:36:56 [DEBUG] token_auth.generate_unique_token:14 - Generated token: 2JYR34CV9W
2025-04-16 12:36:56 [INFO] w3_utils.verify_token_on_blockchain:288 - Verifying token on blockchain: 2JYR34CV9W
2025-04-16 12:36:56 [DEBUG] w3_utils.verify_token_on_blockchain:308 - Calling verifyToken function for token: 2JYR34CV9W
2025-04-16 12:36:57 [INFO] .None:0 - ACCESS: /encrypt | User: test_user_1744787215453 | Token: 6HRV098TDA | IP: 127.0.0.1 | Status: success | Details: Token generated and data stored at https://s3.filebase.com/pii-authenticator-test/6HRV098TDA.txt
2025-04-16 12:36:57 [DEBUG] app.after_request:34 - Request 87631989c79c9006 processed in 1.5424 seconds
2025-04-16 12:36:57 [DEBUG] w3_utils.verify_token_on_blockchain:318 - Traceback (most recent call last):
  File "C:\Users\prajw\AppData\Local\Programs\Python\Python313\Lib\site-packages\web3\contract\utils.py", line 207, in call_contract_function
    output_data = w3.codec.decode(output_types, return_data)
  File "C:\Users\prajw\AppData\Local\Programs\Python\Python313\Lib\site-packages\eth_abi\codec.py", line 162, in decode
    return cast(Tuple[Any, ...], decoder(stream))
                                 ~~~~~~~^^^^^^^^
  File "C:\Users\prajw\AppData\Local\Programs\Python\Python313\Lib\site-packages\eth_abi\decoding.py", line 131, in __call__
    return self.decode(stream)
           ~~~~~~~~~~~^^^^^^^^
  File "C:\Users\prajw\AppData\Local\Programs\Python\Python313\Lib\site-packages\eth_utils\functional.py", line 47, in inner
    return callback(fn(*args, **kwargs))
  File "C:\Users\prajw\AppData\Local\Programs\Python\Python313\Lib\site-packages\eth_abi\decoding.py", line 224, in decode
    self.validate_pointers(stream)
    ~~~~~~~~~~~~~~~~~~~~~~^^^^^^^^
  File "C:\Users\prajw\AppData\Local\Programs\Python\Python313\Lib\site-packages\eth_abi\decoding.py", line 218, in validate_pointers
    decoder(stream)
    ~~~~~~~^^^^^^^^
  File "C:\Users\prajw\AppData\Local\Programs\Python\Python313\Lib\site-packages\eth_abi\decoding.py", line 131, in __call__
    return self.decode(stream)
           ~~~~~~~~~~~^^^^^^^^
  File "C:\Users\prajw\AppData\Local\Programs\Python\Python313\Lib\site-packages\eth_abi\decoding.py", line 250, in decode
    raw_data = self.read_data_from_stream(stream)
  File "C:\Users\prajw\AppData\Local\Programs\Python\Python313\Lib\site-packages\eth_abi\decoding.py", line 389, in read_data_from_stream
    raise InsufficientDataBytes(
    ...<2 lines>...
    )
eth_abi.exceptions.InsufficientDataBytes: Tried to read 32 bytes, only got 0 bytes.

The above exception was the direct cause of the following exception:

Traceback (most recent call last):
  File "p:\blockchain-id-authentication\PII-Authenticator\backend\w3_utils.py", line 309, in verify_token_on_blockchain
    is_valid = contract.functions.verifyToken(user_token).call()
  File "C:\Users\prajw\AppData\Local\Programs\Python\Python313\Lib\site-packages\web3\contract\contract.py", line 291, in call
    return call_contract_function(
        self.w3,
    ...<11 lines>...
        **self.kwargs or {},
    )
  File "C:\Users\prajw\AppData\Local\Programs\Python\Python313\Lib\site-packages\web3\contract\utils.py", line 225, in call_contract_function
    raise BadFunctionCallOutput(msg) from e
web3.exceptions.BadFunctionCallOutput: Could not transact with/call contract function, is contract deployed correctly and chain synced?

2025-04-16 12:36:57 [DEBUG] token_auth.get_or_generate_token:38 - Token 2JYR34CV9W is unique (verified after 1 attempts)
2025-04-16 12:36:57 [INFO] w3_utils.store_token_on_blockchain:228 - Storing token on blockchain: 2JYR34CV9W
2025-04-16 12:36:57 [DEBUG] w3_utils.store_token_on_blockchain:250 - Building transaction for token: 2JYR34CV9W
2025-04-16 12:36:57 [DEBUG] w3_utils.store_token_on_blockchain:259 - Signing transaction...
2025-04-16 12:36:57 [DEBUG] w3_utils.store_token_on_blockchain:262 - Sending transaction to network...
2025-04-16 12:36:57 [DEBUG] w3_utils.store_token_on_blockchain:275 - Traceback (most recent call last):
  File "p:\blockchain-id-authentication\PII-Authenticator\backend\w3_utils.py", line 263, in store_token_on_blockchain
    tx_hash = web3.eth.send_raw_transaction(signed_tx.rawTransaction)
                                            ^^^^^^^^^^^^^^^^^^^^^^^^
AttributeError: 'SignedTransaction' object has no attribute 'rawTransaction'. Did you mean: 'raw_transaction'?

2025-04-16 12:36:57 [WARNING] token_auth.get_or_generate_token:50 - Failed to store token 2JYR34CV9W on blockchain for user test_user_1744787216526
2025-04-16 12:36:57 [DEBUG] token_auth.get_or_generate_token:53 - Token generation completed in 0.9259 seconds
2025-04-16 12:36:57 [INFO] w3_utils.upload_to_filebase:140 - Uploading file 2JYR34CV9W.txt to storage...
2025-04-16 12:36:58 [INFO] .None:0 - ACCESS: /encrypt | User: test_user_1744787216526 | Token: 2JYR34CV9W | IP: 127.0.0.1 | Status: success | Details: Token generated and data stored at https://s3.filebase.com/pii-authenticator-test/2JYR34CV9W.txt
2025-04-16 12:36:58 [DEBUG] app.after_request:34 - Request 43eca6854af465ae processed in 1.5312 seconds
2025-04-16 12:36:58 [INFO] token_auth.verify_token:67 - Verifying token: BQ3FXGQGIM
2025-04-16 12:36:58 [INFO] w3_utils.verify_token_on_blockchain:288 - Verifying token on blockchain: BQ3FXGQGIM
2025-04-16 12:36:58 [DEBUG] w3_utils.verify_token_on_blockchain:308 - Calling verifyToken function for token: BQ3FXGQGIM
2025-04-16 12:36:58 [INFO] token_auth.verify_token:67 - Verifying token: 14QASR890L
2025-04-16 12:36:58 [INFO] w3_utils.verify_token_on_blockchain:288 - Verifying token on blockchain: 14QASR890L
2025-04-16 12:36:58 [DEBUG] w3_utils.verify_token_on_blockchain:308 - Calling verifyToken function for token: 14QASR890L
2025-04-16 12:36:58 [INFO] token_auth.verify_token:67 - Verifying token: INVALID1744787218105
2025-04-16 12:36:58 [INFO] w3_utils.verify_token_on_blockchain:288 - Verifying token on blockchain: INVALID1744787218105
2025-04-16 12:36:58 [DEBUG] w3_utils.verify_token_on_blockchain:308 - Calling verifyToken function for token: INVALID1744787218105
2025-04-16 12:36:58 [DEBUG] w3_utils.verify_token_on_blockchain:318 - Traceback (most recent call last):
  File "C:\Users\prajw\AppData\Local\Programs\Python\Python313\Lib\site-packages\web3\contract\utils.py", line 207, in call_contract_function
    output_data = w3.codec.decode(output_types, return_data)
  File "C:\Users\prajw\AppData\Local\Programs\Python\Python313\Lib\site-packages\eth_abi\codec.py", line 162, in decode
    return cast(Tuple[Any, ...], decoder(stream))
                                 ~~~~~~~^^^^^^^^
  File "C:\Users\prajw\AppData\Local\Programs\Python\Python313\Lib\site-packages\eth_abi\decoding.py", line 131, in __call__
    return self.decode(stream)
           ~~~~~~~~~~~^^^^^^^^
  File "C:\Users\prajw\AppData\Local\Programs\Python\Python313\Lib\site-packages\eth_utils\functional.py", line 47, in inner
    return callback(fn(*args, **kwargs))
  File "C:\Users\prajw\AppData\Local\Programs\Python\Python313\Lib\site-packages\eth_abi\decoding.py", line 224, in decode
    self.validate_pointers(stream)
    ~~~~~~~~~~~~~~~~~~~~~~^^^^^^^^
  File "C:\Users\prajw\AppData\Local\Programs\Python\Python313\Lib\site-packages\eth_abi\decoding.py", line 218, in validate_pointers
    decoder(stream)
    ~~~~~~~^^^^^^^^
  File "C:\Users\prajw\AppData\Local\Programs\Python\Python313\Lib\site-packages\eth_abi\decoding.py", line 131, in __call__
    return self.decode(stream)
           ~~~~~~~~~~~^^^^^^^^
  File "C:\Users\prajw\AppData\Local\Programs\Python\Python313\Lib\site-packages\eth_abi\decoding.py", line 250, in decode
    raw_data = self.read_data_from_stream(stream)
  File "C:\Users\prajw\AppData\Local\Programs\Python\Python313\Lib\site-packages\eth_abi\decoding.py", line 389, in read_data_from_stream
    raise InsufficientDataBytes(
    ...<2 lines>...
    )
eth_abi.exceptions.InsufficientDataBytes: Tried to read 32 bytes, only got 0 bytes.

The above exception was the direct cause of the following exception:

Traceback (most recent call last):
  File "p:\blockchain-id-authentication\PII-Authenticator\backend\w3_utils.py", line 309, in verify_token_on_blockchain
    is_valid = contract.functions.verifyToken(user_token).call()
  File "C:\Users\prajw\AppData\Local\Programs\Python\Python313\Lib\site-packages\web3\contract\contract.py", line 291, in call
    return call_contract_function(
        self.w3,
    ...<11 lines>...
        **self.kwargs or {},
    )
  File "C:\Users\prajw\AppData\Local\Programs\Python\Python313\Lib\site-packages\web3\contract\utils.py", line 225, in call_contract_function
    raise BadFunctionCallOutput(msg) from e
web3.exceptions.BadFunctionCallOutput: Could not transact with/call contract function, is contract deployed correctly and chain synced?

2025-04-16 12:36:58 [DEBUG] token_auth.verify_token:74 - Token verification completed in 0.6438 seconds
2025-04-16 12:36:58 [INFO] token_auth.verify_token:79 - Token INVALID1744787218105 is invalid
2025-04-16 12:36:58 [INFO] .None:0 - ACCESS: /validate_token | User: N/A | Token: INVALID1744787218105 | IP: 127.0.0.1 | Status: invalid | Details: Token validation failed
2025-04-16 12:36:58 [DEBUG] app.after_request:34 - Request 9b5b67458d91e1df processed in 0.6443 seconds
2025-04-16 12:36:58 [DEBUG] w3_utils.verify_token_on_blockchain:318 - Traceback (most recent call last):
  File "C:\Users\prajw\AppData\Local\Programs\Python\Python313\Lib\site-packages\web3\contract\utils.py", line 207, in call_contract_function
    output_data = w3.codec.decode(output_types, return_data)
  File "C:\Users\prajw\AppData\Local\Programs\Python\Python313\Lib\site-packages\eth_abi\codec.py", line 162, in decode
    return cast(Tuple[Any, ...], decoder(stream))
                                 ~~~~~~~^^^^^^^^
  File "C:\Users\prajw\AppData\Local\Programs\Python\Python313\Lib\site-packages\eth_abi\decoding.py", line 131, in __call__
    return self.decode(stream)
           ~~~~~~~~~~~^^^^^^^^
  File "C:\Users\prajw\AppData\Local\Programs\Python\Python313\Lib\site-packages\eth_utils\functional.py", line 47, in inner
    return callback(fn(*args, **kwargs))
  File "C:\Users\prajw\AppData\Local\Programs\Python\Python313\Lib\site-packages\eth_abi\decoding.py", line 224, in decode
    self.validate_pointers(stream)
    ~~~~~~~~~~~~~~~~~~~~~~^^^^^^^^
  File "C:\Users\prajw\AppData\Local\Programs\Python\Python313\Lib\site-packages\eth_abi\decoding.py", line 218, in validate_pointers
    decoder(stream)
    ~~~~~~~^^^^^^^^
  File "C:\Users\prajw\AppData\Local\Programs\Python\Python313\Lib\site-packages\eth_abi\decoding.py", line 131, in __call__
    return self.decode(stream)
           ~~~~~~~~~~~^^^^^^^^
  File "C:\Users\prajw\AppData\Local\Programs\Python\Python313\Lib\site-packages\eth_abi\decoding.py", line 250, in decode
    raw_data = self.read_data_from_stream(stream)
  File "C:\Users\prajw\AppData\Local\Programs\Python\Python313\Lib\site-packages\eth_abi\decoding.py", line 389, in read_data_from_stream
    raise InsufficientDataBytes(
    ...<2 lines>...
    )
eth_abi.exceptions.InsufficientDataBytes: Tried to read 32 bytes, only got 0 bytes.

The above exception was the direct cause of the following exception:

Traceback (most recent call last):
  File "p:\blockchain-id-authentication\PII-Authenticator\backend\w3_utils.py", line 309, in verify_token_on_blockchain
    is_valid = contract.functions.verifyToken(user_token).call()
  File "C:\Users\prajw\AppData\Local\Programs\Python\Python313\Lib\site-packages\web3\contract\contract.py", line 291, in call
    return call_contract_function(
        self.w3,
    ...<11 lines>...
        **self.kwargs or {},
    )
  File "C:\Users\prajw\AppData\Local\Programs\Python\Python313\Lib\site-packages\web3\contract\utils.py", line 225, in call_contract_function
    raise BadFunctionCallOutput(msg) from e
web3.exceptions.BadFunctionCallOutput: Could not transact with/call contract function, is contract deployed correctly and chain synced?

2025-04-16 12:36:58 [DEBUG] token_auth.verify_token:74 - Token verification completed in 0.6650 seconds
2025-04-16 12:36:58 [INFO] token_auth.verify_token:79 - Token 14QASR890L is invalid
2025-04-16 12:36:58 [INFO] .None:0 - ACCESS: /validate_token | User: N/A | Token: 14QASR890L | IP: 127.0.0.1 | Status: invalid | Details: Token validation failed
2025-04-16 12:36:58 [DEBUG] app.after_request:34 - Request 0dafc66b5603300d processed in 0.6655 seconds
2025-04-16 12:36:58 [DEBUG] w3_utils.verify_token_on_blockchain:318 - Traceback (most recent call last):
  File "C:\Users\prajw\AppData\Local\Programs\Python\Python313\Lib\site-packages\web3\contract\utils.py", line 207, in call_contract_function
    output_data = w3.codec.decode(output_types, return_data)
  File "C:\Users\prajw\AppData\Local\Programs\Python\Python313\Lib\site-packages\eth_abi\codec.py", line 162, in decode
    return cast(Tuple[Any, ...], decoder(stream))
                                 ~~~~~~~^^^^^^^^
  File "C:\Users\prajw\AppData\Local\Programs\Python\Python313\Lib\site-packages\eth_abi\decoding.py", line 131, in __call__
    return self.decode(stream)
           ~~~~~~~~~~~^^^^^^^^
  File "C:\Users\prajw\AppData\Local\Programs\Python\Python313\Lib\site-packages\eth_utils\functional.py", line 47, in inner
    return callback(fn(*args, **kwargs))
  File "C:\Users\prajw\AppData\Local\Programs\Python\Python313\Lib\site-packages\eth_abi\decoding.py", line 224, in decode
    self.validate_pointers(stream)
    ~~~~~~~~~~~~~~~~~~~~~~^^^^^^^^
  File "C:\Users\prajw\AppData\Local\Programs\Python\Python313\Lib\site-packages\eth_abi\decoding.py", line 218, in validate_pointers
    decoder(stream)
    ~~~~~~~^^^^^^^^
  File "C:\Users\prajw\AppData\Local\Programs\Python\Python313\Lib\site-packages\eth_abi\decoding.py", line 131, in __call__
    return self.decode(stream)
           ~~~~~~~~~~~^^^^^^^^
  File "C:\Users\prajw\AppData\Local\Programs\Python\Python313\Lib\site-packages\eth_abi\decoding.py", line 250, in decode
    raw_data = self.read_data_from_stream(stream)
  File "C:\Users\prajw\AppData\Local\Programs\Python\Python313\Lib\site-packages\eth_abi\decoding.py", line 389, in read_data_from_stream
    raise InsufficientDataBytes(
    ...<2 lines>...
    )
eth_abi.exceptions.InsufficientDataBytes: Tried to read 32 bytes, only got 0 bytes.

The above exception was the direct cause of the following exception:

Traceback (most recent call last):
  File "p:\blockchain-id-authentication\PII-Authenticator\backend\w3_utils.py", line 309, in verify_token_on_blockchain
    is_valid = contract.functions.verifyToken(user_token).call()
  File "C:\Users\prajw\AppData\Local\Programs\Python\Python313\Lib\site-packages\web3\contract\contract.py", line 291, in call
    return call_contract_function(
        self.w3,
    ...<11 lines>...
        **self.kwargs or {},
    )
  File "C:\Users\prajw\AppData\Local\Programs\Python\Python313\Lib\site-packages\web3\contract\utils.py", line 225, in call_contract_function
    raise BadFunctionCallOutput(msg) from e
web3.exceptions.BadFunctionCallOutput: Could not transact with/call contract function, is contract deployed correctly and chain synced?

2025-04-16 12:36:58 [DEBUG] token_auth.verify_token:74 - Token verification completed in 0.6732 seconds
2025-04-16 12:36:58 [INFO] token_auth.verify_token:79 - Token BQ3FXGQGIM is invalid
2025-04-16 12:36:58 [INFO] .None:0 - ACCESS: /validate_token | User: N/A | Token: BQ3FXGQGIM | IP: 127.0.0.1 | Status: invalid | Details: Token validation failed
2025-04-16 12:36:58 [DEBUG] app.after_request:34 - Request 6aa1f06b1de6bc1d processed in 0.6737 seconds
2025-04-16 12:36:58 [INFO] token_auth.verify_token:67 - Verifying token: INVALID1744787218764
2025-04-16 12:36:58 [INFO] w3_utils.verify_token_on_blockchain:288 - Verifying token on blockchain: INVALID1744787218764
2025-04-16 12:36:58 [DEBUG] w3_utils.verify_token_on_blockchain:308 - Calling verifyToken function for token: INVALID1744787218764
2025-04-16 12:36:58 [INFO] token_auth.verify_token:67 - Verifying token: 2JYR34CV9W
2025-04-16 12:36:58 [INFO] token_auth.verify_token:67 - Verifying token: 85OXRI2605
2025-04-16 12:36:58 [INFO] w3_utils.verify_token_on_blockchain:288 - Verifying token on blockchain: 2JYR34CV9W
2025-04-16 12:36:58 [DEBUG] w3_utils.verify_token_on_blockchain:308 - Calling verifyToken function for token: 2JYR34CV9W
2025-04-16 12:36:58 [INFO] w3_utils.verify_token_on_blockchain:288 - Verifying token on blockchain: 85OXRI2605
2025-04-16 12:36:58 [DEBUG] w3_utils.verify_token_on_blockchain:308 - Calling verifyToken function for token: 85OXRI2605
2025-04-16 12:36:59 [DEBUG] w3_utils.verify_token_on_blockchain:318 - Traceback (most recent call last):
  File "C:\Users\prajw\AppData\Local\Programs\Python\Python313\Lib\site-packages\web3\contract\utils.py", line 207, in call_contract_function
    output_data = w3.codec.decode(output_types, return_data)
  File "C:\Users\prajw\AppData\Local\Programs\Python\Python313\Lib\site-packages\eth_abi\codec.py", line 162, in decode
    return cast(Tuple[Any, ...], decoder(stream))
                                 ~~~~~~~^^^^^^^^
  File "C:\Users\prajw\AppData\Local\Programs\Python\Python313\Lib\site-packages\eth_abi\decoding.py", line 131, in __call__
    return self.decode(stream)
           ~~~~~~~~~~~^^^^^^^^
  File "C:\Users\prajw\AppData\Local\Programs\Python\Python313\Lib\site-packages\eth_utils\functional.py", line 47, in inner
    return callback(fn(*args, **kwargs))
  File "C:\Users\prajw\AppData\Local\Programs\Python\Python313\Lib\site-packages\eth_abi\decoding.py", line 224, in decode
    self.validate_pointers(stream)
    ~~~~~~~~~~~~~~~~~~~~~~^^^^^^^^
  File "C:\Users\prajw\AppData\Local\Programs\Python\Python313\Lib\site-packages\eth_abi\decoding.py", line 218, in validate_pointers
    decoder(stream)
    ~~~~~~~^^^^^^^^
  File "C:\Users\prajw\AppData\Local\Programs\Python\Python313\Lib\site-packages\eth_abi\decoding.py", line 131, in __call__
    return self.decode(stream)
           ~~~~~~~~~~~^^^^^^^^
  File "C:\Users\prajw\AppData\Local\Programs\Python\Python313\Lib\site-packages\eth_abi\decoding.py", line 250, in decode
    raw_data = self.read_data_from_stream(stream)
  File "C:\Users\prajw\AppData\Local\Programs\Python\Python313\Lib\site-packages\eth_abi\decoding.py", line 389, in read_data_from_stream
    raise InsufficientDataBytes(
    ...<2 lines>...
    )
eth_abi.exceptions.InsufficientDataBytes: Tried to read 32 bytes, only got 0 bytes.

The above exception was the direct cause of the following exception:

Traceback (most recent call last):
  File "p:\blockchain-id-authentication\PII-Authenticator\backend\w3_utils.py", line 309, in verify_token_on_blockchain
    is_valid = contract.functions.verifyToken(user_token).call()
  File "C:\Users\prajw\AppData\Local\Programs\Python\Python313\Lib\site-packages\web3\contract\contract.py", line 291, in call
    return call_contract_function(
        self.w3,
    ...<11 lines>...
        **self.kwargs or {},
    )
  File "C:\Users\prajw\AppData\Local\Programs\Python\Python313\Lib\site-packages\web3\contract\utils.py", line 225, in call_contract_function
    raise BadFunctionCallOutput(msg) from e
web3.exceptions.BadFunctionCallOutput: Could not transact with/call contract function, is contract deployed correctly and chain synced?

2025-04-16 12:36:59 [DEBUG] token_auth.verify_token:74 - Token verification completed in 0.7009 seconds
2025-04-16 12:36:59 [INFO] token_auth.verify_token:79 - Token INVALID1744787218764 is invalid
2025-04-16 12:36:59 [INFO] .None:0 - ACCESS: /validate_token | User: N/A | Token: INVALID1744787218764 | IP: 127.0.0.1 | Status: invalid | Details: Token validation failed
2025-04-16 12:36:59 [DEBUG] app.after_request:34 - Request 15e796e6dd14c562 processed in 0.7016 seconds
2025-04-16 12:36:59 [DEBUG] w3_utils.verify_token_on_blockchain:318 - Traceback (most recent call last):
  File "C:\Users\prajw\AppData\Local\Programs\Python\Python313\Lib\site-packages\web3\contract\utils.py", line 207, in call_contract_function
    output_data = w3.codec.decode(output_types, return_data)
  File "C:\Users\prajw\AppData\Local\Programs\Python\Python313\Lib\site-packages\eth_abi\codec.py", line 162, in decode
    return cast(Tuple[Any, ...], decoder(stream))
                                 ~~~~~~~^^^^^^^^
  File "C:\Users\prajw\AppData\Local\Programs\Python\Python313\Lib\site-packages\eth_abi\decoding.py", line 131, in __call__
    return self.decode(stream)
           ~~~~~~~~~~~^^^^^^^^
  File "C:\Users\prajw\AppData\Local\Programs\Python\Python313\Lib\site-packages\eth_utils\functional.py", line 47, in inner
    return callback(fn(*args, **kwargs))
  File "C:\Users\prajw\AppData\Local\Programs\Python\Python313\Lib\site-packages\eth_abi\decoding.py", line 224, in decode
    self.validate_pointers(stream)
    ~~~~~~~~~~~~~~~~~~~~~~^^^^^^^^
  File "C:\Users\prajw\AppData\Local\Programs\Python\Python313\Lib\site-packages\eth_abi\decoding.py", line 218, in validate_pointers
    decoder(stream)
    ~~~~~~~^^^^^^^^
  File "C:\Users\prajw\AppData\Local\Programs\Python\Python313\Lib\site-packages\eth_abi\decoding.py", line 131, in __call__
    return self.decode(stream)
           ~~~~~~~~~~~^^^^^^^^
  File "C:\Users\prajw\AppData\Local\Programs\Python\Python313\Lib\site-packages\eth_abi\decoding.py", line 250, in decode
    raw_data = self.read_data_from_stream(stream)
  File "C:\Users\prajw\AppData\Local\Programs\Python\Python313\Lib\site-packages\eth_abi\decoding.py", line 389, in read_data_from_stream
    raise InsufficientDataBytes(
    ...<2 lines>...
    )
eth_abi.exceptions.InsufficientDataBytes: Tried to read 32 bytes, only got 0 bytes.

The above exception was the direct cause of the following exception:

Traceback (most recent call last):
  File "p:\blockchain-id-authentication\PII-Authenticator\backend\w3_utils.py", line 309, in verify_token_on_blockchain
    is_valid = contract.functions.verifyToken(user_token).call()
  File "C:\Users\prajw\AppData\Local\Programs\Python\Python313\Lib\site-packages\web3\contract\contract.py", line 291, in call
    return call_contract_function(
        self.w3,
    ...<11 lines>...
        **self.kwargs or {},
    )
  File "C:\Users\prajw\AppData\Local\Programs\Python\Python313\Lib\site-packages\web3\contract\utils.py", line 225, in call_contract_function
    raise BadFunctionCallOutput(msg) from e
web3.exceptions.BadFunctionCallOutput: Could not transact with/call contract function, is contract deployed correctly and chain synced?

2025-04-16 12:36:59 [DEBUG] token_auth.verify_token:74 - Token verification completed in 0.6895 seconds
2025-04-16 12:36:59 [INFO] token_auth.verify_token:79 - Token 85OXRI2605 is invalid
2025-04-16 12:36:59 [INFO] .None:0 - ACCESS: /validate_token | User: N/A | Token: 85OXRI2605 | IP: 127.0.0.1 | Status: invalid | Details: Token validation failed
2025-04-16 12:36:59 [DEBUG] app.after_request:34 - Request e120ec353897bf0e processed in 0.6932 seconds
2025-04-16 12:36:59 [DEBUG] w3_utils.verify_token_on_blockchain:318 - Traceback (most recent call last):
  File "C:\Users\prajw\AppData\Local\Programs\Python\Python313\Lib\site-packages\web3\contract\utils.py", line 207, in call_contract_function
    output_data = w3.codec.decode(output_types, return_data)
  File "C:\Users\prajw\AppData\Local\Programs\Python\Python313\Lib\site-packages\eth_abi\codec.py", line 162, in decode
    return cast(Tuple[Any, ...], decoder(stream))
                                 ~~~~~~~^^^^^^^^
  File "C:\Users\prajw\AppData\Local\Programs\Python\Python313\Lib\site-packages\eth_abi\decoding.py", line 131, in __call__
    return self.decode(stream)
           ~~~~~~~~~~~^^^^^^^^
  File "C:\Users\prajw\AppData\Local\Programs\Python\Python313\Lib\site-packages\eth_utils\functional.py", line 47, in inner
    return callback(fn(*args, **kwargs))
  File "C:\Users\prajw\AppData\Local\Programs\Python\Python313\Lib\site-packages\eth_abi\decoding.py", line 224, in decode
    self.validate_pointers(stream)
    ~~~~~~~~~~~~~~~~~~~~~~^^^^^^^^
  File "C:\Users\prajw\AppData\Local\Programs\Python\Python313\Lib\site-packages\eth_abi\decoding.py", line 218, in validate_pointers
    decoder(stream)
    ~~~~~~~^^^^^^^^
  File "C:\Users\prajw\AppData\Local\Programs\Python\Python313\Lib\site-packages\eth_abi\decoding.py", line 131, in __call__
    return self.decode(stream)
           ~~~~~~~~~~~^^^^^^^^
  File "C:\Users\prajw\AppData\Local\Programs\Python\Python313\Lib\site-packages\eth_abi\decoding.py", line 250, in decode
    raw_data = self.read_data_from_stream(stream)
  File "C:\Users\prajw\AppData\Local\Programs\Python\Python313\Lib\site-packages\eth_abi\decoding.py", line 389, in read_data_from_stream
    raise InsufficientDataBytes(
    ...<2 lines>...
    )
eth_abi.exceptions.InsufficientDataBytes: Tried to read 32 bytes, only got 0 bytes.

The above exception was the direct cause of the following exception:

Traceback (most recent call last):
  File "p:\blockchain-id-authentication\PII-Authenticator\backend\w3_utils.py", line 309, in verify_token_on_blockchain
    is_valid = contract.functions.verifyToken(user_token).call()
  File "C:\Users\prajw\AppData\Local\Programs\Python\Python313\Lib\site-packages\web3\contract\contract.py", line 291, in call
    return call_contract_function(
        self.w3,
    ...<11 lines>...
        **self.kwargs or {},
    )
  File "C:\Users\prajw\AppData\Local\Programs\Python\Python313\Lib\site-packages\web3\contract\utils.py", line 225, in call_contract_function
    raise BadFunctionCallOutput(msg) from e
web3.exceptions.BadFunctionCallOutput: Could not transact with/call contract function, is contract deployed correctly and chain synced?

2025-04-16 12:36:59 [DEBUG] token_auth.verify_token:74 - Token verification completed in 0.6983 seconds
2025-04-16 12:36:59 [INFO] token_auth.verify_token:79 - Token 2JYR34CV9W is invalid
2025-04-16 12:36:59 [INFO] .None:0 - ACCESS: /validate_token | User: N/A | Token: 2JYR34CV9W | IP: 127.0.0.1 | Status: invalid | Details: Token validation failed
2025-04-16 12:36:59 [DEBUG] app.after_request:34 - Request 81f194c9269d60b4 processed in 0.6994 seconds
2025-04-16 12:36:59 [INFO] token_auth.verify_token:67 - Verifying token: W4V6QRFO1O
2025-04-16 12:36:59 [INFO] token_auth.verify_token:67 - Verifying token: 6HRV098TDA
2025-04-16 12:36:59 [INFO] token_auth.verify_token:67 - Verifying token: 2JYR34CV9W
2025-04-16 12:36:59 [INFO] w3_utils.verify_token_on_blockchain:288 - Verifying token on blockchain: W4V6QRFO1O
2025-04-16 12:36:59 [INFO] w3_utils.verify_token_on_blockchain:288 - Verifying token on blockchain: 6HRV098TDA
2025-04-16 12:36:59 [DEBUG] w3_utils.verify_token_on_blockchain:308 - Calling verifyToken function for token: W4V6QRFO1O
2025-04-16 12:36:59 [INFO] w3_utils.verify_token_on_blockchain:288 - Verifying token on blockchain: 2JYR34CV9W
2025-04-16 12:36:59 [DEBUG] w3_utils.verify_token_on_blockchain:308 - Calling verifyToken function for token: 6HRV098TDA
2025-04-16 12:36:59 [DEBUG] w3_utils.verify_token_on_blockchain:308 - Calling verifyToken function for token: 2JYR34CV9W
2025-04-16 12:37:00 [DEBUG] w3_utils.verify_token_on_blockchain:318 - Traceback (most recent call last):
  File "C:\Users\prajw\AppData\Local\Programs\Python\Python313\Lib\site-packages\web3\contract\utils.py", line 207, in call_contract_function
    output_data = w3.codec.decode(output_types, return_data)
  File "C:\Users\prajw\AppData\Local\Programs\Python\Python313\Lib\site-packages\eth_abi\codec.py", line 162, in decode
    return cast(Tuple[Any, ...], decoder(stream))
                                 ~~~~~~~^^^^^^^^
  File "C:\Users\prajw\AppData\Local\Programs\Python\Python313\Lib\site-packages\eth_abi\decoding.py", line 131, in __call__
    return self.decode(stream)
           ~~~~~~~~~~~^^^^^^^^
  File "C:\Users\prajw\AppData\Local\Programs\Python\Python313\Lib\site-packages\eth_utils\functional.py", line 47, in inner
    return callback(fn(*args, **kwargs))
  File "C:\Users\prajw\AppData\Local\Programs\Python\Python313\Lib\site-packages\eth_abi\decoding.py", line 224, in decode
    self.validate_pointers(stream)
    ~~~~~~~~~~~~~~~~~~~~~~^^^^^^^^
  File "C:\Users\prajw\AppData\Local\Programs\Python\Python313\Lib\site-packages\eth_abi\decoding.py", line 218, in validate_pointers
    decoder(stream)
    ~~~~~~~^^^^^^^^
  File "C:\Users\prajw\AppData\Local\Programs\Python\Python313\Lib\site-packages\eth_abi\decoding.py", line 131, in __call__
    return self.decode(stream)
           ~~~~~~~~~~~^^^^^^^^
  File "C:\Users\prajw\AppData\Local\Programs\Python\Python313\Lib\site-packages\eth_abi\decoding.py", line 250, in decode
    raw_data = self.read_data_from_stream(stream)
  File "C:\Users\prajw\AppData\Local\Programs\Python\Python313\Lib\site-packages\eth_abi\decoding.py", line 389, in read_data_from_stream
    raise InsufficientDataBytes(
    ...<2 lines>...
    )
eth_abi.exceptions.InsufficientDataBytes: Tried to read 32 bytes, only got 0 bytes.

The above exception was the direct cause of the following exception:

Traceback (most recent call last):
  File "p:\blockchain-id-authentication\PII-Authenticator\backend\w3_utils.py", line 309, in verify_token_on_blockchain
    is_valid = contract.functions.verifyToken(user_token).call()
  File "C:\Users\prajw\AppData\Local\Programs\Python\Python313\Lib\site-packages\web3\contract\contract.py", line 291, in call
    return call_contract_function(
        self.w3,
    ...<11 lines>...
        **self.kwargs or {},
    )
  File "C:\Users\prajw\AppData\Local\Programs\Python\Python313\Lib\site-packages\web3\contract\utils.py", line 225, in call_contract_function
    raise BadFunctionCallOutput(msg) from e
web3.exceptions.BadFunctionCallOutput: Could not transact with/call contract function, is contract deployed correctly and chain synced?

2025-04-16 12:37:00 [DEBUG] token_auth.verify_token:74 - Token verification completed in 0.6874 seconds
2025-04-16 12:37:00 [INFO] token_auth.verify_token:79 - Token W4V6QRFO1O is invalid
2025-04-16 12:37:00 [INFO] .None:0 - ACCESS: /validate_token | User: N/A | Token: W4V6QRFO1O | IP: 127.0.0.1 | Status: invalid | Details: Token validation failed
2025-04-16 12:37:00 [DEBUG] app.after_request:34 - Request b172d1ade8001ae1 processed in 0.6887 seconds
2025-04-16 12:37:00 [INFO] token_auth.verify_token:67 - Verifying token: BQ3FXGQGIM
2025-04-16 12:37:00 [INFO] w3_utils.verify_token_on_blockchain:288 - Verifying token on blockchain: BQ3FXGQGIM
2025-04-16 12:37:00 [DEBUG] w3_utils.verify_token_on_blockchain:308 - Calling verifyToken function for token: BQ3FXGQGIM
2025-04-16 12:37:00 [DEBUG] w3_utils.verify_token_on_blockchain:318 - Traceback (most recent call last):
  File "C:\Users\prajw\AppData\Local\Programs\Python\Python313\Lib\site-packages\web3\contract\utils.py", line 207, in call_contract_function
    output_data = w3.codec.decode(output_types, return_data)
  File "C:\Users\prajw\AppData\Local\Programs\Python\Python313\Lib\site-packages\eth_abi\codec.py", line 162, in decode
    return cast(Tuple[Any, ...], decoder(stream))
                                 ~~~~~~~^^^^^^^^
  File "C:\Users\prajw\AppData\Local\Programs\Python\Python313\Lib\site-packages\eth_abi\decoding.py", line 131, in __call__
    return self.decode(stream)
           ~~~~~~~~~~~^^^^^^^^
  File "C:\Users\prajw\AppData\Local\Programs\Python\Python313\Lib\site-packages\eth_utils\functional.py", line 47, in inner
    return callback(fn(*args, **kwargs))
  File "C:\Users\prajw\AppData\Local\Programs\Python\Python313\Lib\site-packages\eth_abi\decoding.py", line 224, in decode
    self.validate_pointers(stream)
    ~~~~~~~~~~~~~~~~~~~~~~^^^^^^^^
  File "C:\Users\prajw\AppData\Local\Programs\Python\Python313\Lib\site-packages\eth_abi\decoding.py", line 218, in validate_pointers
    decoder(stream)
    ~~~~~~~^^^^^^^^
  File "C:\Users\prajw\AppData\Local\Programs\Python\Python313\Lib\site-packages\eth_abi\decoding.py", line 131, in __call__
    return self.decode(stream)
           ~~~~~~~~~~~^^^^^^^^
  File "C:\Users\prajw\AppData\Local\Programs\Python\Python313\Lib\site-packages\eth_abi\decoding.py", line 250, in decode
    raw_data = self.read_data_from_stream(stream)
  File "C:\Users\prajw\AppData\Local\Programs\Python\Python313\Lib\site-packages\eth_abi\decoding.py", line 389, in read_data_from_stream
    raise InsufficientDataBytes(
    ...<2 lines>...
    )
eth_abi.exceptions.InsufficientDataBytes: Tried to read 32 bytes, only got 0 bytes.

The above exception was the direct cause of the following exception:

Traceback (most recent call last):
  File "p:\blockchain-id-authentication\PII-Authenticator\backend\w3_utils.py", line 309, in verify_token_on_blockchain
    is_valid = contract.functions.verifyToken(user_token).call()
  File "C:\Users\prajw\AppData\Local\Programs\Python\Python313\Lib\site-packages\web3\contract\contract.py", line 291, in call
    return call_contract_function(
        self.w3,
    ...<11 lines>...
        **self.kwargs or {},
    )
  File "C:\Users\prajw\AppData\Local\Programs\Python\Python313\Lib\site-packages\web3\contract\utils.py", line 225, in call_contract_function
    raise BadFunctionCallOutput(msg) from e
web3.exceptions.BadFunctionCallOutput: Could not transact with/call contract function, is contract deployed correctly and chain synced?

2025-04-16 12:37:00 [DEBUG] token_auth.verify_token:74 - Token verification completed in 0.6990 seconds
2025-04-16 12:37:00 [INFO] token_auth.verify_token:79 - Token 2JYR34CV9W is invalid
2025-04-16 12:37:00 [INFO] .None:0 - ACCESS: /validate_token | User: N/A | Token: 2JYR34CV9W | IP: 127.0.0.1 | Status: invalid | Details: Token validation failed
2025-04-16 12:37:00 [DEBUG] app.after_request:34 - Request b5e3e404cd8e0a4a processed in 0.6997 seconds
2025-04-16 12:37:00 [DEBUG] w3_utils.verify_token_on_blockchain:318 - Traceback (most recent call last):
  File "C:\Users\prajw\AppData\Local\Programs\Python\Python313\Lib\site-packages\web3\contract\utils.py", line 207, in call_contract_function
    output_data = w3.codec.decode(output_types, return_data)
  File "C:\Users\prajw\AppData\Local\Programs\Python\Python313\Lib\site-packages\eth_abi\codec.py", line 162, in decode
    return cast(Tuple[Any, ...], decoder(stream))
                                 ~~~~~~~^^^^^^^^
  File "C:\Users\prajw\AppData\Local\Programs\Python\Python313\Lib\site-packages\eth_abi\decoding.py", line 131, in __call__
    return self.decode(stream)
           ~~~~~~~~~~~^^^^^^^^
  File "C:\Users\prajw\AppData\Local\Programs\Python\Python313\Lib\site-packages\eth_utils\functional.py", line 47, in inner
    return callback(fn(*args, **kwargs))
  File "C:\Users\prajw\AppData\Local\Programs\Python\Python313\Lib\site-packages\eth_abi\decoding.py", line 224, in decode
    self.validate_pointers(stream)
    ~~~~~~~~~~~~~~~~~~~~~~^^^^^^^^
  File "C:\Users\prajw\AppData\Local\Programs\Python\Python313\Lib\site-packages\eth_abi\decoding.py", line 218, in validate_pointers
    decoder(stream)
    ~~~~~~~^^^^^^^^
  File "C:\Users\prajw\AppData\Local\Programs\Python\Python313\Lib\site-packages\eth_abi\decoding.py", line 131, in __call__
    return self.decode(stream)
           ~~~~~~~~~~~^^^^^^^^
  File "C:\Users\prajw\AppData\Local\Programs\Python\Python313\Lib\site-packages\eth_abi\decoding.py", line 250, in decode
    raw_data = self.read_data_from_stream(stream)
  File "C:\Users\prajw\AppData\Local\Programs\Python\Python313\Lib\site-packages\eth_abi\decoding.py", line 389, in read_data_from_stream
    raise InsufficientDataBytes(
    ...<2 lines>...
    )
eth_abi.exceptions.InsufficientDataBytes: Tried to read 32 bytes, only got 0 bytes.

The above exception was the direct cause of the following exception:

Traceback (most recent call last):
  File "p:\blockchain-id-authentication\PII-Authenticator\backend\w3_utils.py", line 309, in verify_token_on_blockchain
    is_valid = contract.functions.verifyToken(user_token).call()
  File "C:\Users\prajw\AppData\Local\Programs\Python\Python313\Lib\site-packages\web3\contract\contract.py", line 291, in call
    return call_contract_function(
        self.w3,
    ...<11 lines>...
        **self.kwargs or {},
    )
  File "C:\Users\prajw\AppData\Local\Programs\Python\Python313\Lib\site-packages\web3\contract\utils.py", line 225, in call_contract_function
    raise BadFunctionCallOutput(msg) from e
web3.exceptions.BadFunctionCallOutput: Could not transact with/call contract function, is contract deployed correctly and chain synced?

2025-04-16 12:37:00 [DEBUG] token_auth.verify_token:74 - Token verification completed in 0.7066 seconds
2025-04-16 12:37:00 [INFO] token_auth.verify_token:79 - Token 6HRV098TDA is invalid
2025-04-16 12:37:00 [INFO] .None:0 - ACCESS: /validate_token | User: N/A | Token: 6HRV098TDA | IP: 127.0.0.1 | Status: invalid | Details: Token validation failed
2025-04-16 12:37:00 [DEBUG] app.after_request:34 - Request 0eeb71a67c46f00f processed in 0.7077 seconds
2025-04-16 12:37:01 [DEBUG] w3_utils.verify_token_on_blockchain:318 - Traceback (most recent call last):
  File "C:\Users\prajw\AppData\Local\Programs\Python\Python313\Lib\site-packages\web3\contract\utils.py", line 207, in call_contract_function
    output_data = w3.codec.decode(output_types, return_data)
  File "C:\Users\prajw\AppData\Local\Programs\Python\Python313\Lib\site-packages\eth_abi\codec.py", line 162, in decode
    return cast(Tuple[Any, ...], decoder(stream))
                                 ~~~~~~~^^^^^^^^
  File "C:\Users\prajw\AppData\Local\Programs\Python\Python313\Lib\site-packages\eth_abi\decoding.py", line 131, in __call__
    return self.decode(stream)
           ~~~~~~~~~~~^^^^^^^^
  File "C:\Users\prajw\AppData\Local\Programs\Python\Python313\Lib\site-packages\eth_utils\functional.py", line 47, in inner
    return callback(fn(*args, **kwargs))
  File "C:\Users\prajw\AppData\Local\Programs\Python\Python313\Lib\site-packages\eth_abi\decoding.py", line 224, in decode
    self.validate_pointers(stream)
    ~~~~~~~~~~~~~~~~~~~~~~^^^^^^^^
  File "C:\Users\prajw\AppData\Local\Programs\Python\Python313\Lib\site-packages\eth_abi\decoding.py", line 218, in validate_pointers
    decoder(stream)
    ~~~~~~~^^^^^^^^
  File "C:\Users\prajw\AppData\Local\Programs\Python\Python313\Lib\site-packages\eth_abi\decoding.py", line 131, in __call__
    return self.decode(stream)
           ~~~~~~~~~~~^^^^^^^^
  File "C:\Users\prajw\AppData\Local\Programs\Python\Python313\Lib\site-packages\eth_abi\decoding.py", line 250, in decode
    raw_data = self.read_data_from_stream(stream)
  File "C:\Users\prajw\AppData\Local\Programs\Python\Python313\Lib\site-packages\eth_abi\decoding.py", line 389, in read_data_from_stream
    raise InsufficientDataBytes(
    ...<2 lines>...
    )
eth_abi.exceptions.InsufficientDataBytes: Tried to read 32 bytes, only got 0 bytes.

The above exception was the direct cause of the following exception:

Traceback (most recent call last):
  File "p:\blockchain-id-authentication\PII-Authenticator\backend\w3_utils.py", line 309, in verify_token_on_blockchain
    is_valid = contract.functions.verifyToken(user_token).call()
  File "C:\Users\prajw\AppData\Local\Programs\Python\Python313\Lib\site-packages\web3\contract\contract.py", line 291, in call
    return call_contract_function(
        self.w3,
    ...<11 lines>...
        **self.kwargs or {},
    )
  File "C:\Users\prajw\AppData\Local\Programs\Python\Python313\Lib\site-packages\web3\contract\utils.py", line 225, in call_contract_function
    raise BadFunctionCallOutput(msg) from e
web3.exceptions.BadFunctionCallOutput: Could not transact with/call contract function, is contract deployed correctly and chain synced?

2025-04-16 12:37:01 [DEBUG] token_auth.verify_token:74 - Token verification completed in 1.5230 seconds
2025-04-16 12:37:01 [INFO] token_auth.verify_token:79 - Token BQ3FXGQGIM is invalid
2025-04-16 12:37:01 [INFO] .None:0 - ACCESS: /validate_token | User: N/A | Token: BQ3FXGQGIM | IP: 127.0.0.1 | Status: invalid | Details: Token validation failed
2025-04-16 12:37:01 [DEBUG] app.after_request:34 - Request bc3f0690ecf62b75 processed in 1.5244 seconds
2025-04-16 12:38:17 [INFO] w3_utils.<module>:29 - Connecting to Ethereum network via Alchemy...
2025-04-16 12:38:17 [INFO] w3_utils.<module>:53 - Loading contract ABI...
2025-04-16 12:38:17 [INFO] w3_utils.<module>:85 - Initializing contract...
2025-04-16 12:38:17 [INFO] w3_utils.<module>:109 - Initializing Filebase S3 client...
2025-04-16 12:38:17 [INFO] app.<module>:160 - Starting PII Authenticator backend server
2025-04-16 12:41:52 [INFO] w3_utils.<module>:29 - Connecting to Ethereum network via Alchemy...
2025-04-16 12:41:53 [INFO] w3_utils.<module>:53 - Loading contract ABI...
2025-04-16 12:41:53 [INFO] w3_utils.<module>:85 - Initializing contract...
2025-04-16 12:41:53 [INFO] w3_utils.<module>:109 - Initializing Filebase S3 client...
2025-04-16 12:41:53 [INFO] app.<module>:160 - Starting PII Authenticator backend server
2025-04-16 12:41:55 [INFO] w3_utils.<module>:29 - Connecting to Ethereum network via Alchemy...
2025-04-16 12:41:56 [INFO] w3_utils.<module>:53 - Loading contract ABI...
2025-04-16 12:41:56 [INFO] w3_utils.<module>:85 - Initializing contract...
2025-04-16 12:41:56 [INFO] w3_utils.<module>:109 - Initializing Filebase S3 client...
2025-04-16 12:41:56 [INFO] app.<module>:160 - Starting PII Authenticator backend server
2025-04-16 12:42:50 [DEBUG] app.after_request:34 - Request 13be6c11b41a257a processed in 0.0036 seconds
2025-04-16 12:42:50 [INFO] token_auth.get_or_generate_token:27 - Generating token for user: prajwal k r
2025-04-16 12:42:50 [DEBUG] token_auth.generate_unique_token:14 - Generated token: U18X0OKH14
2025-04-16 12:42:50 [INFO] w3_utils.verify_token_on_blockchain:288 - Verifying token on blockchain: U18X0OKH14
2025-04-16 12:42:50 [DEBUG] w3_utils.verify_token_on_blockchain:308 - Calling verifyToken function for token: U18X0OKH14
2025-04-16 12:42:51 [DEBUG] w3_utils.verify_token_on_blockchain:318 - Traceback (most recent call last):
  File "C:\Users\prajw\AppData\Local\Programs\Python\Python313\Lib\site-packages\web3\contract\utils.py", line 207, in call_contract_function
    output_data = w3.codec.decode(output_types, return_data)
  File "C:\Users\prajw\AppData\Local\Programs\Python\Python313\Lib\site-packages\eth_abi\codec.py", line 162, in decode
    return cast(Tuple[Any, ...], decoder(stream))
                                 ~~~~~~~^^^^^^^^
  File "C:\Users\prajw\AppData\Local\Programs\Python\Python313\Lib\site-packages\eth_abi\decoding.py", line 131, in __call__
    return self.decode(stream)
           ~~~~~~~~~~~^^^^^^^^
  File "C:\Users\prajw\AppData\Local\Programs\Python\Python313\Lib\site-packages\eth_utils\functional.py", line 47, in inner
    return callback(fn(*args, **kwargs))
  File "C:\Users\prajw\AppData\Local\Programs\Python\Python313\Lib\site-packages\eth_abi\decoding.py", line 224, in decode
    self.validate_pointers(stream)
    ~~~~~~~~~~~~~~~~~~~~~~^^^^^^^^
  File "C:\Users\prajw\AppData\Local\Programs\Python\Python313\Lib\site-packages\eth_abi\decoding.py", line 218, in validate_pointers
    decoder(stream)
    ~~~~~~~^^^^^^^^
  File "C:\Users\prajw\AppData\Local\Programs\Python\Python313\Lib\site-packages\eth_abi\decoding.py", line 131, in __call__
    return self.decode(stream)
           ~~~~~~~~~~~^^^^^^^^
  File "C:\Users\prajw\AppData\Local\Programs\Python\Python313\Lib\site-packages\eth_abi\decoding.py", line 250, in decode
    raw_data = self.read_data_from_stream(stream)
  File "C:\Users\prajw\AppData\Local\Programs\Python\Python313\Lib\site-packages\eth_abi\decoding.py", line 389, in read_data_from_stream
    raise InsufficientDataBytes(
    ...<2 lines>...
    )
eth_abi.exceptions.InsufficientDataBytes: Tried to read 32 bytes, only got 0 bytes.

The above exception was the direct cause of the following exception:

Traceback (most recent call last):
  File "p:\blockchain-id-authentication\PII-Authenticator\backend\w3_utils.py", line 309, in verify_token_on_blockchain
    is_valid = contract.functions.verifyToken(user_token).call()
  File "C:\Users\prajw\AppData\Local\Programs\Python\Python313\Lib\site-packages\web3\contract\contract.py", line 291, in call
    return call_contract_function(
        self.w3,
    ...<11 lines>...
        **self.kwargs or {},
    )
  File "C:\Users\prajw\AppData\Local\Programs\Python\Python313\Lib\site-packages\web3\contract\utils.py", line 225, in call_contract_function
    raise BadFunctionCallOutput(msg) from e
web3.exceptions.BadFunctionCallOutput: Could not transact with/call contract function, is contract deployed correctly and chain synced?

2025-04-16 12:42:51 [DEBUG] token_auth.get_or_generate_token:38 - Token U18X0OKH14 is unique (verified after 1 attempts)
2025-04-16 12:42:51 [INFO] w3_utils.store_token_on_blockchain:228 - Storing token on blockchain: U18X0OKH14
2025-04-16 12:42:51 [DEBUG] w3_utils.store_token_on_blockchain:250 - Building transaction for token: U18X0OKH14
2025-04-16 12:42:51 [DEBUG] w3_utils.store_token_on_blockchain:259 - Signing transaction...
2025-04-16 12:42:51 [DEBUG] w3_utils.store_token_on_blockchain:262 - Sending transaction to network...
2025-04-16 12:42:51 [DEBUG] w3_utils.store_token_on_blockchain:265 - Waiting for transaction receipt: c3200167d2ec8963c5fe71b7742699d808b7c456326bba266c3d5e2a34583e38
2025-04-16 12:44:51 [DEBUG] w3_utils.store_token_on_blockchain:275 - Traceback (most recent call last):
  File "C:\Users\prajw\AppData\Local\Programs\Python\Python313\Lib\site-packages\web3\eth\eth.py", line 507, in wait_for_transaction_receipt
    _timeout.sleep(poll_latency)
    ~~~~~~~~~~~~~~^^^^^^^^^^^^^^
  File "C:\Users\prajw\AppData\Local\Programs\Python\Python313\Lib\site-packages\web3\_utils\threads.py", line 101, in sleep
    self.check()
    ~~~~~~~~~~^^
  File "C:\Users\prajw\AppData\Local\Programs\Python\Python313\Lib\site-packages\web3\_utils\threads.py", line 94, in check
    raise self
web3._utils.threads.Timeout: 120 seconds

During handling of the above exception, another exception occurred:

Traceback (most recent call last):
  File "p:\blockchain-id-authentication\PII-Authenticator\backend\w3_utils.py", line 266, in store_token_on_blockchain
    receipt = web3.eth.wait_for_transaction_receipt(tx_hash)
  File "C:\Users\prajw\AppData\Local\Programs\Python\Python313\Lib\site-packages\web3\eth\eth.py", line 511, in wait_for_transaction_receipt
    raise TimeExhausted(
    ...<2 lines>...
    )
web3.exceptions.TimeExhausted: Transaction HexBytes('0xc3200167d2ec8963c5fe71b7742699d808b7c456326bba266c3d5e2a34583e38') is not in the chain after 120 seconds

2025-04-16 12:44:51 [WARNING] token_auth.get_or_generate_token:50 - Failed to store token U18X0OKH14 on blockchain for user prajwal k r
2025-04-16 12:44:51 [DEBUG] token_auth.get_or_generate_token:53 - Token generation completed in 121.3413 seconds
2025-04-16 12:44:51 [INFO] w3_utils.upload_to_filebase:140 - Uploading file U18X0OKH14.txt to storage...
2025-04-16 12:44:52 [INFO] .None:0 - ACCESS: /encrypt | User: prajwal k r | Token: U18X0OKH14 | IP: 127.0.0.1 | Status: success | Details: Token generated and data stored at https://s3.filebase.com/pii-authenticator-test/U18X0OKH14.txt
2025-04-16 12:44:52 [DEBUG] app.after_request:34 - Request c265a3e8abfbf87e processed in 122.5605 seconds
2025-04-16 12:45:23 [DEBUG] app.after_request:34 - Request cf2c0bca1cb2c863 processed in 0.0017 seconds
2025-04-16 12:45:23 [INFO] token_auth.verify_token:67 - Verifying token: U18X0OKH14
2025-04-16 12:45:23 [INFO] w3_utils.verify_token_on_blockchain:288 - Verifying token on blockchain: U18X0OKH14
2025-04-16 12:45:23 [DEBUG] w3_utils.verify_token_on_blockchain:308 - Calling verifyToken function for token: U18X0OKH14
2025-04-16 12:45:24 [DEBUG] w3_utils.verify_token_on_blockchain:318 - Traceback (most recent call last):
  File "C:\Users\prajw\AppData\Local\Programs\Python\Python313\Lib\site-packages\web3\contract\utils.py", line 207, in call_contract_function
    output_data = w3.codec.decode(output_types, return_data)
  File "C:\Users\prajw\AppData\Local\Programs\Python\Python313\Lib\site-packages\eth_abi\codec.py", line 162, in decode
    return cast(Tuple[Any, ...], decoder(stream))
                                 ~~~~~~~^^^^^^^^
  File "C:\Users\prajw\AppData\Local\Programs\Python\Python313\Lib\site-packages\eth_abi\decoding.py", line 131, in __call__
    return self.decode(stream)
           ~~~~~~~~~~~^^^^^^^^
  File "C:\Users\prajw\AppData\Local\Programs\Python\Python313\Lib\site-packages\eth_utils\functional.py", line 47, in inner
    return callback(fn(*args, **kwargs))
  File "C:\Users\prajw\AppData\Local\Programs\Python\Python313\Lib\site-packages\eth_abi\decoding.py", line 224, in decode
    self.validate_pointers(stream)
    ~~~~~~~~~~~~~~~~~~~~~~^^^^^^^^
  File "C:\Users\prajw\AppData\Local\Programs\Python\Python313\Lib\site-packages\eth_abi\decoding.py", line 218, in validate_pointers
    decoder(stream)
    ~~~~~~~^^^^^^^^
  File "C:\Users\prajw\AppData\Local\Programs\Python\Python313\Lib\site-packages\eth_abi\decoding.py", line 131, in __call__
    return self.decode(stream)
           ~~~~~~~~~~~^^^^^^^^
  File "C:\Users\prajw\AppData\Local\Programs\Python\Python313\Lib\site-packages\eth_abi\decoding.py", line 250, in decode
    raw_data = self.read_data_from_stream(stream)
  File "C:\Users\prajw\AppData\Local\Programs\Python\Python313\Lib\site-packages\eth_abi\decoding.py", line 389, in read_data_from_stream
    raise InsufficientDataBytes(
    ...<2 lines>...
    )
eth_abi.exceptions.InsufficientDataBytes: Tried to read 32 bytes, only got 0 bytes.

The above exception was the direct cause of the following exception:

Traceback (most recent call last):
  File "p:\blockchain-id-authentication\PII-Authenticator\backend\w3_utils.py", line 309, in verify_token_on_blockchain
    is_valid = contract.functions.verifyToken(user_token).call()
  File "C:\Users\prajw\AppData\Local\Programs\Python\Python313\Lib\site-packages\web3\contract\contract.py", line 291, in call
    return call_contract_function(
        self.w3,
    ...<11 lines>...
        **self.kwargs or {},
    )
  File "C:\Users\prajw\AppData\Local\Programs\Python\Python313\Lib\site-packages\web3\contract\utils.py", line 225, in call_contract_function
    raise BadFunctionCallOutput(msg) from e
web3.exceptions.BadFunctionCallOutput: Could not transact with/call contract function, is contract deployed correctly and chain synced?

2025-04-16 12:45:24 [DEBUG] token_auth.verify_token:74 - Token verification completed in 0.7929 seconds
2025-04-16 12:45:24 [INFO] token_auth.verify_token:79 - Token U18X0OKH14 is invalid
2025-04-16 12:45:24 [INFO] .None:0 - ACCESS: /validate_token | User: N/A | Token: U18X0OKH14 | IP: 127.0.0.1 | Status: invalid | Details: Token validation failed
2025-04-16 12:45:24 [DEBUG] app.after_request:34 - Request fb8a89a40599e89d processed in 0.7947 seconds
2025-04-16 12:47:21 [DEBUG] app.after_request:34 - Request 0c3202765444c121 processed in 0.0024 seconds
2025-04-16 12:47:21 [INFO] token_auth.get_or_generate_token:27 - Generating token for user: edith
2025-04-16 12:47:21 [DEBUG] token_auth.generate_unique_token:14 - Generated token: X63XUZNOC7
2025-04-16 12:47:21 [INFO] w3_utils.verify_token_on_blockchain:288 - Verifying token on blockchain: X63XUZNOC7
2025-04-16 12:47:21 [DEBUG] w3_utils.verify_token_on_blockchain:308 - Calling verifyToken function for token: X63XUZNOC7
2025-04-16 12:47:22 [DEBUG] w3_utils.verify_token_on_blockchain:318 - Traceback (most recent call last):
  File "C:\Users\prajw\AppData\Local\Programs\Python\Python313\Lib\site-packages\web3\contract\utils.py", line 207, in call_contract_function
    output_data = w3.codec.decode(output_types, return_data)
  File "C:\Users\prajw\AppData\Local\Programs\Python\Python313\Lib\site-packages\eth_abi\codec.py", line 162, in decode
    return cast(Tuple[Any, ...], decoder(stream))
                                 ~~~~~~~^^^^^^^^
  File "C:\Users\prajw\AppData\Local\Programs\Python\Python313\Lib\site-packages\eth_abi\decoding.py", line 131, in __call__
    return self.decode(stream)
           ~~~~~~~~~~~^^^^^^^^
  File "C:\Users\prajw\AppData\Local\Programs\Python\Python313\Lib\site-packages\eth_utils\functional.py", line 47, in inner
    return callback(fn(*args, **kwargs))
  File "C:\Users\prajw\AppData\Local\Programs\Python\Python313\Lib\site-packages\eth_abi\decoding.py", line 224, in decode
    self.validate_pointers(stream)
    ~~~~~~~~~~~~~~~~~~~~~~^^^^^^^^
  File "C:\Users\prajw\AppData\Local\Programs\Python\Python313\Lib\site-packages\eth_abi\decoding.py", line 218, in validate_pointers
    decoder(stream)
    ~~~~~~~^^^^^^^^
  File "C:\Users\prajw\AppData\Local\Programs\Python\Python313\Lib\site-packages\eth_abi\decoding.py", line 131, in __call__
    return self.decode(stream)
           ~~~~~~~~~~~^^^^^^^^
  File "C:\Users\prajw\AppData\Local\Programs\Python\Python313\Lib\site-packages\eth_abi\decoding.py", line 250, in decode
    raw_data = self.read_data_from_stream(stream)
  File "C:\Users\prajw\AppData\Local\Programs\Python\Python313\Lib\site-packages\eth_abi\decoding.py", line 389, in read_data_from_stream
    raise InsufficientDataBytes(
    ...<2 lines>...
    )
eth_abi.exceptions.InsufficientDataBytes: Tried to read 32 bytes, only got 0 bytes.

The above exception was the direct cause of the following exception:

Traceback (most recent call last):
  File "p:\blockchain-id-authentication\PII-Authenticator\backend\w3_utils.py", line 309, in verify_token_on_blockchain
    is_valid = contract.functions.verifyToken(user_token).call()
  File "C:\Users\prajw\AppData\Local\Programs\Python\Python313\Lib\site-packages\web3\contract\contract.py", line 291, in call
    return call_contract_function(
        self.w3,
    ...<11 lines>...
        **self.kwargs or {},
    )
  File "C:\Users\prajw\AppData\Local\Programs\Python\Python313\Lib\site-packages\web3\contract\utils.py", line 225, in call_contract_function
    raise BadFunctionCallOutput(msg) from e
web3.exceptions.BadFunctionCallOutput: Could not transact with/call contract function, is contract deployed correctly and chain synced?

2025-04-16 12:47:22 [DEBUG] token_auth.get_or_generate_token:38 - Token X63XUZNOC7 is unique (verified after 1 attempts)
2025-04-16 12:47:22 [INFO] w3_utils.store_token_on_blockchain:228 - Storing token on blockchain: X63XUZNOC7
2025-04-16 12:47:22 [DEBUG] w3_utils.store_token_on_blockchain:250 - Building transaction for token: X63XUZNOC7
2025-04-16 12:47:22 [DEBUG] w3_utils.store_token_on_blockchain:259 - Signing transaction...
2025-04-16 12:47:22 [DEBUG] w3_utils.store_token_on_blockchain:262 - Sending transaction to network...
2025-04-16 12:47:23 [DEBUG] w3_utils.store_token_on_blockchain:275 - Traceback (most recent call last):
  File "p:\blockchain-id-authentication\PII-Authenticator\backend\w3_utils.py", line 263, in store_token_on_blockchain
    tx_hash = web3.eth.send_raw_transaction(signed_tx.raw_transaction)
  File "C:\Users\prajw\AppData\Local\Programs\Python\Python313\Lib\site-packages\web3\eth\eth.py", line 396, in send_raw_transaction
    return self._send_raw_transaction(transaction)
           ~~~~~~~~~~~~~~~~~~~~~~~~~~^^^^^^^^^^^^^
  File "C:\Users\prajw\AppData\Local\Programs\Python\Python313\Lib\site-packages\web3\module.py", line 112, in caller
    result = w3.manager.request_blocking(
        method_str, params, error_formatters, null_result_formatters
    )
  File "C:\Users\prajw\AppData\Local\Programs\Python\Python313\Lib\site-packages\web3\manager.py", line 232, in request_blocking
    return self.formatted_response(
           ~~~~~~~~~~~~~~~~~~~~~~~^
        response, params, error_formatters, null_result_formatters
        ^^^^^^^^^^^^^^^^^^^^^^^^^^^^^^^^^^^^^^^^^^^^^^^^^^^^^^^^^^
    )
    ^
  File "C:\Users\prajw\AppData\Local\Programs\Python\Python313\Lib\site-packages\web3\manager.py", line 198, in formatted_response
    validate_rpc_response_and_raise_if_error(
    ~~~~~~~~~~~~~~~~~~~~~~~~~~~~~~~~~~~~~~~~^
        response,
        ^^^^^^^^^
    ...<3 lines>...
        params=params,
        ^^^^^^^^^^^^^^
    )
    ^
  File "C:\Users\prajw\AppData\Local\Programs\Python\Python313\Lib\site-packages\web3\_utils\validation.py", line 401, in validate_rpc_response_and_raise_if_error
    raise web3_rpc_error
web3.exceptions.Web3RPCError: {'code': -32603, 'message': 'replacement transaction underpriced'}

2025-04-16 12:47:23 [WARNING] token_auth.get_or_generate_token:50 - Failed to store token X63XUZNOC7 on blockchain for user edith
2025-04-16 12:47:23 [DEBUG] token_auth.get_or_generate_token:53 - Token generation completed in 1.4488 seconds
2025-04-16 12:47:23 [INFO] w3_utils.upload_to_filebase:140 - Uploading file X63XUZNOC7.txt to storage...
2025-04-16 12:47:23 [INFO] .None:0 - ACCESS: /encrypt | User: edith | Token: X63XUZNOC7 | IP: 127.0.0.1 | Status: success | Details: Token generated and data stored at https://s3.filebase.com/pii-authenticator-test/X63XUZNOC7.txt
2025-04-16 12:47:23 [DEBUG] app.after_request:34 - Request de96c6c1b75eadb3 processed in 2.1125 seconds
2025-04-16 12:47:33 [DEBUG] app.after_request:34 - Request 6401b1cadb9d6280 processed in 0.0002 seconds
2025-04-16 12:47:33 [INFO] token_auth.verify_token:67 - Verifying token: X63XUZNOC7
2025-04-16 12:47:33 [INFO] w3_utils.verify_token_on_blockchain:288 - Verifying token on blockchain: X63XUZNOC7
2025-04-16 12:47:33 [DEBUG] w3_utils.verify_token_on_blockchain:308 - Calling verifyToken function for token: X63XUZNOC7
2025-04-16 12:47:33 [DEBUG] w3_utils.verify_token_on_blockchain:318 - Traceback (most recent call last):
  File "C:\Users\prajw\AppData\Local\Programs\Python\Python313\Lib\site-packages\web3\contract\utils.py", line 207, in call_contract_function
    output_data = w3.codec.decode(output_types, return_data)
  File "C:\Users\prajw\AppData\Local\Programs\Python\Python313\Lib\site-packages\eth_abi\codec.py", line 162, in decode
    return cast(Tuple[Any, ...], decoder(stream))
                                 ~~~~~~~^^^^^^^^
  File "C:\Users\prajw\AppData\Local\Programs\Python\Python313\Lib\site-packages\eth_abi\decoding.py", line 131, in __call__
    return self.decode(stream)
           ~~~~~~~~~~~^^^^^^^^
  File "C:\Users\prajw\AppData\Local\Programs\Python\Python313\Lib\site-packages\eth_utils\functional.py", line 47, in inner
    return callback(fn(*args, **kwargs))
  File "C:\Users\prajw\AppData\Local\Programs\Python\Python313\Lib\site-packages\eth_abi\decoding.py", line 224, in decode
    self.validate_pointers(stream)
    ~~~~~~~~~~~~~~~~~~~~~~^^^^^^^^
  File "C:\Users\prajw\AppData\Local\Programs\Python\Python313\Lib\site-packages\eth_abi\decoding.py", line 218, in validate_pointers
    decoder(stream)
    ~~~~~~~^^^^^^^^
  File "C:\Users\prajw\AppData\Local\Programs\Python\Python313\Lib\site-packages\eth_abi\decoding.py", line 131, in __call__
    return self.decode(stream)
           ~~~~~~~~~~~^^^^^^^^
  File "C:\Users\prajw\AppData\Local\Programs\Python\Python313\Lib\site-packages\eth_abi\decoding.py", line 250, in decode
    raw_data = self.read_data_from_stream(stream)
  File "C:\Users\prajw\AppData\Local\Programs\Python\Python313\Lib\site-packages\eth_abi\decoding.py", line 389, in read_data_from_stream
    raise InsufficientDataBytes(
    ...<2 lines>...
    )
eth_abi.exceptions.InsufficientDataBytes: Tried to read 32 bytes, only got 0 bytes.

The above exception was the direct cause of the following exception:

Traceback (most recent call last):
  File "p:\blockchain-id-authentication\PII-Authenticator\backend\w3_utils.py", line 309, in verify_token_on_blockchain
    is_valid = contract.functions.verifyToken(user_token).call()
  File "C:\Users\prajw\AppData\Local\Programs\Python\Python313\Lib\site-packages\web3\contract\contract.py", line 291, in call
    return call_contract_function(
        self.w3,
    ...<11 lines>...
        **self.kwargs or {},
    )
  File "C:\Users\prajw\AppData\Local\Programs\Python\Python313\Lib\site-packages\web3\contract\utils.py", line 225, in call_contract_function
    raise BadFunctionCallOutput(msg) from e
web3.exceptions.BadFunctionCallOutput: Could not transact with/call contract function, is contract deployed correctly and chain synced?

2025-04-16 12:47:33 [DEBUG] token_auth.verify_token:74 - Token verification completed in 0.7073 seconds
2025-04-16 12:47:33 [INFO] token_auth.verify_token:79 - Token X63XUZNOC7 is invalid
2025-04-16 12:47:33 [INFO] .None:0 - ACCESS: /validate_token | User: N/A | Token: X63XUZNOC7 | IP: 127.0.0.1 | Status: invalid | Details: Token validation failed
2025-04-16 12:47:33 [DEBUG] app.after_request:34 - Request af3eaf96c74f3810 processed in 0.7088 seconds
2025-04-16 12:49:11 [INFO] w3_utils.<module>:29 - Connecting to Ethereum network via Alchemy...
2025-04-16 12:49:11 [INFO] w3_utils.<module>:53 - Loading contract ABI...
2025-04-16 12:49:11 [INFO] w3_utils.<module>:85 - Initializing contract...
2025-04-16 12:49:11 [INFO] w3_utils.<module>:109 - Initializing Filebase S3 client...
2025-04-16 12:49:11 [INFO] w3_utils.<module>:53 - Loading contract ABI...
2025-04-16 12:49:11 [INFO] w3_utils.<module>:85 - Initializing contract...
2025-04-16 12:49:11 [INFO] w3_utils.<module>:109 - Initializing Filebase S3 client...
2025-04-16 12:49:11 [INFO] app.<module>:160 - Starting PII Authenticator backend server
2025-04-16 12:49:11 [INFO] app.<module>:160 - Starting PII Authenticator backend server
2025-04-16 12:54:23 [INFO] w3_utils.<module>:29 - Connecting to Ethereum network via Alchemy...
2025-04-16 12:54:24 [INFO] w3_utils.<module>:53 - Loading contract ABI...
2025-04-16 12:54:24 [INFO] w3_utils.<module>:85 - Initializing contract...
2025-04-16 12:54:24 [INFO] w3_utils.<module>:109 - Initializing Filebase S3 client...
2025-04-16 12:54:24 [INFO] w3_utils.<module>:53 - Loading contract ABI...
2025-04-16 12:54:24 [INFO] w3_utils.<module>:85 - Initializing contract...
2025-04-16 12:54:24 [INFO] w3_utils.<module>:109 - Initializing Filebase S3 client...
2025-04-16 12:54:24 [INFO] app.<module>:183 - Starting PII Authenticator backend server
2025-04-16 12:54:24 [INFO] app.<module>:183 - Starting PII Authenticator backend server
2025-04-16 12:56:52 [INFO] w3_utils.<module>:29 - Connecting to Ethereum network via Alchemy...
2025-04-16 12:56:52 [INFO] w3_utils.<module>:53 - Loading contract ABI...
2025-04-16 12:56:52 [INFO] w3_utils.<module>:85 - Initializing contract...
2025-04-16 12:56:52 [INFO] w3_utils.<module>:109 - Initializing Filebase S3 client...
2025-04-16 12:56:52 [INFO] app.<module>:183 - Starting PII Authenticator backend server
2025-04-16 12:56:54 [INFO] w3_utils.<module>:29 - Connecting to Ethereum network via Alchemy...
2025-04-16 12:56:55 [INFO] w3_utils.<module>:53 - Loading contract ABI...
2025-04-16 12:56:55 [INFO] w3_utils.<module>:85 - Initializing contract...
2025-04-16 12:56:55 [INFO] w3_utils.<module>:109 - Initializing Filebase S3 client...
2025-04-16 12:56:55 [INFO] app.<module>:183 - Starting PII Authenticator backend server
2025-04-16 13:01:49 [INFO] w3_utils.<module>:29 - Connecting to Ethereum network via Alchemy...
2025-04-16 13:01:49 [INFO] w3_utils.<module>:53 - Loading contract ABI...
2025-04-16 13:01:49 [INFO] w3_utils.<module>:85 - Initializing contract...
2025-04-16 13:01:49 [INFO] w3_utils.<module>:109 - Initializing Filebase S3 client...
2025-04-16 13:01:50 [INFO] app.<module>:183 - Starting PII Authenticator backend server
2025-04-16 13:01:51 [INFO] w3_utils.<module>:29 - Connecting to Ethereum network via Alchemy...
2025-04-16 13:01:51 [INFO] w3_utils.<module>:53 - Loading contract ABI...
2025-04-16 13:01:51 [INFO] w3_utils.<module>:85 - Initializing contract...
2025-04-16 13:01:51 [INFO] w3_utils.<module>:109 - Initializing Filebase S3 client...
2025-04-16 13:01:51 [INFO] app.<module>:183 - Starting PII Authenticator backend server
2025-04-16 13:09:57 [INFO] w3_utils.<module>:29 - Connecting to Ethereum network via Alchemy...
2025-04-16 13:09:58 [INFO] w3_utils.<module>:53 - Loading contract ABI...
2025-04-16 13:09:58 [INFO] w3_utils.<module>:85 - Initializing contract...
2025-04-16 13:09:58 [INFO] w3_utils.<module>:109 - Initializing Filebase S3 client...
2025-04-16 13:09:58 [INFO] app.<module>:183 - Starting PII Authenticator backend server
2025-04-16 13:10:00 [INFO] w3_utils.<module>:29 - Connecting to Ethereum network via Alchemy...
2025-04-16 13:10:00 [INFO] w3_utils.<module>:53 - Loading contract ABI...
2025-04-16 13:10:00 [INFO] w3_utils.<module>:85 - Initializing contract...
2025-04-16 13:10:00 [INFO] w3_utils.<module>:109 - Initializing Filebase S3 client...
2025-04-16 13:10:00 [INFO] app.<module>:183 - Starting PII Authenticator backend server
2025-04-16 13:17:29 [INFO] w3_utils.<module>:29 - Connecting to Ethereum network via Alchemy...
2025-04-16 13:17:29 [INFO] w3_utils.<module>:29 - Connecting to Ethereum network via Alchemy...
2025-04-16 13:17:30 [INFO] w3_utils.<module>:53 - Loading contract ABI...
2025-04-16 13:17:30 [INFO] w3_utils.<module>:85 - Initializing contract...
2025-04-16 13:17:30 [INFO] w3_utils.<module>:109 - Initializing Filebase S3 client...
2025-04-16 13:17:30 [INFO] w3_utils.<module>:53 - Loading contract ABI...
2025-04-16 13:17:30 [INFO] w3_utils.<module>:85 - Initializing contract...
2025-04-16 13:17:30 [INFO] w3_utils.<module>:109 - Initializing Filebase S3 client...
2025-04-16 13:17:30 [INFO] app.<module>:184 - Starting PII Authenticator backend server
2025-04-16 13:17:30 [INFO] app.<module>:184 - Starting PII Authenticator backend server
2025-04-16 13:17:33 [INFO] w3_utils.<module>:29 - Connecting to Ethereum network via Alchemy...
2025-04-16 13:17:33 [INFO] w3_utils.<module>:53 - Loading contract ABI...
2025-04-16 13:17:33 [INFO] w3_utils.<module>:85 - Initializing contract...
2025-04-16 13:17:33 [INFO] w3_utils.<module>:109 - Initializing Filebase S3 client...
2025-04-16 13:17:33 [INFO] app.<module>:184 - Starting PII Authenticator backend server
2025-04-16 13:17:35 [INFO] w3_utils.<module>:29 - Connecting to Ethereum network via Alchemy...
2025-04-16 13:17:35 [INFO] w3_utils.<module>:53 - Loading contract ABI...
2025-04-16 13:17:35 [INFO] w3_utils.<module>:85 - Initializing contract...
2025-04-16 13:17:35 [INFO] w3_utils.<module>:109 - Initializing Filebase S3 client...
2025-04-16 13:17:35 [INFO] app.<module>:184 - Starting PII Authenticator backend server
2025-04-16 13:22:18 [INFO] w3_utils.<module>:29 - Connecting to Ethereum network via Alchemy...
2025-04-16 13:22:18 [INFO] w3_utils.<module>:53 - Loading contract ABI...
2025-04-16 13:22:18 [INFO] w3_utils.<module>:85 - Initializing contract...
2025-04-16 13:22:18 [INFO] w3_utils.<module>:109 - Initializing Filebase S3 client...
2025-04-16 13:22:18 [INFO] app.<module>:184 - Starting PII Authenticator backend server
2025-04-16 13:22:20 [INFO] w3_utils.<module>:29 - Connecting to Ethereum network via Alchemy...
2025-04-16 13:22:20 [INFO] w3_utils.<module>:53 - Loading contract ABI...
2025-04-16 13:22:20 [INFO] w3_utils.<module>:85 - Initializing contract...
2025-04-16 13:22:20 [INFO] w3_utils.<module>:109 - Initializing Filebase S3 client...
2025-04-16 13:22:20 [INFO] app.<module>:184 - Starting PII Authenticator backend server
2025-04-16 13:22:53 [DEBUG] app.after_request:35 - Request fe00bd6c321d6dc8 processed in 0.0035 seconds
2025-04-16 13:22:53 [INFO] token_auth.verify_token:65 - Verifying token: MOCK_lvjqfclgk78
2025-04-16 13:22:53 [INFO] w3_utils.verify_token_on_blockchain:356 - Verifying token on blockchain: MOCK_lvjqfclgk78
2025-04-16 13:22:53 [INFO] w3_utils.check_file_exists_in_filebase:202 - Checking if file MOCK_lvjqfclgk78.json exists in Filebase...
2025-04-16 13:22:55 [INFO] w3_utils.check_file_exists_in_filebase:202 - Checking if file MOCK_lvjqfclgk78.txt exists in Filebase...
2025-04-16 13:22:56 [DEBUG] token_auth.verify_token:72 - Token verification completed in 2.3044 seconds
2025-04-16 13:22:56 [INFO] token_auth.verify_token:77 - Token MOCK_lvjqfclgk78 is invalid
2025-04-16 13:22:56 [INFO] .None:0 - ACCESS: /validate_token | User: N/A | Token: MOCK_lvjqfclgk78 | IP: 127.0.0.1 | Status: invalid | Details: Token validation failed
2025-04-16 13:22:56 [DEBUG] app.after_request:35 - Request 331e085d762d3c45 processed in 2.3082 seconds
2025-04-16 13:33:14 [INFO] w3_utils.<module>:29 - Connecting to Ethereum network via Alchemy...
2025-04-16 13:33:15 [INFO] w3_utils.<module>:53 - Loading contract ABI...
2025-04-16 13:33:15 [INFO] w3_utils.<module>:85 - Initializing contract...
2025-04-16 13:33:15 [INFO] w3_utils.<module>:109 - Initializing Filebase S3 client...
2025-04-16 13:33:15 [INFO] app.<module>:184 - Starting PII Authenticator backend server
2025-04-16 13:33:17 [INFO] w3_utils.<module>:29 - Connecting to Ethereum network via Alchemy...
2025-04-16 13:33:17 [INFO] w3_utils.<module>:53 - Loading contract ABI...
2025-04-16 13:33:17 [INFO] w3_utils.<module>:85 - Initializing contract...
2025-04-16 13:33:17 [INFO] w3_utils.<module>:109 - Initializing Filebase S3 client...
2025-04-16 13:33:17 [INFO] app.<module>:184 - Starting PII Authenticator backend server
2025-04-16 13:36:36 [INFO] w3_utils.<module>:29 - Connecting to Ethereum network via Alchemy...
2025-04-16 13:36:36 [INFO] w3_utils.<module>:53 - Loading contract ABI...
2025-04-16 13:36:36 [INFO] w3_utils.<module>:85 - Initializing contract...
2025-04-16 13:36:36 [INFO] w3_utils.<module>:109 - Initializing Filebase S3 client...
2025-04-16 13:36:36 [INFO] app.<module>:184 - Starting PII Authenticator backend server
2025-04-16 13:36:38 [INFO] w3_utils.<module>:29 - Connecting to Ethereum network via Alchemy...
2025-04-16 13:36:38 [INFO] w3_utils.<module>:53 - Loading contract ABI...
2025-04-16 13:36:38 [INFO] w3_utils.<module>:85 - Initializing contract...
2025-04-16 13:36:38 [INFO] w3_utils.<module>:109 - Initializing Filebase S3 client...
2025-04-16 13:36:38 [INFO] app.<module>:184 - Starting PII Authenticator backend server
2025-04-16 13:37:23 [DEBUG] app.after_request:35 - Request 6370ba1b0def85dc processed in 0.0063 seconds
2025-04-16 13:37:23 [INFO] token_auth.verify_token:65 - Verifying token: MOCK_ocn87kyl2b
2025-04-16 13:37:23 [INFO] w3_utils.verify_token_on_blockchain:356 - Verifying token on blockchain: MOCK_ocn87kyl2b
2025-04-16 13:37:23 [INFO] w3_utils.check_file_exists_in_filebase:202 - Checking if file MOCK_ocn87kyl2b.json exists in Filebase...
2025-04-16 13:37:24 [INFO] w3_utils.check_file_exists_in_filebase:202 - Checking if file MOCK_ocn87kyl2b.txt exists in Filebase...
2025-04-16 13:37:25 [DEBUG] token_auth.verify_token:72 - Token verification completed in 2.1584 seconds
2025-04-16 13:37:25 [INFO] token_auth.verify_token:77 - Token MOCK_ocn87kyl2b is invalid
2025-04-16 13:37:25 [INFO] .None:0 - ACCESS: /validate_token | User: N/A | Token: MOCK_ocn87kyl2b | IP: 127.0.0.1 | Status: invalid | Details: Token validation failed
2025-04-16 13:37:25 [DEBUG] app.after_request:35 - Request 6d043808659cab96 processed in 2.1688 seconds
2025-04-16 13:38:54 [INFO] w3_utils.<module>:29 - Connecting to Ethereum network via Alchemy...
2025-04-16 13:38:54 [INFO] w3_utils.<module>:53 - Loading contract ABI...
2025-04-16 13:38:54 [INFO] w3_utils.<module>:85 - Initializing contract...
2025-04-16 13:38:54 [INFO] w3_utils.<module>:109 - Initializing Filebase S3 client...
2025-04-16 13:38:55 [INFO] app.<module>:184 - Starting PII Authenticator backend server
2025-04-16 13:38:56 [INFO] w3_utils.<module>:29 - Connecting to Ethereum network via Alchemy...
2025-04-16 13:38:57 [INFO] w3_utils.<module>:53 - Loading contract ABI...
2025-04-16 13:38:57 [INFO] w3_utils.<module>:85 - Initializing contract...
2025-04-16 13:38:57 [INFO] w3_utils.<module>:109 - Initializing Filebase S3 client...
2025-04-16 13:38:57 [INFO] app.<module>:184 - Starting PII Authenticator backend server
2025-04-16 13:39:19 [DEBUG] app.after_request:35 - Request cdc7f9fafcf61275 processed in 0.0015 seconds
2025-04-16 13:39:19 [INFO] token_auth.get_or_generate_token:27 - Generating token for user: ddfe
2025-04-16 13:39:19 [DEBUG] token_auth.generate_unique_token:14 - Generated token: 8FE8699K4K
2025-04-16 13:39:19 [DEBUG] token_auth.get_or_generate_token:34 - Generated token for user ddfe: 8FE8699K4K
2025-04-16 13:39:19 [INFO] w3_utils.store_token_on_blockchain:286 - Storing token on blockchain: 8FE8699K4K
2025-04-16 13:39:19 [DEBUG] w3_utils.store_token_on_blockchain:308 - Building transaction for token: 8FE8699K4K
2025-04-16 13:39:20 [DEBUG] w3_utils.store_token_on_blockchain:317 - Signing transaction...
2025-04-16 13:39:20 [DEBUG] w3_utils.store_token_on_blockchain:320 - Sending transaction to network...
2025-04-16 13:39:20 [DEBUG] w3_utils.store_token_on_blockchain:323 - Transaction sent: 8e9c8b236f46bdda21fb206b51c2fbf6872e7893bc78ccae1766bc1ca57015dd
2025-04-16 13:39:20 [DEBUG] w3_utils.store_token_on_blockchain:327 - Waiting for transaction receipt with timeout: 8e9c8b236f46bdda21fb206b51c2fbf6872e7893bc78ccae1766bc1ca57015dd
2025-04-16 13:39:26 [WARNING] w3_utils.store_token_on_blockchain:331 - Timeout waiting for receipt, but transaction was sent: 8e9c8b236f46bdda21fb206b51c2fbf6872e7893bc78ccae1766bc1ca57015dd
2025-04-16 13:39:26 [WARNING] w3_utils.store_token_on_blockchain:332 - Error: Transaction HexBytes('0x8e9c8b236f46bdda21fb206b51c2fbf6872e7893bc78ccae1766bc1ca57015dd') is not in the chain after 5 seconds
2025-04-16 13:39:26 [DEBUG] w3_utils.store_token_on_blockchain:343 - Traceback (most recent call last):
  File "p:\blockchain-id-authentication\PII-Authenticator\backend\w3_utils.py", line 338, in store_token_on_blockchain
    logger.info(f"Transaction hash: {receipt.transactionHash.hex()}")
                                     ^^^^^^^
UnboundLocalError: cannot access local variable 'receipt' where it is not associated with a value

2025-04-16 13:39:26 [WARNING] token_auth.get_or_generate_token:46 - Failed to store token 8FE8699K4K on blockchain for user ddfe
2025-04-16 13:39:26 [DEBUG] token_auth.get_or_generate_token:51 - Token generation completed in 6.1479 seconds
2025-04-16 13:39:26 [INFO] w3_utils.upload_to_filebase:140 - Uploading file 8FE8699K4K.json to storage...
2025-04-16 13:39:26 [INFO] .None:0 - ACCESS: /encrypt | User: ddfe | Token: 8FE8699K4K | IP: 127.0.0.1 | Status: success | Details: Token generated and data stored at https://s3.filebase.com/pii-authenticator-test/8FE8699K4K.json
2025-04-16 13:39:26 [DEBUG] app.after_request:35 - Request 56588e69b4523d0d processed in 6.8394 seconds
2025-04-16 13:39:39 [DEBUG] app.after_request:35 - Request ff3338846295e580 processed in 0.0006 seconds
2025-04-16 13:39:39 [INFO] token_auth.verify_token:65 - Verifying token: 8FE8699K4K
2025-04-16 13:39:39 [INFO] w3_utils.verify_token_on_blockchain:356 - Verifying token on blockchain: 8FE8699K4K
2025-04-16 13:39:39 [INFO] w3_utils.check_file_exists_in_filebase:202 - Checking if file 8FE8699K4K.json exists in Filebase...
2025-04-16 13:39:40 [DEBUG] token_auth.verify_token:72 - Token verification completed in 0.5636 seconds
2025-04-16 13:39:40 [INFO] token_auth.verify_token:75 - Token 8FE8699K4K is valid
2025-04-16 13:39:40 [INFO] .None:0 - ACCESS: /validate_token | User: N/A | Token: 8FE8699K4K | IP: 127.0.0.1 | Status: success | Details: Token validation successful
2025-04-16 13:39:40 [DEBUG] app.after_request:35 - Request 7a42ea82659e50bf processed in 0.5642 seconds
2025-04-16 13:40:08 [DEBUG] app.after_request:35 - Request 259d23200b526dd8 processed in 0.0002 seconds
2025-04-16 13:40:08 [INFO] token_auth.verify_token:65 - Verifying token: 8FE8699K4K
2025-04-16 13:40:08 [INFO] w3_utils.verify_token_on_blockchain:356 - Verifying token on blockchain: 8FE8699K4K
2025-04-16 13:40:08 [INFO] w3_utils.check_file_exists_in_filebase:202 - Checking if file 8FE8699K4K.json exists in Filebase...
2025-04-16 13:40:09 [DEBUG] token_auth.verify_token:72 - Token verification completed in 0.6607 seconds
2025-04-16 13:40:09 [INFO] token_auth.verify_token:75 - Token 8FE8699K4K is valid
2025-04-16 13:40:09 [INFO] .None:0 - ACCESS: /validate_token | User: N/A | Token: 8FE8699K4K | IP: 127.0.0.1 | Status: success | Details: Token validation successful
2025-04-16 13:40:09 [DEBUG] app.after_request:35 - Request c47e30a080b31a4f processed in 0.6615 seconds
2025-04-16 13:40:55 [INFO] w3_utils.<module>:29 - Connecting to Ethereum network via Alchemy...
2025-04-16 13:40:56 [INFO] w3_utils.<module>:53 - Loading contract ABI...
2025-04-16 13:40:56 [INFO] w3_utils.<module>:85 - Initializing contract...
2025-04-16 13:40:56 [INFO] w3_utils.<module>:109 - Initializing Filebase S3 client...
2025-04-16 13:40:56 [INFO] app.<module>:184 - Starting PII Authenticator backend server
2025-04-16 13:40:58 [INFO] w3_utils.<module>:29 - Connecting to Ethereum network via Alchemy...
2025-04-16 13:40:58 [INFO] w3_utils.<module>:53 - Loading contract ABI...
2025-04-16 13:40:58 [INFO] w3_utils.<module>:85 - Initializing contract...
2025-04-16 13:40:58 [INFO] w3_utils.<module>:109 - Initializing Filebase S3 client...
2025-04-16 13:40:58 [INFO] app.<module>:184 - Starting PII Authenticator backend server
2025-04-16 13:41:26 [DEBUG] app.after_request:35 - Request 7e7e17249286cd17 processed in 0.0001 seconds
2025-04-16 13:41:26 [INFO] token_auth.get_or_generate_token:27 - Generating token for user: anupsdsfc
2025-04-16 13:41:26 [DEBUG] token_auth.generate_unique_token:14 - Generated token: EKSQKJ3T2R
2025-04-16 13:41:26 [DEBUG] token_auth.get_or_generate_token:34 - Generated token for user anupsdsfc: EKSQKJ3T2R
2025-04-16 13:41:26 [INFO] w3_utils.store_token_on_blockchain:286 - Storing token on blockchain: EKSQKJ3T2R
2025-04-16 13:41:26 [DEBUG] w3_utils.store_token_on_blockchain:308 - Building transaction for token: EKSQKJ3T2R
2025-04-16 13:41:27 [DEBUG] w3_utils.store_token_on_blockchain:317 - Signing transaction...
2025-04-16 13:41:27 [DEBUG] w3_utils.store_token_on_blockchain:320 - Sending transaction to network...
2025-04-16 13:41:27 [DEBUG] w3_utils.store_token_on_blockchain:343 - Traceback (most recent call last):
  File "P:\blockchain-id-authentication\PII-Authenticator\backend\w3_utils.py", line 321, in store_token_on_blockchain
    tx_hash = web3.eth.send_raw_transaction(signed_tx.raw_transaction)
  File "C:\Users\prajw\AppData\Local\Programs\Python\Python313\Lib\site-packages\web3\eth\eth.py", line 396, in send_raw_transaction
    return self._send_raw_transaction(transaction)
           ~~~~~~~~~~~~~~~~~~~~~~~~~~^^^^^^^^^^^^^
  File "C:\Users\prajw\AppData\Local\Programs\Python\Python313\Lib\site-packages\web3\module.py", line 112, in caller
    result = w3.manager.request_blocking(
        method_str, params, error_formatters, null_result_formatters
    )
  File "C:\Users\prajw\AppData\Local\Programs\Python\Python313\Lib\site-packages\web3\manager.py", line 232, in request_blocking
    return self.formatted_response(
           ~~~~~~~~~~~~~~~~~~~~~~~^
        response, params, error_formatters, null_result_formatters
        ^^^^^^^^^^^^^^^^^^^^^^^^^^^^^^^^^^^^^^^^^^^^^^^^^^^^^^^^^^
    )
    ^
  File "C:\Users\prajw\AppData\Local\Programs\Python\Python313\Lib\site-packages\web3\manager.py", line 198, in formatted_response
    validate_rpc_response_and_raise_if_error(
    ~~~~~~~~~~~~~~~~~~~~~~~~~~~~~~~~~~~~~~~~^
        response,
        ^^^^^^^^^
    ...<3 lines>...
        params=params,
        ^^^^^^^^^^^^^^
    )
    ^
  File "C:\Users\prajw\AppData\Local\Programs\Python\Python313\Lib\site-packages\web3\_utils\validation.py", line 401, in validate_rpc_response_and_raise_if_error
    raise web3_rpc_error
web3.exceptions.Web3RPCError: {'code': -32603, 'message': 'replacement transaction underpriced'}

2025-04-16 13:41:27 [WARNING] token_auth.get_or_generate_token:46 - Failed to store token EKSQKJ3T2R on blockchain for user anupsdsfc
2025-04-16 13:41:27 [DEBUG] token_auth.get_or_generate_token:51 - Token generation completed in 0.9842 seconds
2025-04-16 13:41:27 [INFO] w3_utils.upload_to_filebase:140 - Uploading file EKSQKJ3T2R.json to storage...
2025-04-16 13:41:28 [INFO] .None:0 - ACCESS: /encrypt | User: anupsdsfc | Token: EKSQKJ3T2R | IP: 127.0.0.1 | Status: success | Details: Token generated and data stored at https://s3.filebase.com/pii-authenticator-test/EKSQKJ3T2R.json
2025-04-16 13:41:28 [DEBUG] app.after_request:35 - Request 2b44af750c77701a processed in 2.2257 seconds
2025-04-16 13:41:38 [DEBUG] app.after_request:35 - Request fdbea13007b1163d processed in 0.0001 seconds
2025-04-16 13:41:38 [INFO] token_auth.verify_token:65 - Verifying token: EKSQKJ3T2R
2025-04-16 13:41:38 [INFO] w3_utils.verify_token_on_blockchain:356 - Verifying token on blockchain: EKSQKJ3T2R
2025-04-16 13:41:38 [INFO] w3_utils.check_file_exists_in_filebase:202 - Checking if file EKSQKJ3T2R.json exists in Filebase...
2025-04-16 13:41:38 [DEBUG] token_auth.verify_token:72 - Token verification completed in 0.7469 seconds
2025-04-16 13:41:38 [INFO] token_auth.verify_token:75 - Token EKSQKJ3T2R is valid
2025-04-16 13:41:38 [INFO] .None:0 - ACCESS: /validate_token | User: N/A | Token: EKSQKJ3T2R | IP: 127.0.0.1 | Status: success | Details: Token validation successful
2025-04-16 13:41:38 [DEBUG] app.after_request:35 - Request 658ee786bc39ea92 processed in 0.7482 seconds
